2024-11-07 15:56:39,273 - app.src.utils.hanlerError - ERROR - Excepción capturada: 'InfomacionToEncodear' object has no attribute 'valu'
Traceback (most recent call last):
  File "C:\Users\Kevin\Desktop\KaminariApi\app\src\utils\jwtUtils.py", line 25, in encode
    key=InfomacionToEncodear.SECRETKEY.valu,
        ^^^^^^^^^^^^^^^^^^^^^^^^^^^^^^^^^^^
AttributeError: 'InfomacionToEncodear' object has no attribute 'valu'. Did you mean: 'value'?
2024-11-11 12:33:14,247 - ERROR - Excepción capturada: 'InfomacionToEncodear' object has no attribute 'valu'
Traceback (most recent call last):
  File "C:\Users\Kevin\Desktop\KaminariApi\app\src\utils\jwtUtils.py", line 25, in encode
    key=InfomacionToEncodear.SECRETKEY.valu,
        ^^^^^^^^^^^^^^^^^^^^^^^^^^^^^^^^^^^
AttributeError: 'InfomacionToEncodear' object has no attribute 'valu'. Did you mean: 'value'?
2024-11-11 12:33:42,590 - ERROR - Excepción capturada: 'InfomacionToEncodear' object has no attribute 'valu'
Traceback (most recent call last):
  File "C:\Users\Kevin\Desktop\KaminariApi\app\src\utils\jwtUtils.py", line 25, in encode
    key=InfomacionToEncodear.SECRETKEY.valu,
        ^^^^^^^^^^^^^^^^^^^^^^^^^^^^^^^^^^^
AttributeError: 'InfomacionToEncodear' object has no attribute 'valu'. Did you mean: 'value'?
2024-11-11 12:50:38,684 - ERROR - Excepción capturada: 'InfomacionToEncodear' object has no attribute 'valu'
Traceback (most recent call last):
  File "C:\Users\Kevin\Desktop\KaminariApi\app\src\utils\jwtUtils.py", line 26, in encode
    algorithm=InfomacionToEncodear.ALGORITH.valu[0] # para encriptar va en formato str y para desencriptar va en lista
              ^^^^^^^^^^^^^^^^^^^^^^^^^^^^^^^^^^
AttributeError: 'InfomacionToEncodear' object has no attribute 'valu'. Did you mean: 'value'?
2024-11-11 12:53:03,902 - ERROR - Excepción capturada: 'InfomacionToEncodear' object has no attribute 'valu'
Traceback (most recent call last):
  File "C:\Users\Kevin\Desktop\KaminariApi\app\src\utils\jwtUtils.py", line 26, in encode
    algorithm=InfomacionToEncodear.ALGORITH.valu[0] # para encriptar va en formato str y para desencriptar va en lista
              ^^^^^^^^^^^^^^^^^^^^^^^^^^^^^^^^^^
AttributeError: 'InfomacionToEncodear' object has no attribute 'valu'. Did you mean: 'value'?
2024-11-11 14:34:09,140 - ERROR - Form data requires "python-multipart" to be installed. 
You can install "python-multipart" with: 

pip install python-multipart

2024-11-11 15:26:32,935 - ERROR - Excepción capturada: Not enough segments
Traceback (most recent call last):
  File "C:\Users\Kevin\Desktop\KaminariApi\venv\Lib\site-packages\jose\jws.py", line 176, in _load
    signing_input, crypto_segment = jwt.rsplit(b".", 1)
    ^^^^^^^^^^^^^^^^^^^^^^^^^^^^^
ValueError: not enough values to unpack (expected 2, got 1)

During handling of the above exception, another exception occurred:

Traceback (most recent call last):
  File "C:\Users\Kevin\Desktop\KaminariApi\venv\Lib\site-packages\jose\jwt.py", line 142, in decode
    payload = jws.verify(token, key, algorithms, verify=verify_signature)
              ^^^^^^^^^^^^^^^^^^^^^^^^^^^^^^^^^^^^^^^^^^^^^^^^^^^^^^^^^^^
  File "C:\Users\Kevin\Desktop\KaminariApi\venv\Lib\site-packages\jose\jws.py", line 70, in verify
    header, payload, signing_input, signature = _load(token)
                                                ^^^^^^^^^^^^
  File "C:\Users\Kevin\Desktop\KaminariApi\venv\Lib\site-packages\jose\jws.py", line 180, in _load
    raise JWSError("Not enough segments")
jose.exceptions.JWSError: Not enough segments

During handling of the above exception, another exception occurred:

Traceback (most recent call last):
  File "C:\Users\Kevin\Desktop\KaminariApi\app\src\utils\jwtUtils.py", line 48, in decodeToken
    return decode(
           ^^^^^^^
  File "C:\Users\Kevin\Desktop\KaminariApi\venv\Lib\site-packages\jose\jwt.py", line 144, in decode
    raise JWTError(e)
jose.exceptions.JWTError: Not enough segments
2024-11-11 15:30:23,784 - ERROR - Excepción capturada: Not enough segments
Traceback (most recent call last):
  File "C:\Users\Kevin\Desktop\KaminariApi\venv\Lib\site-packages\jose\jws.py", line 176, in _load
    signing_input, crypto_segment = jwt.rsplit(b".", 1)
    ^^^^^^^^^^^^^^^^^^^^^^^^^^^^^
ValueError: not enough values to unpack (expected 2, got 1)

During handling of the above exception, another exception occurred:

Traceback (most recent call last):
  File "C:\Users\Kevin\Desktop\KaminariApi\venv\Lib\site-packages\jose\jwt.py", line 142, in decode
    payload = jws.verify(token, key, algorithms, verify=verify_signature)
              ^^^^^^^^^^^^^^^^^^^^^^^^^^^^^^^^^^^^^^^^^^^^^^^^^^^^^^^^^^^
  File "C:\Users\Kevin\Desktop\KaminariApi\venv\Lib\site-packages\jose\jws.py", line 70, in verify
    header, payload, signing_input, signature = _load(token)
                                                ^^^^^^^^^^^^
  File "C:\Users\Kevin\Desktop\KaminariApi\venv\Lib\site-packages\jose\jws.py", line 180, in _load
    raise JWSError("Not enough segments")
jose.exceptions.JWSError: Not enough segments

During handling of the above exception, another exception occurred:

Traceback (most recent call last):
  File "C:\Users\Kevin\Desktop\KaminariApi\app\src\utils\jwtUtils.py", line 48, in decodeToken
    return decode(
           ^^^^^^^
  File "C:\Users\Kevin\Desktop\KaminariApi\venv\Lib\site-packages\jose\jwt.py", line 144, in decode
    raise JWTError(e)
jose.exceptions.JWTError: Not enough segments
2024-11-11 15:42:15,757 - ERROR - Excepción capturada: Not enough segments
Traceback (most recent call last):
  File "C:\Users\Kevin\Desktop\KaminariApi\venv\Lib\site-packages\jose\jws.py", line 176, in _load
    signing_input, crypto_segment = jwt.rsplit(b".", 1)
    ^^^^^^^^^^^^^^^^^^^^^^^^^^^^^
ValueError: not enough values to unpack (expected 2, got 1)

During handling of the above exception, another exception occurred:

Traceback (most recent call last):
  File "C:\Users\Kevin\Desktop\KaminariApi\venv\Lib\site-packages\jose\jwt.py", line 142, in decode
    payload = jws.verify(token, key, algorithms, verify=verify_signature)
              ^^^^^^^^^^^^^^^^^^^^^^^^^^^^^^^^^^^^^^^^^^^^^^^^^^^^^^^^^^^
  File "C:\Users\Kevin\Desktop\KaminariApi\venv\Lib\site-packages\jose\jws.py", line 70, in verify
    header, payload, signing_input, signature = _load(token)
                                                ^^^^^^^^^^^^
  File "C:\Users\Kevin\Desktop\KaminariApi\venv\Lib\site-packages\jose\jws.py", line 180, in _load
    raise JWSError("Not enough segments")
jose.exceptions.JWSError: Not enough segments

During handling of the above exception, another exception occurred:

Traceback (most recent call last):
  File "C:\Users\Kevin\Desktop\KaminariApi\app\src\utils\jwtUtils.py", line 48, in decodeToken
    return decode(
           ^^^^^^^
  File "C:\Users\Kevin\Desktop\KaminariApi\venv\Lib\site-packages\jose\jwt.py", line 144, in decode
    raise JWTError(e)
jose.exceptions.JWTError: Not enough segments
2024-11-11 15:50:26,941 - ERROR - Excepción capturada: Not enough segments
Traceback (most recent call last):
  File "C:\Users\Kevin\Desktop\KaminariApi\venv\Lib\site-packages\jose\jws.py", line 176, in _load
    signing_input, crypto_segment = jwt.rsplit(b".", 1)
    ^^^^^^^^^^^^^^^^^^^^^^^^^^^^^
ValueError: not enough values to unpack (expected 2, got 1)

During handling of the above exception, another exception occurred:

Traceback (most recent call last):
  File "C:\Users\Kevin\Desktop\KaminariApi\venv\Lib\site-packages\jose\jwt.py", line 142, in decode
    payload = jws.verify(token, key, algorithms, verify=verify_signature)
              ^^^^^^^^^^^^^^^^^^^^^^^^^^^^^^^^^^^^^^^^^^^^^^^^^^^^^^^^^^^
  File "C:\Users\Kevin\Desktop\KaminariApi\venv\Lib\site-packages\jose\jws.py", line 70, in verify
    header, payload, signing_input, signature = _load(token)
                                                ^^^^^^^^^^^^
  File "C:\Users\Kevin\Desktop\KaminariApi\venv\Lib\site-packages\jose\jws.py", line 180, in _load
    raise JWSError("Not enough segments")
jose.exceptions.JWSError: Not enough segments

During handling of the above exception, another exception occurred:

Traceback (most recent call last):
  File "C:\Users\Kevin\Desktop\KaminariApi\app\src\utils\jwtUtils.py", line 48, in decodeToken
    return decode(
           ^^^^^^^
  File "C:\Users\Kevin\Desktop\KaminariApi\venv\Lib\site-packages\jose\jwt.py", line 144, in decode
    raise JWTError(e)
jose.exceptions.JWTError: Not enough segments
2024-11-11 15:53:40,333 - ERROR - Excepción capturada: Not enough segments
Traceback (most recent call last):
  File "C:\Users\Kevin\Desktop\KaminariApi\venv\Lib\site-packages\jose\jws.py", line 176, in _load
    signing_input, crypto_segment = jwt.rsplit(b".", 1)
    ^^^^^^^^^^^^^^^^^^^^^^^^^^^^^
ValueError: not enough values to unpack (expected 2, got 1)

During handling of the above exception, another exception occurred:

Traceback (most recent call last):
  File "C:\Users\Kevin\Desktop\KaminariApi\venv\Lib\site-packages\jose\jwt.py", line 142, in decode
    payload = jws.verify(token, key, algorithms, verify=verify_signature)
              ^^^^^^^^^^^^^^^^^^^^^^^^^^^^^^^^^^^^^^^^^^^^^^^^^^^^^^^^^^^
  File "C:\Users\Kevin\Desktop\KaminariApi\venv\Lib\site-packages\jose\jws.py", line 70, in verify
    header, payload, signing_input, signature = _load(token)
                                                ^^^^^^^^^^^^
  File "C:\Users\Kevin\Desktop\KaminariApi\venv\Lib\site-packages\jose\jws.py", line 180, in _load
    raise JWSError("Not enough segments")
jose.exceptions.JWSError: Not enough segments

During handling of the above exception, another exception occurred:

Traceback (most recent call last):
  File "C:\Users\Kevin\Desktop\KaminariApi\app\src\utils\jwtUtils.py", line 51, in decodeToken
    return decode(
           ^^^^^^^
  File "C:\Users\Kevin\Desktop\KaminariApi\venv\Lib\site-packages\jose\jwt.py", line 144, in decode
    raise JWTError(e)
jose.exceptions.JWTError: Not enough segments
2024-11-15 12:30:40,822 - ERROR - Excepción capturada: cannot access local variable 'datosRequired' where it is not associated with a value
Traceback (most recent call last):
  File "C:\Users\Kevin\Desktop\KaminariApi\main.py", line 28, in login
    userInDb = ClienteHandler().consultarClienteInDb(username=form_data.username, pwd=form_data.password)
               ^^^^^^^^^^^^^^^^^^^^^^^^^^^^^^^^^^^^^^^^^^^^^^^^^^^^^^^^^^^^^^^^^^^^^^^^^^^^^^^^^^^^^^^^^^
  File "C:\Users\Kevin\Desktop\KaminariApi\app\src\schemas\cliente.py", line 127, in consultarClienteInDb
    return datosRequired
           ^^^^^^^^^^^^^
UnboundLocalError: cannot access local variable 'datosRequired' where it is not associated with a value
2024-11-15 12:30:47,610 - ERROR - Excepción capturada: Not enough segments
Traceback (most recent call last):
  File "C:\Users\Kevin\Desktop\KaminariApi\venv\Lib\site-packages\jose\jws.py", line 176, in _load
    signing_input, crypto_segment = jwt.rsplit(b".", 1)
    ^^^^^^^^^^^^^^^^^^^^^^^^^^^^^
ValueError: not enough values to unpack (expected 2, got 1)

During handling of the above exception, another exception occurred:

Traceback (most recent call last):
  File "C:\Users\Kevin\Desktop\KaminariApi\venv\Lib\site-packages\jose\jwt.py", line 142, in decode
    payload = jws.verify(token, key, algorithms, verify=verify_signature)
              ^^^^^^^^^^^^^^^^^^^^^^^^^^^^^^^^^^^^^^^^^^^^^^^^^^^^^^^^^^^
  File "C:\Users\Kevin\Desktop\KaminariApi\venv\Lib\site-packages\jose\jws.py", line 70, in verify
    header, payload, signing_input, signature = _load(token)
                                                ^^^^^^^^^^^^
  File "C:\Users\Kevin\Desktop\KaminariApi\venv\Lib\site-packages\jose\jws.py", line 180, in _load
    raise JWSError("Not enough segments")
jose.exceptions.JWSError: Not enough segments

During handling of the above exception, another exception occurred:

Traceback (most recent call last):
  File "C:\Users\Kevin\Desktop\KaminariApi\app\src\utils\jwtUtils.py", line 50, in decodeToken
    return decode(
           ^^^^^^^
  File "C:\Users\Kevin\Desktop\KaminariApi\venv\Lib\site-packages\jose\jwt.py", line 144, in decode
    raise JWTError(e)
jose.exceptions.JWTError: Not enough segments
2024-11-15 12:31:30,400 - ERROR - Excepción capturada: cannot access local variable 'datosRequired' where it is not associated with a value
Traceback (most recent call last):
  File "C:\Users\Kevin\Desktop\KaminariApi\main.py", line 28, in login
    userInDb = ClienteHandler().consultarClienteInDb(username=form_data.username, pwd=form_data.password)
               ^^^^^^^^^^^^^^^^^^^^^^^^^^^^^^^^^^^^^^^^^^^^^^^^^^^^^^^^^^^^^^^^^^^^^^^^^^^^^^^^^^^^^^^^^^
  File "C:\Users\Kevin\Desktop\KaminariApi\app\src\schemas\cliente.py", line 127, in consultarClienteInDb
    return datosRequired
           ^^^^^^^^^^^^^
UnboundLocalError: cannot access local variable 'datosRequired' where it is not associated with a value
2024-11-15 12:31:38,506 - ERROR - Excepción capturada: Not enough segments
Traceback (most recent call last):
  File "C:\Users\Kevin\Desktop\KaminariApi\venv\Lib\site-packages\jose\jws.py", line 176, in _load
    signing_input, crypto_segment = jwt.rsplit(b".", 1)
    ^^^^^^^^^^^^^^^^^^^^^^^^^^^^^
ValueError: not enough values to unpack (expected 2, got 1)

During handling of the above exception, another exception occurred:

Traceback (most recent call last):
  File "C:\Users\Kevin\Desktop\KaminariApi\venv\Lib\site-packages\jose\jwt.py", line 142, in decode
    payload = jws.verify(token, key, algorithms, verify=verify_signature)
              ^^^^^^^^^^^^^^^^^^^^^^^^^^^^^^^^^^^^^^^^^^^^^^^^^^^^^^^^^^^
  File "C:\Users\Kevin\Desktop\KaminariApi\venv\Lib\site-packages\jose\jws.py", line 70, in verify
    header, payload, signing_input, signature = _load(token)
                                                ^^^^^^^^^^^^
  File "C:\Users\Kevin\Desktop\KaminariApi\venv\Lib\site-packages\jose\jws.py", line 180, in _load
    raise JWSError("Not enough segments")
jose.exceptions.JWSError: Not enough segments

During handling of the above exception, another exception occurred:

Traceback (most recent call last):
  File "C:\Users\Kevin\Desktop\KaminariApi\app\src\utils\jwtUtils.py", line 50, in decodeToken
    return decode(
           ^^^^^^^
  File "C:\Users\Kevin\Desktop\KaminariApi\venv\Lib\site-packages\jose\jwt.py", line 144, in decode
    raise JWTError(e)
jose.exceptions.JWTError: Not enough segments
2024-11-15 12:32:07,477 - ERROR - Excepción capturada: cannot access local variable 'datosRequired' where it is not associated with a value
Traceback (most recent call last):
  File "C:\Users\Kevin\Desktop\KaminariApi\main.py", line 28, in login
    userInDb = ClienteHandler().consultarClienteInDb(username=form_data.username, pwd=form_data.password)
               ^^^^^^^^^^^^^^^^^^^^^^^^^^^^^^^^^^^^^^^^^^^^^^^^^^^^^^^^^^^^^^^^^^^^^^^^^^^^^^^^^^^^^^^^^^
  File "C:\Users\Kevin\Desktop\KaminariApi\app\src\schemas\cliente.py", line 127, in consultarClienteInDb
    return datosRequired
           ^^^^^^^^^^^^^
UnboundLocalError: cannot access local variable 'datosRequired' where it is not associated with a value
2024-11-15 12:32:16,744 - ERROR - Excepción capturada: Not enough segments
Traceback (most recent call last):
  File "C:\Users\Kevin\Desktop\KaminariApi\venv\Lib\site-packages\jose\jws.py", line 176, in _load
    signing_input, crypto_segment = jwt.rsplit(b".", 1)
    ^^^^^^^^^^^^^^^^^^^^^^^^^^^^^
ValueError: not enough values to unpack (expected 2, got 1)

During handling of the above exception, another exception occurred:

Traceback (most recent call last):
  File "C:\Users\Kevin\Desktop\KaminariApi\venv\Lib\site-packages\jose\jwt.py", line 142, in decode
    payload = jws.verify(token, key, algorithms, verify=verify_signature)
              ^^^^^^^^^^^^^^^^^^^^^^^^^^^^^^^^^^^^^^^^^^^^^^^^^^^^^^^^^^^
  File "C:\Users\Kevin\Desktop\KaminariApi\venv\Lib\site-packages\jose\jws.py", line 70, in verify
    header, payload, signing_input, signature = _load(token)
                                                ^^^^^^^^^^^^
  File "C:\Users\Kevin\Desktop\KaminariApi\venv\Lib\site-packages\jose\jws.py", line 180, in _load
    raise JWSError("Not enough segments")
jose.exceptions.JWSError: Not enough segments

During handling of the above exception, another exception occurred:

Traceback (most recent call last):
  File "C:\Users\Kevin\Desktop\KaminariApi\app\src\utils\jwtUtils.py", line 50, in decodeToken
    return decode(
           ^^^^^^^
  File "C:\Users\Kevin\Desktop\KaminariApi\venv\Lib\site-packages\jose\jwt.py", line 144, in decode
    raise JWTError(e)
jose.exceptions.JWTError: Not enough segments
2024-11-15 12:33:08,933 - ERROR - Excepción capturada: Not enough segments
Traceback (most recent call last):
  File "C:\Users\Kevin\Desktop\KaminariApi\venv\Lib\site-packages\jose\jws.py", line 176, in _load
    signing_input, crypto_segment = jwt.rsplit(b".", 1)
    ^^^^^^^^^^^^^^^^^^^^^^^^^^^^^
ValueError: not enough values to unpack (expected 2, got 1)

During handling of the above exception, another exception occurred:

Traceback (most recent call last):
  File "C:\Users\Kevin\Desktop\KaminariApi\venv\Lib\site-packages\jose\jwt.py", line 142, in decode
    payload = jws.verify(token, key, algorithms, verify=verify_signature)
              ^^^^^^^^^^^^^^^^^^^^^^^^^^^^^^^^^^^^^^^^^^^^^^^^^^^^^^^^^^^
  File "C:\Users\Kevin\Desktop\KaminariApi\venv\Lib\site-packages\jose\jws.py", line 70, in verify
    header, payload, signing_input, signature = _load(token)
                                                ^^^^^^^^^^^^
  File "C:\Users\Kevin\Desktop\KaminariApi\venv\Lib\site-packages\jose\jws.py", line 180, in _load
    raise JWSError("Not enough segments")
jose.exceptions.JWSError: Not enough segments

During handling of the above exception, another exception occurred:

Traceback (most recent call last):
  File "C:\Users\Kevin\Desktop\KaminariApi\app\src\utils\jwtUtils.py", line 50, in decodeToken
    return decode(
           ^^^^^^^
  File "C:\Users\Kevin\Desktop\KaminariApi\venv\Lib\site-packages\jose\jwt.py", line 144, in decode
    raise JWTError(e)
jose.exceptions.JWTError: Not enough segments
2024-11-15 12:34:40,453 - ERROR - Excepción capturada: cannot access local variable 'datosRequired' where it is not associated with a value
Traceback (most recent call last):
  File "C:\Users\Kevin\Desktop\KaminariApi\main.py", line 28, in login
    userInDb = ClienteHandler().consultarClienteInDb(username=form_data.username, pwd=form_data.password)
               ^^^^^^^^^^^^^^^^^^^^^^^^^^^^^^^^^^^^^^^^^^^^^^^^^^^^^^^^^^^^^^^^^^^^^^^^^^^^^^^^^^^^^^^^^^
  File "C:\Users\Kevin\Desktop\KaminariApi\app\src\schemas\cliente.py", line 127, in consultarClienteInDb
    return datosRequired
           ^^^^^^^^^^^^^
UnboundLocalError: cannot access local variable 'datosRequired' where it is not associated with a value
2024-11-15 12:36:37,840 - ERROR - Excepción capturada: cannot access local variable 'datosRequired' where it is not associated with a value
Traceback (most recent call last):
  File "C:\Users\Kevin\Desktop\KaminariApi\main.py", line 28, in login
    userInDb = ClienteHandler().consultarClienteInDb(username=form_data.username, pwd=form_data.password)
               ^^^^^^^^^^^^^^^^^^^^^^^^^^^^^^^^^^^^^^^^^^^^^^^^^^^^^^^^^^^^^^^^^^^^^^^^^^^^^^^^^^^^^^^^^^
  File "C:\Users\Kevin\Desktop\KaminariApi\app\src\schemas\cliente.py", line 127, in consultarClienteInDb
    return datosRequired
           ^^^^^^^^^^^^^
UnboundLocalError: cannot access local variable 'datosRequired' where it is not associated with a value
2024-11-15 12:39:16,628 - ERROR - Excepción capturada: cannot access local variable 'datosRequired' where it is not associated with a value
Traceback (most recent call last):
  File "C:\Users\Kevin\Desktop\KaminariApi\main.py", line 28, in login
    userInDb = ClienteHandler().consultarClienteInDb(username=form_data.username, pwd=form_data.password)
               ^^^^^^^^^^^^^^^^^^^^^^^^^^^^^^^^^^^^^^^^^^^^^^^^^^^^^^^^^^^^^^^^^^^^^^^^^^^^^^^^^^^^^^^^^^
  File "C:\Users\Kevin\Desktop\KaminariApi\app\src\schemas\cliente.py", line 127, in consultarClienteInDb
    return datosRequired
           ^^^^^^^^^^^^^
UnboundLocalError: cannot access local variable 'datosRequired' where it is not associated with a value
2024-11-15 12:51:33,618 - ERROR - Excepción capturada: cannot access local variable 'datosRequired' where it is not associated with a value
Traceback (most recent call last):
  File "C:\Users\Kevin\Desktop\KaminariApi\main.py", line 28, in login
    userInDb = ClienteHandler().consultarClienteInDb(username=form_data.username, pwd=form_data.password)
               ^^^^^^^^^^^^^^^^^^^^^^^^^^^^^^^^^^^^^^^^^^^^^^^^^^^^^^^^^^^^^^^^^^^^^^^^^^^^^^^^^^^^^^^^^^
  File "C:\Users\Kevin\Desktop\KaminariApi\app\src\schemas\cliente.py", line 127, in consultarClienteInDb
    return datosRequired
           ^^^^^^^^^^^^^
UnboundLocalError: cannot access local variable 'datosRequired' where it is not associated with a value
2024-11-15 13:00:49,009 - ERROR - Excepción capturada: cannot access local variable 'datosRequired' where it is not associated with a value
Traceback (most recent call last):
  File "C:\Users\Kevin\Desktop\KaminariApi\main.py", line 30, in login
    userInDb = ClienteHandler().consultarClienteInDb(username=form_data.username, pwd=form_data.password)
               ^^^^^^^^^^^^^^^^^^^^^^^^^^^^^^^^^^^^^^^^^^^^^^^^^^^^^^^^^^^^^^^^^^^^^^^^^^^^^^^^^^^^^^^^^^
  File "C:\Users\Kevin\Desktop\KaminariApi\app\src\schemas\cliente.py", line 127, in consultarClienteInDb
    return datosRequired
           ^^^^^^^^^^^^^
UnboundLocalError: cannot access local variable 'datosRequired' where it is not associated with a value
2024-11-15 13:23:23,863 - ERROR - Excepción capturada: cannot access local variable 'datosRequired' where it is not associated with a value
Traceback (most recent call last):
  File "C:\Users\Kevin\Desktop\KaminariApi\main.py", line 30, in login
    userInDb = ClienteHandler().consultarClienteInDb(username=form_data.username, pwd=form_data.password)
               ^^^^^^^^^^^^^^^^^^^^^^^^^^^^^^^^^^^^^^^^^^^^^^^^^^^^^^^^^^^^^^^^^^^^^^^^^^^^^^^^^^^^^^^^^^
  File "C:\Users\Kevin\Desktop\KaminariApi\app\src\schemas\cliente.py", line 127, in consultarClienteInDb
    return datosRequired
           ^^^^^^^^^^^^^
UnboundLocalError: cannot access local variable 'datosRequired' where it is not associated with a value
2024-11-15 13:49:36,579 - ERROR - Excepción capturada: cannot access local variable 'datosRequired' where it is not associated with a value
Traceback (most recent call last):
  File "C:\Users\Kevin\Desktop\KaminariApi\main.py", line 30, in login
    userInDb = ClienteHandler().consultarClienteInDb(username=form_data.username, pwd=form_data.password)
               ^^^^^^^^^^^^^^^^^^^^^^^^^^^^^^^^^^^^^^^^^^^^^^^^^^^^^^^^^^^^^^^^^^^^^^^^^^^^^^^^^^^^^^^^^^
  File "C:\Users\Kevin\Desktop\KaminariApi\app\src\schemas\cliente.py", line 128, in consultarClienteInDb
    return datosRequired
           ^^^^^^^^^^^^^
UnboundLocalError: cannot access local variable 'datosRequired' where it is not associated with a value
2024-11-15 13:51:35,161 - ERROR - Excepción capturada: cannot access local variable 'datosRequired' where it is not associated with a value
Traceback (most recent call last):
  File "C:\Users\Kevin\Desktop\KaminariApi\main.py", line 30, in login
    userInDb = ClienteHandler().consultarClienteInDb(username=form_data.username, pwd=form_data.password)
               ^^^^^^^^^^^^^^^^^^^^^^^^^^^^^^^^^^^^^^^^^^^^^^^^^^^^^^^^^^^^^^^^^^^^^^^^^^^^^^^^^^^^^^^^^^
  File "C:\Users\Kevin\Desktop\KaminariApi\app\src\schemas\cliente.py", line 128, in consultarClienteInDb
    return datosRequired
           ^^^^^^^^^^^^^
UnboundLocalError: cannot access local variable 'datosRequired' where it is not associated with a value
2024-11-15 13:56:32,932 - ERROR - Excepción capturada: cannot access local variable 'datosRequired' where it is not associated with a value
Traceback (most recent call last):
  File "C:\Users\Kevin\Desktop\KaminariApi\main.py", line 30, in login
    userInDb = ClienteHandler().consultarClienteInDb(username=form_data.username, pwd=form_data.password)
               ^^^^^^^^^^^^^^^^^^^^^^^^^^^^^^^^^^^^^^^^^^^^^^^^^^^^^^^^^^^^^^^^^^^^^^^^^^^^^^^^^^^^^^^^^^
  File "C:\Users\Kevin\Desktop\KaminariApi\app\src\schemas\cliente.py", line 128, in consultarClienteInDb
    return datosRequired
           ^^^^^^^^^^^^^
UnboundLocalError: cannot access local variable 'datosRequired' where it is not associated with a value
2024-11-15 14:16:43,093 - ERROR - Excepción capturada: 'NoneType' object has no attribute 'id'
Traceback (most recent call last):
  File "C:\Users\Kevin\Desktop\KaminariApi\main.py", line 30, in login
    userInDb = ClienteHandler().consultarClienteInDb(username=form_data.username, pwd=form_data.password)
               ^^^^^^^^^^^^^^^^^^^^^^^^^^^^^^^^^^^^^^^^^^^^^^^^^^^^^^^^^^^^^^^^^^^^^^^^^^^^^^^^^^^^^^^^^^
  File "C:\Users\Kevin\Desktop\KaminariApi\app\src\schemas\cliente.py", line 124, in consultarClienteInDb
    datosRequired = {'id': cliente.id, 'username': cliente.username, 'pwd': cliente.pwd}
                           ^^^^^^^^^^
AttributeError: 'NoneType' object has no attribute 'id'
2024-11-15 14:17:48,365 - ERROR - Excepción capturada: 'NoneType' object is not subscriptable
Traceback (most recent call last):
  File "C:\Users\Kevin\Desktop\KaminariApi\main.py", line 30, in login
    userInDb = ClienteHandler().consultarClienteInDb(username=form_data.username, pwd=form_data.password)
               ^^^^^^^^^^^^^^^^^^^^^^^^^^^^^^^^^^^^^^^^^^^^^^^^^^^^^^^^^^^^^^^^^^^^^^^^^^^^^^^^^^^^^^^^^^
  File "C:\Users\Kevin\Desktop\KaminariApi\app\src\schemas\cliente.py", line 124, in consultarClienteInDb
    datosRequired = {'id': cliente['id'], 'username': cliente['username'], 'pwd': cliente['pwd']}
                           ~~~~~~~^^^^^^
TypeError: 'NoneType' object is not subscriptable
2024-11-15 14:20:25,491 - ERROR - Excepción capturada: Not enough segments
Traceback (most recent call last):
  File "C:\Users\Kevin\Desktop\KaminariApi\venv\Lib\site-packages\jose\jws.py", line 176, in _load
    signing_input, crypto_segment = jwt.rsplit(b".", 1)
    ^^^^^^^^^^^^^^^^^^^^^^^^^^^^^
ValueError: not enough values to unpack (expected 2, got 1)

During handling of the above exception, another exception occurred:

Traceback (most recent call last):
  File "C:\Users\Kevin\Desktop\KaminariApi\venv\Lib\site-packages\jose\jwt.py", line 142, in decode
    payload = jws.verify(token, key, algorithms, verify=verify_signature)
              ^^^^^^^^^^^^^^^^^^^^^^^^^^^^^^^^^^^^^^^^^^^^^^^^^^^^^^^^^^^
  File "C:\Users\Kevin\Desktop\KaminariApi\venv\Lib\site-packages\jose\jws.py", line 70, in verify
    header, payload, signing_input, signature = _load(token)
                                                ^^^^^^^^^^^^
  File "C:\Users\Kevin\Desktop\KaminariApi\venv\Lib\site-packages\jose\jws.py", line 180, in _load
    raise JWSError("Not enough segments")
jose.exceptions.JWSError: Not enough segments

During handling of the above exception, another exception occurred:

Traceback (most recent call last):
  File "C:\Users\Kevin\Desktop\KaminariApi\app\src\utils\jwtUtils.py", line 51, in decodeToken
    return decode(
           ^^^^^^^
  File "C:\Users\Kevin\Desktop\KaminariApi\venv\Lib\site-packages\jose\jwt.py", line 144, in decode
    raise JWTError(e)
jose.exceptions.JWTError: Not enough segments
2024-11-15 14:23:52,173 - ERROR - Excepción capturada: 401: Credenciales inválidas
Traceback (most recent call last):
  File "C:\Users\Kevin\Desktop\KaminariApi\main.py", line 34, in login
    raise HTTPException(
fastapi.exceptions.HTTPException: 401: Credenciales inválidas
2024-11-15 14:24:34,195 - ERROR - Excepción capturada: Not enough segments
Traceback (most recent call last):
  File "C:\Users\Kevin\Desktop\KaminariApi\venv\Lib\site-packages\jose\jws.py", line 176, in _load
    signing_input, crypto_segment = jwt.rsplit(b".", 1)
    ^^^^^^^^^^^^^^^^^^^^^^^^^^^^^
ValueError: not enough values to unpack (expected 2, got 1)

During handling of the above exception, another exception occurred:

Traceback (most recent call last):
  File "C:\Users\Kevin\Desktop\KaminariApi\venv\Lib\site-packages\jose\jwt.py", line 142, in decode
    payload = jws.verify(token, key, algorithms, verify=verify_signature)
              ^^^^^^^^^^^^^^^^^^^^^^^^^^^^^^^^^^^^^^^^^^^^^^^^^^^^^^^^^^^
  File "C:\Users\Kevin\Desktop\KaminariApi\venv\Lib\site-packages\jose\jws.py", line 70, in verify
    header, payload, signing_input, signature = _load(token)
                                                ^^^^^^^^^^^^
  File "C:\Users\Kevin\Desktop\KaminariApi\venv\Lib\site-packages\jose\jws.py", line 180, in _load
    raise JWSError("Not enough segments")
jose.exceptions.JWSError: Not enough segments

During handling of the above exception, another exception occurred:

Traceback (most recent call last):
  File "C:\Users\Kevin\Desktop\KaminariApi\app\src\utils\jwtUtils.py", line 51, in decodeToken
    return decode(
           ^^^^^^^
  File "C:\Users\Kevin\Desktop\KaminariApi\venv\Lib\site-packages\jose\jwt.py", line 144, in decode
    raise JWTError(e)
jose.exceptions.JWTError: Not enough segments
2024-11-15 14:30:39,908 - ERROR - Excepción capturada: 401: Credenciales inválidas
Traceback (most recent call last):
  File "C:\Users\Kevin\Desktop\KaminariApi\main.py", line 34, in login
    raise HTTPException(
fastapi.exceptions.HTTPException: 401: Credenciales inválidas
2024-11-15 14:30:44,313 - ERROR - Excepción capturada: Not enough segments
Traceback (most recent call last):
  File "C:\Users\Kevin\Desktop\KaminariApi\venv\Lib\site-packages\jose\jws.py", line 176, in _load
    signing_input, crypto_segment = jwt.rsplit(b".", 1)
    ^^^^^^^^^^^^^^^^^^^^^^^^^^^^^
ValueError: not enough values to unpack (expected 2, got 1)

During handling of the above exception, another exception occurred:

Traceback (most recent call last):
  File "C:\Users\Kevin\Desktop\KaminariApi\venv\Lib\site-packages\jose\jwt.py", line 142, in decode
    payload = jws.verify(token, key, algorithms, verify=verify_signature)
              ^^^^^^^^^^^^^^^^^^^^^^^^^^^^^^^^^^^^^^^^^^^^^^^^^^^^^^^^^^^
  File "C:\Users\Kevin\Desktop\KaminariApi\venv\Lib\site-packages\jose\jws.py", line 70, in verify
    header, payload, signing_input, signature = _load(token)
                                                ^^^^^^^^^^^^
  File "C:\Users\Kevin\Desktop\KaminariApi\venv\Lib\site-packages\jose\jws.py", line 180, in _load
    raise JWSError("Not enough segments")
jose.exceptions.JWSError: Not enough segments

During handling of the above exception, another exception occurred:

Traceback (most recent call last):
  File "C:\Users\Kevin\Desktop\KaminariApi\app\src\utils\jwtUtils.py", line 51, in decodeToken
    return decode(
           ^^^^^^^
  File "C:\Users\Kevin\Desktop\KaminariApi\venv\Lib\site-packages\jose\jwt.py", line 144, in decode
    raise JWTError(e)
jose.exceptions.JWTError: Not enough segments
2024-11-15 14:34:25,018 - ERROR - Excepción capturada: 401: Credenciales inválidas
Traceback (most recent call last):
  File "C:\Users\Kevin\Desktop\KaminariApi\main.py", line 34, in login
    raise HTTPException(
fastapi.exceptions.HTTPException: 401: Credenciales inválidas
2024-11-15 14:34:42,050 - ERROR - Excepción capturada: Not enough segments
Traceback (most recent call last):
  File "C:\Users\Kevin\Desktop\KaminariApi\venv\Lib\site-packages\jose\jws.py", line 176, in _load
    signing_input, crypto_segment = jwt.rsplit(b".", 1)
    ^^^^^^^^^^^^^^^^^^^^^^^^^^^^^
ValueError: not enough values to unpack (expected 2, got 1)

During handling of the above exception, another exception occurred:

Traceback (most recent call last):
  File "C:\Users\Kevin\Desktop\KaminariApi\venv\Lib\site-packages\jose\jwt.py", line 142, in decode
    payload = jws.verify(token, key, algorithms, verify=verify_signature)
              ^^^^^^^^^^^^^^^^^^^^^^^^^^^^^^^^^^^^^^^^^^^^^^^^^^^^^^^^^^^
  File "C:\Users\Kevin\Desktop\KaminariApi\venv\Lib\site-packages\jose\jws.py", line 70, in verify
    header, payload, signing_input, signature = _load(token)
                                                ^^^^^^^^^^^^
  File "C:\Users\Kevin\Desktop\KaminariApi\venv\Lib\site-packages\jose\jws.py", line 180, in _load
    raise JWSError("Not enough segments")
jose.exceptions.JWSError: Not enough segments

During handling of the above exception, another exception occurred:

Traceback (most recent call last):
  File "C:\Users\Kevin\Desktop\KaminariApi\app\src\utils\jwtUtils.py", line 51, in decodeToken
    return decode(
           ^^^^^^^
  File "C:\Users\Kevin\Desktop\KaminariApi\venv\Lib\site-packages\jose\jwt.py", line 144, in decode
    raise JWTError(e)
jose.exceptions.JWTError: Not enough segments
2024-11-15 15:31:35,775 - ERROR - Excepción capturada: 401: Credenciales inválidas
Traceback (most recent call last):
  File "C:\Users\Kevin\Desktop\KaminariApi\main.py", line 34, in login
    raise HTTPException(
fastapi.exceptions.HTTPException: 401: Credenciales inválidas
2024-11-15 15:32:32,011 - ERROR - Excepción capturada: Not enough segments
Traceback (most recent call last):
  File "C:\Users\Kevin\Desktop\KaminariApi\venv\Lib\site-packages\jose\jws.py", line 176, in _load
    signing_input, crypto_segment = jwt.rsplit(b".", 1)
    ^^^^^^^^^^^^^^^^^^^^^^^^^^^^^
ValueError: not enough values to unpack (expected 2, got 1)

During handling of the above exception, another exception occurred:

Traceback (most recent call last):
  File "C:\Users\Kevin\Desktop\KaminariApi\venv\Lib\site-packages\jose\jwt.py", line 142, in decode
    payload = jws.verify(token, key, algorithms, verify=verify_signature)
              ^^^^^^^^^^^^^^^^^^^^^^^^^^^^^^^^^^^^^^^^^^^^^^^^^^^^^^^^^^^
  File "C:\Users\Kevin\Desktop\KaminariApi\venv\Lib\site-packages\jose\jws.py", line 70, in verify
    header, payload, signing_input, signature = _load(token)
                                                ^^^^^^^^^^^^
  File "C:\Users\Kevin\Desktop\KaminariApi\venv\Lib\site-packages\jose\jws.py", line 180, in _load
    raise JWSError("Not enough segments")
jose.exceptions.JWSError: Not enough segments

During handling of the above exception, another exception occurred:

Traceback (most recent call last):
  File "C:\Users\Kevin\Desktop\KaminariApi\app\src\utils\jwtUtils.py", line 51, in decodeToken
    return decode(
           ^^^^^^^
  File "C:\Users\Kevin\Desktop\KaminariApi\venv\Lib\site-packages\jose\jwt.py", line 144, in decode
    raise JWTError(e)
jose.exceptions.JWTError: Not enough segments
2024-11-15 15:40:18,232 - ERROR - Excepción capturada: 401: Credenciales inválidas
Traceback (most recent call last):
  File "C:\Users\Kevin\Desktop\KaminariApi\main.py", line 34, in login
    raise HTTPException(
fastapi.exceptions.HTTPException: 401: Credenciales inválidas
2024-11-15 15:40:22,453 - ERROR - Excepción capturada: Not enough segments
Traceback (most recent call last):
  File "C:\Users\Kevin\Desktop\KaminariApi\venv\Lib\site-packages\jose\jws.py", line 176, in _load
    signing_input, crypto_segment = jwt.rsplit(b".", 1)
    ^^^^^^^^^^^^^^^^^^^^^^^^^^^^^
ValueError: not enough values to unpack (expected 2, got 1)

During handling of the above exception, another exception occurred:

Traceback (most recent call last):
  File "C:\Users\Kevin\Desktop\KaminariApi\venv\Lib\site-packages\jose\jwt.py", line 142, in decode
    payload = jws.verify(token, key, algorithms, verify=verify_signature)
              ^^^^^^^^^^^^^^^^^^^^^^^^^^^^^^^^^^^^^^^^^^^^^^^^^^^^^^^^^^^
  File "C:\Users\Kevin\Desktop\KaminariApi\venv\Lib\site-packages\jose\jws.py", line 70, in verify
    header, payload, signing_input, signature = _load(token)
                                                ^^^^^^^^^^^^
  File "C:\Users\Kevin\Desktop\KaminariApi\venv\Lib\site-packages\jose\jws.py", line 180, in _load
    raise JWSError("Not enough segments")
jose.exceptions.JWSError: Not enough segments

During handling of the above exception, another exception occurred:

Traceback (most recent call last):
  File "C:\Users\Kevin\Desktop\KaminariApi\app\src\utils\jwtUtils.py", line 51, in decodeToken
    return decode(
           ^^^^^^^
  File "C:\Users\Kevin\Desktop\KaminariApi\venv\Lib\site-packages\jose\jwt.py", line 144, in decode
    raise JWTError(e)
jose.exceptions.JWTError: Not enough segments
2024-11-15 15:44:58,405 - ERROR - Excepción capturada: 401: Credenciales inválidas
Traceback (most recent call last):
  File "C:\Users\Kevin\Desktop\KaminariApi\main.py", line 34, in login
    raise HTTPException(
fastapi.exceptions.HTTPException: 401: Credenciales inválidas
2024-11-15 15:46:27,233 - ERROR - Excepción capturada: 401: Credenciales inválidas
Traceback (most recent call last):
  File "C:\Users\Kevin\Desktop\KaminariApi\main.py", line 34, in login
    raise HTTPException(
fastapi.exceptions.HTTPException: 401: Credenciales inválidas
2024-11-15 15:46:31,684 - ERROR - Excepción capturada: Not enough segments
Traceback (most recent call last):
  File "C:\Users\Kevin\Desktop\KaminariApi\venv\Lib\site-packages\jose\jws.py", line 176, in _load
    signing_input, crypto_segment = jwt.rsplit(b".", 1)
    ^^^^^^^^^^^^^^^^^^^^^^^^^^^^^
ValueError: not enough values to unpack (expected 2, got 1)

During handling of the above exception, another exception occurred:

Traceback (most recent call last):
  File "C:\Users\Kevin\Desktop\KaminariApi\venv\Lib\site-packages\jose\jwt.py", line 142, in decode
    payload = jws.verify(token, key, algorithms, verify=verify_signature)
              ^^^^^^^^^^^^^^^^^^^^^^^^^^^^^^^^^^^^^^^^^^^^^^^^^^^^^^^^^^^
  File "C:\Users\Kevin\Desktop\KaminariApi\venv\Lib\site-packages\jose\jws.py", line 70, in verify
    header, payload, signing_input, signature = _load(token)
                                                ^^^^^^^^^^^^
  File "C:\Users\Kevin\Desktop\KaminariApi\venv\Lib\site-packages\jose\jws.py", line 180, in _load
    raise JWSError("Not enough segments")
jose.exceptions.JWSError: Not enough segments

During handling of the above exception, another exception occurred:

Traceback (most recent call last):
  File "C:\Users\Kevin\Desktop\KaminariApi\app\src\utils\jwtUtils.py", line 51, in decodeToken
    return decode(
           ^^^^^^^
  File "C:\Users\Kevin\Desktop\KaminariApi\venv\Lib\site-packages\jose\jwt.py", line 144, in decode
    raise JWTError(e)
jose.exceptions.JWTError: Not enough segments
2024-11-15 15:47:50,045 - ERROR - Excepción capturada: 401: Credenciales inválidas
Traceback (most recent call last):
  File "C:\Users\Kevin\Desktop\KaminariApi\main.py", line 34, in login
    raise HTTPException(
fastapi.exceptions.HTTPException: 401: Credenciales inválidas
2024-11-15 15:47:57,890 - ERROR - Excepción capturada: Not enough segments
Traceback (most recent call last):
  File "C:\Users\Kevin\Desktop\KaminariApi\venv\Lib\site-packages\jose\jws.py", line 176, in _load
    signing_input, crypto_segment = jwt.rsplit(b".", 1)
    ^^^^^^^^^^^^^^^^^^^^^^^^^^^^^
ValueError: not enough values to unpack (expected 2, got 1)

During handling of the above exception, another exception occurred:

Traceback (most recent call last):
  File "C:\Users\Kevin\Desktop\KaminariApi\venv\Lib\site-packages\jose\jwt.py", line 142, in decode
    payload = jws.verify(token, key, algorithms, verify=verify_signature)
              ^^^^^^^^^^^^^^^^^^^^^^^^^^^^^^^^^^^^^^^^^^^^^^^^^^^^^^^^^^^
  File "C:\Users\Kevin\Desktop\KaminariApi\venv\Lib\site-packages\jose\jws.py", line 70, in verify
    header, payload, signing_input, signature = _load(token)
                                                ^^^^^^^^^^^^
  File "C:\Users\Kevin\Desktop\KaminariApi\venv\Lib\site-packages\jose\jws.py", line 180, in _load
    raise JWSError("Not enough segments")
jose.exceptions.JWSError: Not enough segments

During handling of the above exception, another exception occurred:

Traceback (most recent call last):
  File "C:\Users\Kevin\Desktop\KaminariApi\app\src\utils\jwtUtils.py", line 51, in decodeToken
    return decode(
           ^^^^^^^
  File "C:\Users\Kevin\Desktop\KaminariApi\venv\Lib\site-packages\jose\jwt.py", line 144, in decode
    raise JWTError(e)
jose.exceptions.JWTError: Not enough segments
2024-11-15 15:51:15,419 - ERROR - Excepción capturada: 401: Credenciales inválidas
Traceback (most recent call last):
  File "C:\Users\Kevin\Desktop\KaminariApi\main.py", line 34, in login
    raise HTTPException(
fastapi.exceptions.HTTPException: 401: Credenciales inválidas
2024-11-15 15:51:28,704 - ERROR - Excepción capturada: Not enough segments
Traceback (most recent call last):
  File "C:\Users\Kevin\Desktop\KaminariApi\venv\Lib\site-packages\jose\jws.py", line 176, in _load
    signing_input, crypto_segment = jwt.rsplit(b".", 1)
    ^^^^^^^^^^^^^^^^^^^^^^^^^^^^^
ValueError: not enough values to unpack (expected 2, got 1)

During handling of the above exception, another exception occurred:

Traceback (most recent call last):
  File "C:\Users\Kevin\Desktop\KaminariApi\venv\Lib\site-packages\jose\jwt.py", line 142, in decode
    payload = jws.verify(token, key, algorithms, verify=verify_signature)
              ^^^^^^^^^^^^^^^^^^^^^^^^^^^^^^^^^^^^^^^^^^^^^^^^^^^^^^^^^^^
  File "C:\Users\Kevin\Desktop\KaminariApi\venv\Lib\site-packages\jose\jws.py", line 70, in verify
    header, payload, signing_input, signature = _load(token)
                                                ^^^^^^^^^^^^
  File "C:\Users\Kevin\Desktop\KaminariApi\venv\Lib\site-packages\jose\jws.py", line 180, in _load
    raise JWSError("Not enough segments")
jose.exceptions.JWSError: Not enough segments

During handling of the above exception, another exception occurred:

Traceback (most recent call last):
  File "C:\Users\Kevin\Desktop\KaminariApi\app\src\utils\jwtUtils.py", line 51, in decodeToken
    return decode(
           ^^^^^^^
  File "C:\Users\Kevin\Desktop\KaminariApi\venv\Lib\site-packages\jose\jwt.py", line 144, in decode
    raise JWTError(e)
jose.exceptions.JWTError: Not enough segments
2024-11-15 15:54:04,087 - ERROR - Excepción capturada: 401: Credenciales inválidas
Traceback (most recent call last):
  File "C:\Users\Kevin\Desktop\KaminariApi\main.py", line 34, in login
    raise HTTPException(
fastapi.exceptions.HTTPException: 401: Credenciales inválidas
2024-11-15 15:55:12,610 - ERROR - Excepción capturada: 401: Credenciales inválidas
Traceback (most recent call last):
  File "C:\Users\Kevin\Desktop\KaminariApi\main.py", line 34, in login
    raise HTTPException(
fastapi.exceptions.HTTPException: 401: Credenciales inválidas
2024-11-15 17:19:28,612 - ERROR - Excepción capturada: 401: Credenciales inválidas
Traceback (most recent call last):
  File "C:\Users\Kevin\Desktop\KaminariApi\main.py", line 36, in login
    raise HTTPException(
fastapi.exceptions.HTTPException: 401: Credenciales inválidas
2024-11-15 17:19:50,363 - ERROR - Excepción capturada: 'Cliente' object is not subscriptable
Traceback (most recent call last):
  File "C:\Users\Kevin\Desktop\KaminariApi\app\src\schemas\cliente.py", line 120, in consultarClienteInDb
    datosRequired = {'id': cliente['id'], 'username': cliente['username'], 'pwd': cliente['pwd']}
                           ~~~~~~~^^^^^^
TypeError: 'Cliente' object is not subscriptable
2024-11-15 17:19:50,366 - ERROR - Excepción capturada: string indices must be integers, not 'str'
Traceback (most recent call last):
  File "C:\Users\Kevin\Desktop\KaminariApi\main.py", line 33, in login
    if not userInDb or form_data.password != userInDb['pwd']:
                                             ~~~~~~~~^^^^^^^
TypeError: string indices must be integers, not 'str'
2024-11-15 17:37:30,793 - ERROR - Excepción capturada: 401: Credenciales inválidas
Traceback (most recent call last):
  File "C:\Users\Kevin\Desktop\KaminariApi\main.py", line 36, in login
    raise HTTPException(
fastapi.exceptions.HTTPException: 401: Credenciales inválidas
2024-11-15 17:38:09,851 - ERROR - Excepción capturada: 'Cliente' object is not subscriptable
Traceback (most recent call last):
  File "C:\Users\Kevin\Desktop\KaminariApi\app\src\schemas\cliente.py", line 120, in consultarClienteInDb
    datosRequired = {'id': cliente['id'], 'username': cliente['username'], 'pwd': cliente['pwd']}
                           ~~~~~~~^^^^^^
TypeError: 'Cliente' object is not subscriptable
2024-11-15 17:38:09,854 - ERROR - Excepción capturada: 401: Credenciales inválidas
Traceback (most recent call last):
  File "C:\Users\Kevin\Desktop\KaminariApi\main.py", line 36, in login
    raise HTTPException(
fastapi.exceptions.HTTPException: 401: Credenciales inválidas
2024-11-15 17:39:07,003 - ERROR - Excepción capturada: 'Cliente' object is not subscriptable
Traceback (most recent call last):
  File "C:\Users\Kevin\Desktop\KaminariApi\app\src\schemas\cliente.py", line 120, in consultarClienteInDb
    datosRequired = {'id': cliente['id'], 'username': cliente['username'], 'pwd': cliente['pwd']}
                           ~~~~~~~^^^^^^
TypeError: 'Cliente' object is not subscriptable
2024-11-15 17:39:07,006 - ERROR - Excepción capturada: 401: Credenciales inválidas
Traceback (most recent call last):
  File "C:\Users\Kevin\Desktop\KaminariApi\main.py", line 36, in login
    raise HTTPException(
fastapi.exceptions.HTTPException: 401: Credenciales inválidas
2024-11-16 19:19:26,507 - ERROR - Excepción capturada: GetProducto.__init__() got an unexpected keyword argument 'session'
Traceback (most recent call last):
  File "C:\Users\Kevin\Desktop\KaminariApi\app\src\schemas\producto.py", line 72, in crearGetProducto
    producto: GetProducto = GetProducto(session=session, id=id)
                            ^^^^^^^^^^^^^^^^^^^^^^^^^^^^^^^^^^^
TypeError: GetProducto.__init__() got an unexpected keyword argument 'session'
2024-11-17 19:44:33,926 - ERROR - Excepción capturada: 401: Credenciales inválidas
Traceback (most recent call last):
  File "C:\Users\Kevin\Desktop\KaminariApi\main.py", line 39, in login
    raise HTTPException(
fastapi.exceptions.HTTPException: 401: Credenciales inválidas
2024-11-17 19:45:07,255 - ERROR - Excepción capturada: 401: Credenciales inválidas
Traceback (most recent call last):
  File "C:\Users\Kevin\Desktop\KaminariApi\main.py", line 39, in login
    raise HTTPException(
fastapi.exceptions.HTTPException: 401: Credenciales inválidas
2024-11-17 19:47:38,524 - ERROR - Excepción capturada: 'int' object has no attribute 'value'
Traceback (most recent call last):
  File "C:\Users\Kevin\Desktop\KaminariApi\app\oauthJWT\encodeJwt.py", line 15, in encodeTheStr
    expiration = datetime.now(timezone.utc) + timedelta(minutes=InfomacionToEncodear.EXPIRETOKEN.value)
                                                                ^^^^^^^^^^^^^^^^^^^^^^^^^^^^^^^^^^^^^^
AttributeError: 'int' object has no attribute 'value'
2024-11-17 19:47:43,610 - ERROR - Excepción capturada: 'str' object has no attribute 'value'
Traceback (most recent call last):
  File "C:\Users\Kevin\Desktop\KaminariApi\app\oauthJWT\decodeJwt.py", line 24, in decodeToken
    key=InfomacionToEncodear.SECRETKEY.value,
        ^^^^^^^^^^^^^^^^^^^^^^^^^^^^^^^^^^^^
AttributeError: 'str' object has no attribute 'value'
2024-11-17 19:47:56,803 - ERROR - Excepción capturada: 401: Credenciales inválidas
Traceback (most recent call last):
  File "C:\Users\Kevin\Desktop\KaminariApi\main.py", line 39, in login
    raise HTTPException(
fastapi.exceptions.HTTPException: 401: Credenciales inválidas
2024-11-17 19:48:55,409 - ERROR - Excepción capturada: 'int' object has no attribute 'value'
Traceback (most recent call last):
  File "C:\Users\Kevin\Desktop\KaminariApi\app\oauthJWT\encodeJwt.py", line 15, in encodeTheStr
    expiration = datetime.now(timezone.utc) + timedelta(minutes=InfomacionToEncodear.EXPIRETOKEN.value)
                                                                ^^^^^^^^^^^^^^^^^^^^^^^^^^^^^^^^^^^^^^
AttributeError: 'int' object has no attribute 'value'
2024-11-17 19:48:58,435 - ERROR - Excepción capturada: 'str' object has no attribute 'value'
Traceback (most recent call last):
  File "C:\Users\Kevin\Desktop\KaminariApi\app\oauthJWT\decodeJwt.py", line 24, in decodeToken
    key=InfomacionToEncodear.SECRETKEY.value,
        ^^^^^^^^^^^^^^^^^^^^^^^^^^^^^^^^^^^^
AttributeError: 'str' object has no attribute 'value'
2024-11-17 20:04:37,059 - ERROR - Excepción capturada: 401: Credenciales inválidas
Traceback (most recent call last):
  File "C:\Users\Kevin\Desktop\KaminariApi\main.py", line 39, in login
    raise HTTPException(
fastapi.exceptions.HTTPException: 401: Credenciales inválidas
2024-11-18 00:10:28,889 - ERROR - Excepción capturada: 'ClienteHandler' object has no attribute 'conexionDb'
Traceback (most recent call last):
  File "C:\Users\Kevin\Desktop\KaminariApi\app\src\models\usuarioModels\contollerUsuario.py", line 29, in consultarClienteInDb
    session = self.conexionDb.abrirConexion()
              ^^^^^^^^^^^^^^^
AttributeError: 'ClienteHandler' object has no attribute 'conexionDb'
2024-11-18 00:10:28,896 - ERROR - Excepción capturada: 401: Credenciales inválidas
Traceback (most recent call last):
  File "C:\Users\Kevin\Desktop\KaminariApi\main.py", line 39, in login
    raise HTTPException(
fastapi.exceptions.HTTPException: 401: Credenciales inválidas
2024-11-18 00:10:55,657 - ERROR - Excepción capturada: 'ClienteHandler' object has no attribute 'conexionDb'
Traceback (most recent call last):
  File "C:\Users\Kevin\Desktop\KaminariApi\app\src\models\usuarioModels\contollerUsuario.py", line 29, in consultarClienteInDb
    session = self.conexionDb.abrirConexion()
              ^^^^^^^^^^^^^^^
AttributeError: 'ClienteHandler' object has no attribute 'conexionDb'
2024-11-18 00:10:55,661 - ERROR - Excepción capturada: 401: Credenciales inválidas
Traceback (most recent call last):
  File "C:\Users\Kevin\Desktop\KaminariApi\main.py", line 39, in login
    raise HTTPException(
fastapi.exceptions.HTTPException: 401: Credenciales inválidas
2024-11-18 00:12:14,213 - ERROR - Excepción capturada: 'ClienteHandler' object has no attribute 'consultarClienteInDb'
Traceback (most recent call last):
  File "C:\Users\Kevin\Desktop\KaminariApi\main.py", line 35, in login
    userInDb = ClienteHandler().consultarClienteInDb(username=form_data.username, pwd=form_data.password)
               ^^^^^^^^^^^^^^^^^^^^^^^^^^^^^^^^^^^^^
AttributeError: 'ClienteHandler' object has no attribute 'consultarClienteInDb'
2024-11-18 00:13:01,523 - ERROR - Excepción capturada: 'ClienteHandler' object has no attribute 'consultarClienteInDb'
Traceback (most recent call last):
  File "C:\Users\Kevin\Desktop\KaminariApi\main.py", line 35, in login
    userInDb = ClienteHandler().consultarClienteInDb(username=form_data.username, pwd=form_data.password)
               ^^^^^^^^^^^^^^^^^^^^^^^^^^^^^^^^^^^^^
AttributeError: 'ClienteHandler' object has no attribute 'consultarClienteInDb'
2024-11-18 00:16:33,993 - ERROR - Excepción capturada: 'ClienteHandler' object has no attribute 'consultarClienteInDb'
Traceback (most recent call last):
  File "C:\Users\Kevin\Desktop\KaminariApi\main.py", line 35, in login
    userInDb = ClienteHandler().consultarClienteInDb(username=form_data.username, pwd=form_data.password)
               ^^^^^^^^^^^^^^^^^^^^^^^^^^^^^^^^^^^^^
AttributeError: 'ClienteHandler' object has no attribute 'consultarClienteInDb'
2024-11-18 00:17:47,762 - ERROR - Excepción capturada: 'ClienteHandler' object has no attribute 'consultarClienteInDb'
Traceback (most recent call last):
  File "C:\Users\Kevin\Desktop\KaminariApi\main.py", line 35, in login
    userInDb = ClienteHandler().consultarClienteInDb(username=form_data.username, pwd=form_data.password)
               ^^^^^^^^^^^^^^^^^^^^^^^^^^^^^^^^^^^^^
AttributeError: 'ClienteHandler' object has no attribute 'consultarClienteInDb'
2024-11-18 00:18:34,605 - ERROR - Excepción capturada: 'ClienteHandler' object has no attribute 'consultarClienteInDb'
Traceback (most recent call last):
  File "C:\Users\Kevin\Desktop\KaminariApi\main.py", line 35, in login
    userInDb = ClienteHandler().consultarClienteInDb(username=form_data.username, pwd=form_data.password)
               ^^^^^^^^^^^^^^^^^^^^^^^^^^^^^^^^^^^^^
AttributeError: 'ClienteHandler' object has no attribute 'consultarClienteInDb'
2024-11-18 00:21:22,740 - ERROR - Excepción capturada: 'Cliente' object is not subscriptable
Traceback (most recent call last):
  File "C:\Users\Kevin\Desktop\KaminariApi\main.py", line 36, in login
    if not userInDb or form_data.password != userInDb['pwd']:
                                             ~~~~~~~~^^^^^^^
TypeError: 'Cliente' object is not subscriptable
2024-11-18 00:22:13,698 - ERROR - Excepción capturada: 'Cliente' object is not subscriptable
Traceback (most recent call last):
  File "C:\Users\Kevin\Desktop\KaminariApi\main.py", line 37, in login
    if not userInDb or form_data.password != userInDb['pwd']:
                                             ~~~~~~~~^^^^^^^
TypeError: 'Cliente' object is not subscriptable
2024-11-18 00:24:37,554 - ERROR - Excepción capturada: Instance <Cliente at 0x1f843ac4560> is not bound to a Session; attribute refresh operation cannot proceed (Background on this error at: https://sqlalche.me/e/20/bhk3)
Traceback (most recent call last):
  File "C:\Users\Kevin\Desktop\KaminariApi\main.py", line 37, in login
    if not userInDb or form_data.password != userInDb.pwd:
                                             ^^^^^^^^^^^^
  File "C:\Users\Kevin\Desktop\KaminariApi\venv\Lib\site-packages\sqlalchemy\orm\attributes.py", line 566, in __get__
    return self.impl.get(state, dict_)  # type: ignore[no-any-return]
           ^^^^^^^^^^^^^^^^^^^^^^^^^^^
  File "C:\Users\Kevin\Desktop\KaminariApi\venv\Lib\site-packages\sqlalchemy\orm\attributes.py", line 1086, in get
    value = self._fire_loader_callables(state, key, passive)
            ^^^^^^^^^^^^^^^^^^^^^^^^^^^^^^^^^^^^^^^^^^^^^^^^
  File "C:\Users\Kevin\Desktop\KaminariApi\venv\Lib\site-packages\sqlalchemy\orm\attributes.py", line 1116, in _fire_loader_callables
    return state._load_expired(state, passive)
           ^^^^^^^^^^^^^^^^^^^^^^^^^^^^^^^^^^^
  File "C:\Users\Kevin\Desktop\KaminariApi\venv\Lib\site-packages\sqlalchemy\orm\state.py", line 803, in _load_expired
    self.manager.expired_attribute_loader(self, toload, passive)
  File "C:\Users\Kevin\Desktop\KaminariApi\venv\Lib\site-packages\sqlalchemy\orm\loading.py", line 1603, in load_scalar_attributes
    raise orm_exc.DetachedInstanceError(
sqlalchemy.orm.exc.DetachedInstanceError: Instance <Cliente at 0x1f843ac4560> is not bound to a Session; attribute refresh operation cannot proceed (Background on this error at: https://sqlalche.me/e/20/bhk3)
2024-11-18 00:26:33,108 - ERROR - Excepción capturada: Instance <Cliente at 0x1b416fe6b40> is not bound to a Session; attribute refresh operation cannot proceed (Background on this error at: https://sqlalche.me/e/20/bhk3)
Traceback (most recent call last):
  File "C:\Users\Kevin\Desktop\KaminariApi\main.py", line 36, in login
    print(userInDb.id, userInDb.username,'dsssssssssssssssssss')
          ^^^^^^^^^^^
  File "C:\Users\Kevin\Desktop\KaminariApi\venv\Lib\site-packages\sqlalchemy\orm\attributes.py", line 566, in __get__
    return self.impl.get(state, dict_)  # type: ignore[no-any-return]
           ^^^^^^^^^^^^^^^^^^^^^^^^^^^
  File "C:\Users\Kevin\Desktop\KaminariApi\venv\Lib\site-packages\sqlalchemy\orm\attributes.py", line 1086, in get
    value = self._fire_loader_callables(state, key, passive)
            ^^^^^^^^^^^^^^^^^^^^^^^^^^^^^^^^^^^^^^^^^^^^^^^^
  File "C:\Users\Kevin\Desktop\KaminariApi\venv\Lib\site-packages\sqlalchemy\orm\attributes.py", line 1116, in _fire_loader_callables
    return state._load_expired(state, passive)
           ^^^^^^^^^^^^^^^^^^^^^^^^^^^^^^^^^^^
  File "C:\Users\Kevin\Desktop\KaminariApi\venv\Lib\site-packages\sqlalchemy\orm\state.py", line 803, in _load_expired
    self.manager.expired_attribute_loader(self, toload, passive)
  File "C:\Users\Kevin\Desktop\KaminariApi\venv\Lib\site-packages\sqlalchemy\orm\loading.py", line 1603, in load_scalar_attributes
    raise orm_exc.DetachedInstanceError(
sqlalchemy.orm.exc.DetachedInstanceError: Instance <Cliente at 0x1b416fe6b40> is not bound to a Session; attribute refresh operation cannot proceed (Background on this error at: https://sqlalche.me/e/20/bhk3)
2024-11-18 00:35:53,832 - ERROR - Excepción capturada: Instance <Cliente at 0x233d688e9c0> is not bound to a Session; attribute refresh operation cannot proceed (Background on this error at: https://sqlalche.me/e/20/bhk3)
Traceback (most recent call last):
  File "C:\Users\Kevin\Desktop\KaminariApi\app\src\models\usuarioModels\consultarUsuario.py", line 20, in consultarCliente
    return cliente.id
           ^^^^^^^^^^
  File "C:\Users\Kevin\Desktop\KaminariApi\venv\Lib\site-packages\sqlalchemy\orm\attributes.py", line 566, in __get__
    return self.impl.get(state, dict_)  # type: ignore[no-any-return]
           ^^^^^^^^^^^^^^^^^^^^^^^^^^^
  File "C:\Users\Kevin\Desktop\KaminariApi\venv\Lib\site-packages\sqlalchemy\orm\attributes.py", line 1086, in get
    value = self._fire_loader_callables(state, key, passive)
            ^^^^^^^^^^^^^^^^^^^^^^^^^^^^^^^^^^^^^^^^^^^^^^^^
  File "C:\Users\Kevin\Desktop\KaminariApi\venv\Lib\site-packages\sqlalchemy\orm\attributes.py", line 1116, in _fire_loader_callables
    return state._load_expired(state, passive)
           ^^^^^^^^^^^^^^^^^^^^^^^^^^^^^^^^^^^
  File "C:\Users\Kevin\Desktop\KaminariApi\venv\Lib\site-packages\sqlalchemy\orm\state.py", line 803, in _load_expired
    self.manager.expired_attribute_loader(self, toload, passive)
  File "C:\Users\Kevin\Desktop\KaminariApi\venv\Lib\site-packages\sqlalchemy\orm\loading.py", line 1603, in load_scalar_attributes
    raise orm_exc.DetachedInstanceError(
sqlalchemy.orm.exc.DetachedInstanceError: Instance <Cliente at 0x233d688e9c0> is not bound to a Session; attribute refresh operation cannot proceed (Background on this error at: https://sqlalche.me/e/20/bhk3)
2024-11-18 00:36:08,949 - ERROR - Excepción capturada: Instance <Cliente at 0x2a591f8ea50> is not bound to a Session; attribute refresh operation cannot proceed (Background on this error at: https://sqlalche.me/e/20/bhk3)
Traceback (most recent call last):
  File "C:\Users\Kevin\Desktop\KaminariApi\app\src\models\usuarioModels\consultarUsuario.py", line 20, in consultarCliente
    return cliente.id
           ^^^^^^^^^^
  File "C:\Users\Kevin\Desktop\KaminariApi\venv\Lib\site-packages\sqlalchemy\orm\attributes.py", line 566, in __get__
    return self.impl.get(state, dict_)  # type: ignore[no-any-return]
           ^^^^^^^^^^^^^^^^^^^^^^^^^^^
  File "C:\Users\Kevin\Desktop\KaminariApi\venv\Lib\site-packages\sqlalchemy\orm\attributes.py", line 1086, in get
    value = self._fire_loader_callables(state, key, passive)
            ^^^^^^^^^^^^^^^^^^^^^^^^^^^^^^^^^^^^^^^^^^^^^^^^
  File "C:\Users\Kevin\Desktop\KaminariApi\venv\Lib\site-packages\sqlalchemy\orm\attributes.py", line 1116, in _fire_loader_callables
    return state._load_expired(state, passive)
           ^^^^^^^^^^^^^^^^^^^^^^^^^^^^^^^^^^^
  File "C:\Users\Kevin\Desktop\KaminariApi\venv\Lib\site-packages\sqlalchemy\orm\state.py", line 803, in _load_expired
    self.manager.expired_attribute_loader(self, toload, passive)
  File "C:\Users\Kevin\Desktop\KaminariApi\venv\Lib\site-packages\sqlalchemy\orm\loading.py", line 1603, in load_scalar_attributes
    raise orm_exc.DetachedInstanceError(
sqlalchemy.orm.exc.DetachedInstanceError: Instance <Cliente at 0x2a591f8ea50> is not bound to a Session; attribute refresh operation cannot proceed (Background on this error at: https://sqlalche.me/e/20/bhk3)
2024-11-18 12:48:50,593 - ERROR - Excepción capturada: 'Cliente' object is not subscriptable
Traceback (most recent call last):
  File "C:\Users\Kevin\Desktop\KaminariApi\main.py", line 37, in login
    if not userInDb or form_data.password != userInDb['pwd']:
                                             ~~~~~~~~^^^^^^^
TypeError: 'Cliente' object is not subscriptable
2024-11-18 12:50:19,052 - ERROR - Excepción capturada: 'int' object has no attribute 'value'
Traceback (most recent call last):
  File "C:\Users\Kevin\Desktop\KaminariApi\app\oauthJWT\encodeJwt.py", line 15, in encodeTheStr
    expiration = datetime.now(timezone.utc) + timedelta(minutes=InfomacionToEncodear.EXPIRETOKEN.value)
                                                                ^^^^^^^^^^^^^^^^^^^^^^^^^^^^^^^^^^^^^^
AttributeError: 'int' object has no attribute 'value'
2024-11-18 12:50:23,500 - ERROR - Excepción capturada: Not enough segments
Traceback (most recent call last):
  File "C:\Users\Kevin\Desktop\KaminariApi\venv\Lib\site-packages\jose\jws.py", line 176, in _load
    signing_input, crypto_segment = jwt.rsplit(b".", 1)
    ^^^^^^^^^^^^^^^^^^^^^^^^^^^^^
ValueError: not enough values to unpack (expected 2, got 1)

During handling of the above exception, another exception occurred:

Traceback (most recent call last):
  File "C:\Users\Kevin\Desktop\KaminariApi\venv\Lib\site-packages\jose\jwt.py", line 142, in decode
    payload = jws.verify(token, key, algorithms, verify=verify_signature)
              ^^^^^^^^^^^^^^^^^^^^^^^^^^^^^^^^^^^^^^^^^^^^^^^^^^^^^^^^^^^
  File "C:\Users\Kevin\Desktop\KaminariApi\venv\Lib\site-packages\jose\jws.py", line 70, in verify
    header, payload, signing_input, signature = _load(token)
                                                ^^^^^^^^^^^^
  File "C:\Users\Kevin\Desktop\KaminariApi\venv\Lib\site-packages\jose\jws.py", line 180, in _load
    raise JWSError("Not enough segments")
jose.exceptions.JWSError: Not enough segments

During handling of the above exception, another exception occurred:

Traceback (most recent call last):
  File "C:\Users\Kevin\Desktop\KaminariApi\app\oauthJWT\decodeJwt.py", line 22, in decodeToken
    return decode(
           ^^^^^^^
  File "C:\Users\Kevin\Desktop\KaminariApi\venv\Lib\site-packages\jose\jwt.py", line 144, in decode
    raise JWTError(e)
jose.exceptions.JWTError: Not enough segments
2024-11-18 13:29:34,561 - ERROR - Excepción capturada: Session.delete() got an unexpected keyword argument 'synchronize_session'
Traceback (most recent call last):
  File "C:\Users\Kevin\Desktop\KaminariApi\app\src\models\usuarioModels\deleteUsuario.py", line 14, in deleteCliente
    session.delete(clientToDelete, synchronize_session=False)
TypeError: Session.delete() got an unexpected keyword argument 'synchronize_session'
2024-11-21 14:05:39,688 - ERROR - Excepción capturada: 401: Credenciales inválidas
Traceback (most recent call last):
  File "C:\Users\Kevin\Desktop\KaminariApi\main.py", line 45, in login
    raise HTTPException(
fastapi.exceptions.HTTPException: 401: Credenciales inválidas
2024-11-21 14:13:13,934 - ERROR - Excepción capturada: 401: Credenciales inválidas
Traceback (most recent call last):
  File "C:\Users\Kevin\Desktop\KaminariApi\main.py", line 45, in login
    raise HTTPException(
fastapi.exceptions.HTTPException: 401: Credenciales inválidas
2024-11-21 15:03:24,124 - ERROR - Excepción capturada: Class 'builtins.int' is not mapped
Traceback (most recent call last):
  File "C:\Users\Kevin\Desktop\KaminariApi\venv\Lib\site-packages\sqlalchemy\orm\session.py", line 3534, in delete
    state = attributes.instance_state(instance)
            ^^^^^^^^^^^^^^^^^^^^^^^^^^^^^^^^^^^
AttributeError: 'int' object has no attribute '_sa_instance_state'

The above exception was the direct cause of the following exception:

Traceback (most recent call last):
  File "C:\Users\Kevin\Desktop\KaminariApi\app\src\models\productoModels\deleteProducto.py", line 15, in eliminarProducto
    session.delete(producto)
  File "C:\Users\Kevin\Desktop\KaminariApi\venv\Lib\site-packages\sqlalchemy\orm\session.py", line 3536, in delete
    raise exc.UnmappedInstanceError(instance) from err
sqlalchemy.orm.exc.UnmappedInstanceError: Class 'builtins.int' is not mapped
2024-11-21 15:06:06,103 - ERROR - Excepción capturada: Class 'builtins.int' is not mapped
Traceback (most recent call last):
  File "C:\Users\Kevin\Desktop\KaminariApi\venv\Lib\site-packages\sqlalchemy\orm\session.py", line 3534, in delete
    state = attributes.instance_state(instance)
            ^^^^^^^^^^^^^^^^^^^^^^^^^^^^^^^^^^^
AttributeError: 'int' object has no attribute '_sa_instance_state'

The above exception was the direct cause of the following exception:

Traceback (most recent call last):
  File "C:\Users\Kevin\Desktop\KaminariApi\app\src\models\productoModels\deleteProducto.py", line 15, in eliminarProducto
    session.delete(producto)
  File "C:\Users\Kevin\Desktop\KaminariApi\venv\Lib\site-packages\sqlalchemy\orm\session.py", line 3536, in delete
    raise exc.UnmappedInstanceError(instance) from err
sqlalchemy.orm.exc.UnmappedInstanceError: Class 'builtins.int' is not mapped
2024-11-21 15:06:52,659 - ERROR - Excepción capturada: Class 'sqlalchemy.orm.query.Query' is not mapped
Traceback (most recent call last):
  File "C:\Users\Kevin\Desktop\KaminariApi\venv\Lib\site-packages\sqlalchemy\orm\session.py", line 3534, in delete
    state = attributes.instance_state(instance)
            ^^^^^^^^^^^^^^^^^^^^^^^^^^^^^^^^^^^
AttributeError: 'Query' object has no attribute '_sa_instance_state'

The above exception was the direct cause of the following exception:

Traceback (most recent call last):
  File "C:\Users\Kevin\Desktop\KaminariApi\app\src\models\productoModels\deleteProducto.py", line 15, in eliminarProducto
    session.delete(producto)
  File "C:\Users\Kevin\Desktop\KaminariApi\venv\Lib\site-packages\sqlalchemy\orm\session.py", line 3536, in delete
    raise exc.UnmappedInstanceError(instance) from err
sqlalchemy.orm.exc.UnmappedInstanceError: Class 'sqlalchemy.orm.query.Query' is not mapped
2024-11-21 15:12:06,097 - ERROR - Excepción capturada: Class 'sqlalchemy.orm.query.Query' is not mapped
Traceback (most recent call last):
  File "C:\Users\Kevin\Desktop\KaminariApi\venv\Lib\site-packages\sqlalchemy\orm\session.py", line 3534, in delete
    state = attributes.instance_state(instance)
            ^^^^^^^^^^^^^^^^^^^^^^^^^^^^^^^^^^^
AttributeError: 'Query' object has no attribute '_sa_instance_state'

The above exception was the direct cause of the following exception:

Traceback (most recent call last):
  File "C:\Users\Kevin\Desktop\KaminariApi\app\src\models\productoModels\deleteProducto.py", line 15, in eliminarProducto
    session.delete(productoVariante)
  File "C:\Users\Kevin\Desktop\KaminariApi\venv\Lib\site-packages\sqlalchemy\orm\session.py", line 3536, in delete
    raise exc.UnmappedInstanceError(instance) from err
sqlalchemy.orm.exc.UnmappedInstanceError: Class 'sqlalchemy.orm.query.Query' is not mapped
2024-11-21 15:13:00,190 - ERROR - Excepción capturada: Class 'builtins.list' is not mapped
Traceback (most recent call last):
  File "C:\Users\Kevin\Desktop\KaminariApi\venv\Lib\site-packages\sqlalchemy\orm\session.py", line 3534, in delete
    state = attributes.instance_state(instance)
            ^^^^^^^^^^^^^^^^^^^^^^^^^^^^^^^^^^^
AttributeError: 'list' object has no attribute '_sa_instance_state'

The above exception was the direct cause of the following exception:

Traceback (most recent call last):
  File "C:\Users\Kevin\Desktop\KaminariApi\app\src\models\productoModels\deleteProducto.py", line 15, in eliminarProducto
    session.delete(productoVariante)
  File "C:\Users\Kevin\Desktop\KaminariApi\venv\Lib\site-packages\sqlalchemy\orm\session.py", line 3536, in delete
    raise exc.UnmappedInstanceError(instance) from err
sqlalchemy.orm.exc.UnmappedInstanceError: Class 'builtins.list' is not mapped
2024-11-22 10:46:22,992 - ERROR - Excepción capturada: For many-to-one relationship ProductoIndumentariaVariante.producto, delete-orphan cascade is normally configured only on the "one" side of a one-to-many relationship, and not on the "many" side of a many-to-one or many-to-many relationship.  To force this relationship to allow a particular "ProductoIndumentaria" object to be referenced by only a single "ProductoIndumentariaVariante" object at a time via the ProductoIndumentariaVariante.producto relationship, which would allow delete-orphan cascade to take place in this direction, set the single_parent=True flag. (Background on this error at: https://sqlalche.me/e/20/bbf0)
Traceback (most recent call last):
  File "C:\Users\Kevin\Desktop\KaminariApi\app\src\models\productoModels\deleteProducto.py", line 14, in eliminarProducto
    producto = session.query(ProductoIndumentaria).filter_by(id=idProducto).first()
               ^^^^^^^^^^^^^^^^^^^^^^^^^^^^^^^^^^^
  File "C:\Users\Kevin\Desktop\KaminariApi\venv\Lib\site-packages\sqlalchemy\orm\session.py", line 2952, in query
    return self._query_cls(entities, self, **kwargs)
           ^^^^^^^^^^^^^^^^^^^^^^^^^^^^^^^^^^^^^^^^^
  File "C:\Users\Kevin\Desktop\KaminariApi\venv\Lib\site-packages\sqlalchemy\orm\query.py", line 275, in __init__
    self._set_entities(entities)
  File "C:\Users\Kevin\Desktop\KaminariApi\venv\Lib\site-packages\sqlalchemy\orm\query.py", line 288, in _set_entities
    coercions.expect(
  File "C:\Users\Kevin\Desktop\KaminariApi\venv\Lib\site-packages\sqlalchemy\sql\coercions.py", line 388, in expect
    insp._post_inspect
  File "C:\Users\Kevin\Desktop\KaminariApi\venv\Lib\site-packages\sqlalchemy\util\langhelpers.py", line 1253, in __get__
    obj.__dict__[self.__name__] = result = self.fget(obj)
                                           ^^^^^^^^^^^^^^
  File "C:\Users\Kevin\Desktop\KaminariApi\venv\Lib\site-packages\sqlalchemy\orm\mapper.py", line 2722, in _post_inspect
    self._check_configure()
  File "C:\Users\Kevin\Desktop\KaminariApi\venv\Lib\site-packages\sqlalchemy\orm\mapper.py", line 2399, in _check_configure
    _configure_registries({self.registry}, cascade=True)
  File "C:\Users\Kevin\Desktop\KaminariApi\venv\Lib\site-packages\sqlalchemy\orm\mapper.py", line 4215, in _configure_registries
    _do_configure_registries(registries, cascade)
  File "C:\Users\Kevin\Desktop\KaminariApi\venv\Lib\site-packages\sqlalchemy\orm\mapper.py", line 4256, in _do_configure_registries
    mapper._post_configure_properties()
  File "C:\Users\Kevin\Desktop\KaminariApi\venv\Lib\site-packages\sqlalchemy\orm\mapper.py", line 2416, in _post_configure_properties
    prop.init()
  File "C:\Users\Kevin\Desktop\KaminariApi\venv\Lib\site-packages\sqlalchemy\orm\interfaces.py", line 589, in init
    self.do_init()
  File "C:\Users\Kevin\Desktop\KaminariApi\venv\Lib\site-packages\sqlalchemy\orm\relationships.py", line 1645, in do_init
    self._check_cascade_settings(self._cascade)
  File "C:\Users\Kevin\Desktop\KaminariApi\venv\Lib\site-packages\sqlalchemy\orm\relationships.py", line 1988, in _check_cascade_settings
    raise sa_exc.ArgumentError(
sqlalchemy.exc.ArgumentError: For many-to-one relationship ProductoIndumentariaVariante.producto, delete-orphan cascade is normally configured only on the "one" side of a one-to-many relationship, and not on the "many" side of a many-to-one or many-to-many relationship.  To force this relationship to allow a particular "ProductoIndumentaria" object to be referenced by only a single "ProductoIndumentariaVariante" object at a time via the ProductoIndumentariaVariante.producto relationship, which would allow delete-orphan cascade to take place in this direction, set the single_parent=True flag. (Background on this error at: https://sqlalche.me/e/20/bbf0)
2024-11-25 18:48:43,593 - ERROR - Excepción capturada: 'OAuth2PasswordRequestForm' object has no attribute 'pwd'
Traceback (most recent call last):
  File "C:\Users\Kevin\Desktop\KaminariApi\main.py", line 41, in login
    userInDb = ClienteHandler().crearGetClienteInDb().consultarCliente(username=form_data.username.split(), pwd=form_data.pwd)
                                                                                                                ^^^^^^^^^^^^^
AttributeError: 'OAuth2PasswordRequestForm' object has no attribute 'pwd'
2024-11-25 18:49:58,962 - ERROR - Excepción capturada: 'OAuth2PasswordRequestForm' object is not subscriptable
Traceback (most recent call last):
  File "C:\Users\Kevin\Desktop\KaminariApi\main.py", line 41, in login
    userInDb = ClienteHandler().crearGetClienteInDb().consultarCliente(username=form_data['username'], pwd=form_data['pwd'])
                                                                                ~~~~~~~~~^^^^^^^^^^^^
TypeError: 'OAuth2PasswordRequestForm' object is not subscriptable
2024-11-25 18:50:35,109 - ERROR - Excepción capturada: 'OAuth2PasswordRequestForm' object is not subscriptable
Traceback (most recent call last):
  File "C:\Users\Kevin\Desktop\KaminariApi\main.py", line 42, in login
    userInDb = ClienteHandler().crearGetClienteInDb().consultarCliente(username=form_data['username'], pwd=form_data['pwd'])
                                                                                ~~~~~~~~~^^^^^^^^^^^^
TypeError: 'OAuth2PasswordRequestForm' object is not subscriptable
2024-11-25 19:46:08,518 - ERROR - Excepción capturada: 401: Credenciales inválidas
Traceback (most recent call last):
  File "C:\Users\Kevin\Desktop\KaminariApi\main.py", line 45, in login
    raise HTTPException(
fastapi.exceptions.HTTPException: 401: Credenciales inválidas
2024-11-25 19:48:48,767 - ERROR - Excepción capturada: 401: Credenciales inválidas
Traceback (most recent call last):
  File "C:\Users\Kevin\Desktop\KaminariApi\main.py", line 45, in login
    raise HTTPException(
fastapi.exceptions.HTTPException: 401: Credenciales inválidas
2024-11-25 19:49:44,591 - ERROR - Excepción capturada: 401: Credenciales inválidas
Traceback (most recent call last):
  File "C:\Users\Kevin\Desktop\KaminariApi\main.py", line 45, in login
    raise HTTPException(
fastapi.exceptions.HTTPException: 401: Credenciales inválidas
2024-11-25 19:51:31,981 - ERROR - Excepción capturada: 401: Credenciales inválidas
Traceback (most recent call last):
  File "C:\Users\Kevin\Desktop\KaminariApi\main.py", line 45, in login
    raise HTTPException(
fastapi.exceptions.HTTPException: 401: Credenciales inválidas
2024-11-25 19:52:47,770 - ERROR - Excepción capturada: JSONResponse.__init__() got an unexpected keyword argument 'detail'
Traceback (most recent call last):
  File "C:\Users\Kevin\Desktop\KaminariApi\main.py", line 45, in login
    return JSONResponse(
           ^^^^^^^^^^^^^
TypeError: JSONResponse.__init__() got an unexpected keyword argument 'detail'
2024-11-27 12:15:53,909 - ERROR - Excepción capturada: (mysql.connector.errors.IntegrityError) 1062 (23000): Duplicate entry 'kvn@gmail.com' for key 'cliente.email'
[SQL: INSERT INTO `Cliente` (nombre, apellido, username, email, pwd, fecha_registro) VALUES (%(nombre)s, %(apellido)s, %(username)s, %(email)s, %(pwd)s, CURRENT_TIMESTAMP)]
[parameters: {'nombre': 'kevin', 'apellido': 'herrera', 'username': 'kkvn', 'email': 'kvn@gmail.com', 'pwd': 'Hola1234'}]
(Background on this error at: https://sqlalche.me/e/20/gkpj)
Traceback (most recent call last):
  File "C:\Users\Kevin\Desktop\KaminariApi\venv\Lib\site-packages\mysql\connector\connection_cext.py", line 706, in cmd_query
    self._cmysql.query(
_mysql_connector.MySQLInterfaceError: Duplicate entry 'kvn@gmail.com' for key 'cliente.email'

The above exception was the direct cause of the following exception:

Traceback (most recent call last):
  File "C:\Users\Kevin\Desktop\KaminariApi\venv\Lib\site-packages\sqlalchemy\engine\base.py", line 1967, in _exec_single_context
    self.dialect.do_execute(
  File "C:\Users\Kevin\Desktop\KaminariApi\venv\Lib\site-packages\sqlalchemy\engine\default.py", line 941, in do_execute
    cursor.execute(statement, parameters)
  File "C:\Users\Kevin\Desktop\KaminariApi\venv\Lib\site-packages\mysql\connector\cursor_cext.py", line 357, in execute
    result = self._connection.cmd_query(
             ^^^^^^^^^^^^^^^^^^^^^^^^^^^
  File "C:\Users\Kevin\Desktop\KaminariApi\venv\Lib\site-packages\mysql\connector\opentelemetry\context_propagation.py", line 97, in wrapper
    return method(cnx, *args, **kwargs)
           ^^^^^^^^^^^^^^^^^^^^^^^^^^^^
  File "C:\Users\Kevin\Desktop\KaminariApi\venv\Lib\site-packages\mysql\connector\connection_cext.py", line 714, in cmd_query
    raise get_mysql_exception(
mysql.connector.errors.IntegrityError: 1062 (23000): Duplicate entry 'kvn@gmail.com' for key 'cliente.email'

The above exception was the direct cause of the following exception:

Traceback (most recent call last):
  File "C:\Users\Kevin\Desktop\KaminariApi\app\src\models\dbConect.py", line 21, in guardarCambiosDb
    return Session.commit()
           ^^^^^^^^^^^^^^^^
  File "C:\Users\Kevin\Desktop\KaminariApi\venv\Lib\site-packages\sqlalchemy\orm\session.py", line 2028, in commit
    trans.commit(_to_root=True)
  File "<string>", line 2, in commit
  File "C:\Users\Kevin\Desktop\KaminariApi\venv\Lib\site-packages\sqlalchemy\orm\state_changes.py", line 139, in _go
    ret_value = fn(self, *arg, **kw)
                ^^^^^^^^^^^^^^^^^^^^
  File "C:\Users\Kevin\Desktop\KaminariApi\venv\Lib\site-packages\sqlalchemy\orm\session.py", line 1313, in commit
    self._prepare_impl()
  File "<string>", line 2, in _prepare_impl
  File "C:\Users\Kevin\Desktop\KaminariApi\venv\Lib\site-packages\sqlalchemy\orm\state_changes.py", line 139, in _go
    ret_value = fn(self, *arg, **kw)
                ^^^^^^^^^^^^^^^^^^^^
  File "C:\Users\Kevin\Desktop\KaminariApi\venv\Lib\site-packages\sqlalchemy\orm\session.py", line 1288, in _prepare_impl
    self.session.flush()
  File "C:\Users\Kevin\Desktop\KaminariApi\venv\Lib\site-packages\sqlalchemy\orm\session.py", line 4352, in flush
    self._flush(objects)
  File "C:\Users\Kevin\Desktop\KaminariApi\venv\Lib\site-packages\sqlalchemy\orm\session.py", line 4487, in _flush
    with util.safe_reraise():
  File "C:\Users\Kevin\Desktop\KaminariApi\venv\Lib\site-packages\sqlalchemy\util\langhelpers.py", line 146, in __exit__
    raise exc_value.with_traceback(exc_tb)
  File "C:\Users\Kevin\Desktop\KaminariApi\venv\Lib\site-packages\sqlalchemy\orm\session.py", line 4448, in _flush
    flush_context.execute()
  File "C:\Users\Kevin\Desktop\KaminariApi\venv\Lib\site-packages\sqlalchemy\orm\unitofwork.py", line 466, in execute
    rec.execute(self)
  File "C:\Users\Kevin\Desktop\KaminariApi\venv\Lib\site-packages\sqlalchemy\orm\unitofwork.py", line 642, in execute
    util.preloaded.orm_persistence.save_obj(
  File "C:\Users\Kevin\Desktop\KaminariApi\venv\Lib\site-packages\sqlalchemy\orm\persistence.py", line 93, in save_obj
    _emit_insert_statements(
  File "C:\Users\Kevin\Desktop\KaminariApi\venv\Lib\site-packages\sqlalchemy\orm\persistence.py", line 1233, in _emit_insert_statements
    result = connection.execute(
             ^^^^^^^^^^^^^^^^^^^
  File "C:\Users\Kevin\Desktop\KaminariApi\venv\Lib\site-packages\sqlalchemy\engine\base.py", line 1418, in execute
    return meth(
           ^^^^^
  File "C:\Users\Kevin\Desktop\KaminariApi\venv\Lib\site-packages\sqlalchemy\sql\elements.py", line 515, in _execute_on_connection
    return connection._execute_clauseelement(
           ^^^^^^^^^^^^^^^^^^^^^^^^^^^^^^^^^^
  File "C:\Users\Kevin\Desktop\KaminariApi\venv\Lib\site-packages\sqlalchemy\engine\base.py", line 1640, in _execute_clauseelement
    ret = self._execute_context(
          ^^^^^^^^^^^^^^^^^^^^^^
  File "C:\Users\Kevin\Desktop\KaminariApi\venv\Lib\site-packages\sqlalchemy\engine\base.py", line 1846, in _execute_context
    return self._exec_single_context(
           ^^^^^^^^^^^^^^^^^^^^^^^^^^
  File "C:\Users\Kevin\Desktop\KaminariApi\venv\Lib\site-packages\sqlalchemy\engine\base.py", line 1986, in _exec_single_context
    self._handle_dbapi_exception(
  File "C:\Users\Kevin\Desktop\KaminariApi\venv\Lib\site-packages\sqlalchemy\engine\base.py", line 2355, in _handle_dbapi_exception
    raise sqlalchemy_exception.with_traceback(exc_info[2]) from e
  File "C:\Users\Kevin\Desktop\KaminariApi\venv\Lib\site-packages\sqlalchemy\engine\base.py", line 1967, in _exec_single_context
    self.dialect.do_execute(
  File "C:\Users\Kevin\Desktop\KaminariApi\venv\Lib\site-packages\sqlalchemy\engine\default.py", line 941, in do_execute
    cursor.execute(statement, parameters)
  File "C:\Users\Kevin\Desktop\KaminariApi\venv\Lib\site-packages\mysql\connector\cursor_cext.py", line 357, in execute
    result = self._connection.cmd_query(
             ^^^^^^^^^^^^^^^^^^^^^^^^^^^
  File "C:\Users\Kevin\Desktop\KaminariApi\venv\Lib\site-packages\mysql\connector\opentelemetry\context_propagation.py", line 97, in wrapper
    return method(cnx, *args, **kwargs)
           ^^^^^^^^^^^^^^^^^^^^^^^^^^^^
  File "C:\Users\Kevin\Desktop\KaminariApi\venv\Lib\site-packages\mysql\connector\connection_cext.py", line 714, in cmd_query
    raise get_mysql_exception(
sqlalchemy.exc.IntegrityError: (mysql.connector.errors.IntegrityError) 1062 (23000): Duplicate entry 'kvn@gmail.com' for key 'cliente.email'
[SQL: INSERT INTO `Cliente` (nombre, apellido, username, email, pwd, fecha_registro) VALUES (%(nombre)s, %(apellido)s, %(username)s, %(email)s, %(pwd)s, CURRENT_TIMESTAMP)]
[parameters: {'nombre': 'kevin', 'apellido': 'herrera', 'username': 'kkvn', 'email': 'kvn@gmail.com', 'pwd': 'Hola1234'}]
(Background on this error at: https://sqlalche.me/e/20/gkpj)
2024-11-27 12:36:43,576 - ERROR - Excepción capturada: (mysql.connector.errors.IntegrityError) 1062 (23000): Duplicate entry 'kvnn' for key 'cliente.username'
[SQL: INSERT INTO `Cliente` (nombre, apellido, username, email, pwd, fecha_registro) VALUES (%(nombre)s, %(apellido)s, %(username)s, %(email)s, %(pwd)s, CURRENT_TIMESTAMP)]
[parameters: {'nombre': 'kevin', 'apellido': 'herrera', 'username': 'kvnn', 'email': 'kvn@gmail.com', 'pwd': 'Hola1234'}]
(Background on this error at: https://sqlalche.me/e/20/gkpj)
Traceback (most recent call last):
  File "C:\Users\Kevin\Desktop\KaminariApi\venv\Lib\site-packages\mysql\connector\connection_cext.py", line 706, in cmd_query
    self._cmysql.query(
_mysql_connector.MySQLInterfaceError: Duplicate entry 'kvnn' for key 'cliente.username'

The above exception was the direct cause of the following exception:

Traceback (most recent call last):
  File "C:\Users\Kevin\Desktop\KaminariApi\venv\Lib\site-packages\sqlalchemy\engine\base.py", line 1967, in _exec_single_context
    self.dialect.do_execute(
  File "C:\Users\Kevin\Desktop\KaminariApi\venv\Lib\site-packages\sqlalchemy\engine\default.py", line 941, in do_execute
    cursor.execute(statement, parameters)
  File "C:\Users\Kevin\Desktop\KaminariApi\venv\Lib\site-packages\mysql\connector\cursor_cext.py", line 357, in execute
    result = self._connection.cmd_query(
             ^^^^^^^^^^^^^^^^^^^^^^^^^^^
  File "C:\Users\Kevin\Desktop\KaminariApi\venv\Lib\site-packages\mysql\connector\opentelemetry\context_propagation.py", line 97, in wrapper
    return method(cnx, *args, **kwargs)
           ^^^^^^^^^^^^^^^^^^^^^^^^^^^^
  File "C:\Users\Kevin\Desktop\KaminariApi\venv\Lib\site-packages\mysql\connector\connection_cext.py", line 714, in cmd_query
    raise get_mysql_exception(
mysql.connector.errors.IntegrityError: 1062 (23000): Duplicate entry 'kvnn' for key 'cliente.username'

The above exception was the direct cause of the following exception:

Traceback (most recent call last):
  File "C:\Users\Kevin\Desktop\KaminariApi\app\src\models\dbConect.py", line 21, in guardarCambiosDb
    return Session.commit()
           ^^^^^^^^^^^^^^^^
  File "C:\Users\Kevin\Desktop\KaminariApi\venv\Lib\site-packages\sqlalchemy\orm\session.py", line 2028, in commit
    trans.commit(_to_root=True)
  File "<string>", line 2, in commit
  File "C:\Users\Kevin\Desktop\KaminariApi\venv\Lib\site-packages\sqlalchemy\orm\state_changes.py", line 139, in _go
    ret_value = fn(self, *arg, **kw)
                ^^^^^^^^^^^^^^^^^^^^
  File "C:\Users\Kevin\Desktop\KaminariApi\venv\Lib\site-packages\sqlalchemy\orm\session.py", line 1313, in commit
    self._prepare_impl()
  File "<string>", line 2, in _prepare_impl
  File "C:\Users\Kevin\Desktop\KaminariApi\venv\Lib\site-packages\sqlalchemy\orm\state_changes.py", line 139, in _go
    ret_value = fn(self, *arg, **kw)
                ^^^^^^^^^^^^^^^^^^^^
  File "C:\Users\Kevin\Desktop\KaminariApi\venv\Lib\site-packages\sqlalchemy\orm\session.py", line 1288, in _prepare_impl
    self.session.flush()
  File "C:\Users\Kevin\Desktop\KaminariApi\venv\Lib\site-packages\sqlalchemy\orm\session.py", line 4352, in flush
    self._flush(objects)
  File "C:\Users\Kevin\Desktop\KaminariApi\venv\Lib\site-packages\sqlalchemy\orm\session.py", line 4487, in _flush
    with util.safe_reraise():
  File "C:\Users\Kevin\Desktop\KaminariApi\venv\Lib\site-packages\sqlalchemy\util\langhelpers.py", line 146, in __exit__
    raise exc_value.with_traceback(exc_tb)
  File "C:\Users\Kevin\Desktop\KaminariApi\venv\Lib\site-packages\sqlalchemy\orm\session.py", line 4448, in _flush
    flush_context.execute()
  File "C:\Users\Kevin\Desktop\KaminariApi\venv\Lib\site-packages\sqlalchemy\orm\unitofwork.py", line 466, in execute
    rec.execute(self)
  File "C:\Users\Kevin\Desktop\KaminariApi\venv\Lib\site-packages\sqlalchemy\orm\unitofwork.py", line 642, in execute
    util.preloaded.orm_persistence.save_obj(
  File "C:\Users\Kevin\Desktop\KaminariApi\venv\Lib\site-packages\sqlalchemy\orm\persistence.py", line 93, in save_obj
    _emit_insert_statements(
  File "C:\Users\Kevin\Desktop\KaminariApi\venv\Lib\site-packages\sqlalchemy\orm\persistence.py", line 1233, in _emit_insert_statements
    result = connection.execute(
             ^^^^^^^^^^^^^^^^^^^
  File "C:\Users\Kevin\Desktop\KaminariApi\venv\Lib\site-packages\sqlalchemy\engine\base.py", line 1418, in execute
    return meth(
           ^^^^^
  File "C:\Users\Kevin\Desktop\KaminariApi\venv\Lib\site-packages\sqlalchemy\sql\elements.py", line 515, in _execute_on_connection
    return connection._execute_clauseelement(
           ^^^^^^^^^^^^^^^^^^^^^^^^^^^^^^^^^^
  File "C:\Users\Kevin\Desktop\KaminariApi\venv\Lib\site-packages\sqlalchemy\engine\base.py", line 1640, in _execute_clauseelement
    ret = self._execute_context(
          ^^^^^^^^^^^^^^^^^^^^^^
  File "C:\Users\Kevin\Desktop\KaminariApi\venv\Lib\site-packages\sqlalchemy\engine\base.py", line 1846, in _execute_context
    return self._exec_single_context(
           ^^^^^^^^^^^^^^^^^^^^^^^^^^
  File "C:\Users\Kevin\Desktop\KaminariApi\venv\Lib\site-packages\sqlalchemy\engine\base.py", line 1986, in _exec_single_context
    self._handle_dbapi_exception(
  File "C:\Users\Kevin\Desktop\KaminariApi\venv\Lib\site-packages\sqlalchemy\engine\base.py", line 2355, in _handle_dbapi_exception
    raise sqlalchemy_exception.with_traceback(exc_info[2]) from e
  File "C:\Users\Kevin\Desktop\KaminariApi\venv\Lib\site-packages\sqlalchemy\engine\base.py", line 1967, in _exec_single_context
    self.dialect.do_execute(
  File "C:\Users\Kevin\Desktop\KaminariApi\venv\Lib\site-packages\sqlalchemy\engine\default.py", line 941, in do_execute
    cursor.execute(statement, parameters)
  File "C:\Users\Kevin\Desktop\KaminariApi\venv\Lib\site-packages\mysql\connector\cursor_cext.py", line 357, in execute
    result = self._connection.cmd_query(
             ^^^^^^^^^^^^^^^^^^^^^^^^^^^
  File "C:\Users\Kevin\Desktop\KaminariApi\venv\Lib\site-packages\mysql\connector\opentelemetry\context_propagation.py", line 97, in wrapper
    return method(cnx, *args, **kwargs)
           ^^^^^^^^^^^^^^^^^^^^^^^^^^^^
  File "C:\Users\Kevin\Desktop\KaminariApi\venv\Lib\site-packages\mysql\connector\connection_cext.py", line 714, in cmd_query
    raise get_mysql_exception(
sqlalchemy.exc.IntegrityError: (mysql.connector.errors.IntegrityError) 1062 (23000): Duplicate entry 'kvnn' for key 'cliente.username'
[SQL: INSERT INTO `Cliente` (nombre, apellido, username, email, pwd, fecha_registro) VALUES (%(nombre)s, %(apellido)s, %(username)s, %(email)s, %(pwd)s, CURRENT_TIMESTAMP)]
[parameters: {'nombre': 'kevin', 'apellido': 'herrera', 'username': 'kvnn', 'email': 'kvn@gmail.com', 'pwd': 'Hola1234'}]
(Background on this error at: https://sqlalche.me/e/20/gkpj)
2024-11-27 13:18:27,290 - ERROR - Excepción capturada: (mysql.connector.errors.IntegrityError) 1062 (23000): Duplicate entry 'kvn@gmail.com' for key 'cliente.email'
[SQL: INSERT INTO `Cliente` (nombre, apellido, username, email, pwd, fecha_registro) VALUES (%(nombre)s, %(apellido)s, %(username)s, %(email)s, %(pwd)s, CURRENT_TIMESTAMP)]
[parameters: {'nombre': 'kevin', 'apellido': 'herrera', 'username': 'kkk', 'email': 'kvn@gmail.com', 'pwd': 'Hola1234'}]
(Background on this error at: https://sqlalche.me/e/20/gkpj)
Traceback (most recent call last):
  File "C:\Users\Kevin\Desktop\KaminariApi\venv\Lib\site-packages\mysql\connector\connection_cext.py", line 706, in cmd_query
    self._cmysql.query(
_mysql_connector.MySQLInterfaceError: Duplicate entry 'kvn@gmail.com' for key 'cliente.email'

The above exception was the direct cause of the following exception:

Traceback (most recent call last):
  File "C:\Users\Kevin\Desktop\KaminariApi\venv\Lib\site-packages\sqlalchemy\engine\base.py", line 1967, in _exec_single_context
    self.dialect.do_execute(
  File "C:\Users\Kevin\Desktop\KaminariApi\venv\Lib\site-packages\sqlalchemy\engine\default.py", line 941, in do_execute
    cursor.execute(statement, parameters)
  File "C:\Users\Kevin\Desktop\KaminariApi\venv\Lib\site-packages\mysql\connector\cursor_cext.py", line 357, in execute
    result = self._connection.cmd_query(
             ^^^^^^^^^^^^^^^^^^^^^^^^^^^
  File "C:\Users\Kevin\Desktop\KaminariApi\venv\Lib\site-packages\mysql\connector\opentelemetry\context_propagation.py", line 97, in wrapper
    return method(cnx, *args, **kwargs)
           ^^^^^^^^^^^^^^^^^^^^^^^^^^^^
  File "C:\Users\Kevin\Desktop\KaminariApi\venv\Lib\site-packages\mysql\connector\connection_cext.py", line 714, in cmd_query
    raise get_mysql_exception(
mysql.connector.errors.IntegrityError: 1062 (23000): Duplicate entry 'kvn@gmail.com' for key 'cliente.email'

The above exception was the direct cause of the following exception:

Traceback (most recent call last):
  File "C:\Users\Kevin\Desktop\KaminariApi\app\src\models\dbConect.py", line 21, in guardarCambiosDb
    return Session.commit()
           ^^^^^^^^^^^^^^^^
  File "C:\Users\Kevin\Desktop\KaminariApi\venv\Lib\site-packages\sqlalchemy\orm\session.py", line 2028, in commit
    trans.commit(_to_root=True)
  File "<string>", line 2, in commit
  File "C:\Users\Kevin\Desktop\KaminariApi\venv\Lib\site-packages\sqlalchemy\orm\state_changes.py", line 139, in _go
    ret_value = fn(self, *arg, **kw)
                ^^^^^^^^^^^^^^^^^^^^
  File "C:\Users\Kevin\Desktop\KaminariApi\venv\Lib\site-packages\sqlalchemy\orm\session.py", line 1313, in commit
    self._prepare_impl()
  File "<string>", line 2, in _prepare_impl
  File "C:\Users\Kevin\Desktop\KaminariApi\venv\Lib\site-packages\sqlalchemy\orm\state_changes.py", line 139, in _go
    ret_value = fn(self, *arg, **kw)
                ^^^^^^^^^^^^^^^^^^^^
  File "C:\Users\Kevin\Desktop\KaminariApi\venv\Lib\site-packages\sqlalchemy\orm\session.py", line 1288, in _prepare_impl
    self.session.flush()
  File "C:\Users\Kevin\Desktop\KaminariApi\venv\Lib\site-packages\sqlalchemy\orm\session.py", line 4352, in flush
    self._flush(objects)
  File "C:\Users\Kevin\Desktop\KaminariApi\venv\Lib\site-packages\sqlalchemy\orm\session.py", line 4487, in _flush
    with util.safe_reraise():
  File "C:\Users\Kevin\Desktop\KaminariApi\venv\Lib\site-packages\sqlalchemy\util\langhelpers.py", line 146, in __exit__
    raise exc_value.with_traceback(exc_tb)
  File "C:\Users\Kevin\Desktop\KaminariApi\venv\Lib\site-packages\sqlalchemy\orm\session.py", line 4448, in _flush
    flush_context.execute()
  File "C:\Users\Kevin\Desktop\KaminariApi\venv\Lib\site-packages\sqlalchemy\orm\unitofwork.py", line 466, in execute
    rec.execute(self)
  File "C:\Users\Kevin\Desktop\KaminariApi\venv\Lib\site-packages\sqlalchemy\orm\unitofwork.py", line 642, in execute
    util.preloaded.orm_persistence.save_obj(
  File "C:\Users\Kevin\Desktop\KaminariApi\venv\Lib\site-packages\sqlalchemy\orm\persistence.py", line 93, in save_obj
    _emit_insert_statements(
  File "C:\Users\Kevin\Desktop\KaminariApi\venv\Lib\site-packages\sqlalchemy\orm\persistence.py", line 1233, in _emit_insert_statements
    result = connection.execute(
             ^^^^^^^^^^^^^^^^^^^
  File "C:\Users\Kevin\Desktop\KaminariApi\venv\Lib\site-packages\sqlalchemy\engine\base.py", line 1418, in execute
    return meth(
           ^^^^^
  File "C:\Users\Kevin\Desktop\KaminariApi\venv\Lib\site-packages\sqlalchemy\sql\elements.py", line 515, in _execute_on_connection
    return connection._execute_clauseelement(
           ^^^^^^^^^^^^^^^^^^^^^^^^^^^^^^^^^^
  File "C:\Users\Kevin\Desktop\KaminariApi\venv\Lib\site-packages\sqlalchemy\engine\base.py", line 1640, in _execute_clauseelement
    ret = self._execute_context(
          ^^^^^^^^^^^^^^^^^^^^^^
  File "C:\Users\Kevin\Desktop\KaminariApi\venv\Lib\site-packages\sqlalchemy\engine\base.py", line 1846, in _execute_context
    return self._exec_single_context(
           ^^^^^^^^^^^^^^^^^^^^^^^^^^
  File "C:\Users\Kevin\Desktop\KaminariApi\venv\Lib\site-packages\sqlalchemy\engine\base.py", line 1986, in _exec_single_context
    self._handle_dbapi_exception(
  File "C:\Users\Kevin\Desktop\KaminariApi\venv\Lib\site-packages\sqlalchemy\engine\base.py", line 2355, in _handle_dbapi_exception
    raise sqlalchemy_exception.with_traceback(exc_info[2]) from e
  File "C:\Users\Kevin\Desktop\KaminariApi\venv\Lib\site-packages\sqlalchemy\engine\base.py", line 1967, in _exec_single_context
    self.dialect.do_execute(
  File "C:\Users\Kevin\Desktop\KaminariApi\venv\Lib\site-packages\sqlalchemy\engine\default.py", line 941, in do_execute
    cursor.execute(statement, parameters)
  File "C:\Users\Kevin\Desktop\KaminariApi\venv\Lib\site-packages\mysql\connector\cursor_cext.py", line 357, in execute
    result = self._connection.cmd_query(
             ^^^^^^^^^^^^^^^^^^^^^^^^^^^
  File "C:\Users\Kevin\Desktop\KaminariApi\venv\Lib\site-packages\mysql\connector\opentelemetry\context_propagation.py", line 97, in wrapper
    return method(cnx, *args, **kwargs)
           ^^^^^^^^^^^^^^^^^^^^^^^^^^^^
  File "C:\Users\Kevin\Desktop\KaminariApi\venv\Lib\site-packages\mysql\connector\connection_cext.py", line 714, in cmd_query
    raise get_mysql_exception(
sqlalchemy.exc.IntegrityError: (mysql.connector.errors.IntegrityError) 1062 (23000): Duplicate entry 'kvn@gmail.com' for key 'cliente.email'
[SQL: INSERT INTO `Cliente` (nombre, apellido, username, email, pwd, fecha_registro) VALUES (%(nombre)s, %(apellido)s, %(username)s, %(email)s, %(pwd)s, CURRENT_TIMESTAMP)]
[parameters: {'nombre': 'kevin', 'apellido': 'herrera', 'username': 'kkk', 'email': 'kvn@gmail.com', 'pwd': 'Hola1234'}]
(Background on this error at: https://sqlalche.me/e/20/gkpj)
2024-11-27 14:38:02,398 - ERROR - Excepción capturada: 'list' object has no attribute 'id'
Traceback (most recent call last):
  File "C:\Users\Kevin\Desktop\KaminariApi\app\src\models\productoModels\readProductoModels.py", line 22, in getProductoInDb
    "id": productos.id,
          ^^^^^^^^^^^^
AttributeError: 'list' object has no attribute 'id'
2024-11-28 16:22:15,643 - ERROR - Excepción capturada: (mysql.connector.errors.IntegrityError) 1062 (23000): Duplicate entry 'kvnn' for key 'cliente.username'
[SQL: INSERT INTO `Cliente` (nombre, apellido, username, email, pwd, fecha_registro) VALUES (%(nombre)s, %(apellido)s, %(username)s, %(email)s, %(pwd)s, CURRENT_TIMESTAMP)]
[parameters: {'nombre': 'kevin', 'apellido': 'herrera', 'username': 'kvnn', 'email': 'kvn@gmail.com', 'pwd': 'Hola1234'}]
(Background on this error at: https://sqlalche.me/e/20/gkpj)
Traceback (most recent call last):
  File "C:\Users\Kevin\Desktop\KaminariApi\venv\Lib\site-packages\mysql\connector\connection_cext.py", line 706, in cmd_query
    self._cmysql.query(
_mysql_connector.MySQLInterfaceError: Duplicate entry 'kvnn' for key 'cliente.username'

The above exception was the direct cause of the following exception:

Traceback (most recent call last):
  File "C:\Users\Kevin\Desktop\KaminariApi\venv\Lib\site-packages\sqlalchemy\engine\base.py", line 1967, in _exec_single_context
    self.dialect.do_execute(
  File "C:\Users\Kevin\Desktop\KaminariApi\venv\Lib\site-packages\sqlalchemy\engine\default.py", line 941, in do_execute
    cursor.execute(statement, parameters)
  File "C:\Users\Kevin\Desktop\KaminariApi\venv\Lib\site-packages\mysql\connector\cursor_cext.py", line 357, in execute
    result = self._connection.cmd_query(
             ^^^^^^^^^^^^^^^^^^^^^^^^^^^
  File "C:\Users\Kevin\Desktop\KaminariApi\venv\Lib\site-packages\mysql\connector\opentelemetry\context_propagation.py", line 97, in wrapper
    return method(cnx, *args, **kwargs)
           ^^^^^^^^^^^^^^^^^^^^^^^^^^^^
  File "C:\Users\Kevin\Desktop\KaminariApi\venv\Lib\site-packages\mysql\connector\connection_cext.py", line 714, in cmd_query
    raise get_mysql_exception(
mysql.connector.errors.IntegrityError: 1062 (23000): Duplicate entry 'kvnn' for key 'cliente.username'

The above exception was the direct cause of the following exception:

Traceback (most recent call last):
  File "C:\Users\Kevin\Desktop\KaminariApi\app\src\models\dbConect.py", line 21, in guardarCambiosDb
    return Session.commit()
           ^^^^^^^^^^^^^^^^
  File "C:\Users\Kevin\Desktop\KaminariApi\venv\Lib\site-packages\sqlalchemy\orm\session.py", line 2028, in commit
    trans.commit(_to_root=True)
  File "<string>", line 2, in commit
  File "C:\Users\Kevin\Desktop\KaminariApi\venv\Lib\site-packages\sqlalchemy\orm\state_changes.py", line 139, in _go
    ret_value = fn(self, *arg, **kw)
                ^^^^^^^^^^^^^^^^^^^^
  File "C:\Users\Kevin\Desktop\KaminariApi\venv\Lib\site-packages\sqlalchemy\orm\session.py", line 1313, in commit
    self._prepare_impl()
  File "<string>", line 2, in _prepare_impl
  File "C:\Users\Kevin\Desktop\KaminariApi\venv\Lib\site-packages\sqlalchemy\orm\state_changes.py", line 139, in _go
    ret_value = fn(self, *arg, **kw)
                ^^^^^^^^^^^^^^^^^^^^
  File "C:\Users\Kevin\Desktop\KaminariApi\venv\Lib\site-packages\sqlalchemy\orm\session.py", line 1288, in _prepare_impl
    self.session.flush()
  File "C:\Users\Kevin\Desktop\KaminariApi\venv\Lib\site-packages\sqlalchemy\orm\session.py", line 4352, in flush
    self._flush(objects)
  File "C:\Users\Kevin\Desktop\KaminariApi\venv\Lib\site-packages\sqlalchemy\orm\session.py", line 4487, in _flush
    with util.safe_reraise():
  File "C:\Users\Kevin\Desktop\KaminariApi\venv\Lib\site-packages\sqlalchemy\util\langhelpers.py", line 146, in __exit__
    raise exc_value.with_traceback(exc_tb)
  File "C:\Users\Kevin\Desktop\KaminariApi\venv\Lib\site-packages\sqlalchemy\orm\session.py", line 4448, in _flush
    flush_context.execute()
  File "C:\Users\Kevin\Desktop\KaminariApi\venv\Lib\site-packages\sqlalchemy\orm\unitofwork.py", line 466, in execute
    rec.execute(self)
  File "C:\Users\Kevin\Desktop\KaminariApi\venv\Lib\site-packages\sqlalchemy\orm\unitofwork.py", line 642, in execute
    util.preloaded.orm_persistence.save_obj(
  File "C:\Users\Kevin\Desktop\KaminariApi\venv\Lib\site-packages\sqlalchemy\orm\persistence.py", line 93, in save_obj
    _emit_insert_statements(
  File "C:\Users\Kevin\Desktop\KaminariApi\venv\Lib\site-packages\sqlalchemy\orm\persistence.py", line 1233, in _emit_insert_statements
    result = connection.execute(
             ^^^^^^^^^^^^^^^^^^^
  File "C:\Users\Kevin\Desktop\KaminariApi\venv\Lib\site-packages\sqlalchemy\engine\base.py", line 1418, in execute
    return meth(
           ^^^^^
  File "C:\Users\Kevin\Desktop\KaminariApi\venv\Lib\site-packages\sqlalchemy\sql\elements.py", line 515, in _execute_on_connection
    return connection._execute_clauseelement(
           ^^^^^^^^^^^^^^^^^^^^^^^^^^^^^^^^^^
  File "C:\Users\Kevin\Desktop\KaminariApi\venv\Lib\site-packages\sqlalchemy\engine\base.py", line 1640, in _execute_clauseelement
    ret = self._execute_context(
          ^^^^^^^^^^^^^^^^^^^^^^
  File "C:\Users\Kevin\Desktop\KaminariApi\venv\Lib\site-packages\sqlalchemy\engine\base.py", line 1846, in _execute_context
    return self._exec_single_context(
           ^^^^^^^^^^^^^^^^^^^^^^^^^^
  File "C:\Users\Kevin\Desktop\KaminariApi\venv\Lib\site-packages\sqlalchemy\engine\base.py", line 1986, in _exec_single_context
    self._handle_dbapi_exception(
  File "C:\Users\Kevin\Desktop\KaminariApi\venv\Lib\site-packages\sqlalchemy\engine\base.py", line 2355, in _handle_dbapi_exception
    raise sqlalchemy_exception.with_traceback(exc_info[2]) from e
  File "C:\Users\Kevin\Desktop\KaminariApi\venv\Lib\site-packages\sqlalchemy\engine\base.py", line 1967, in _exec_single_context
    self.dialect.do_execute(
  File "C:\Users\Kevin\Desktop\KaminariApi\venv\Lib\site-packages\sqlalchemy\engine\default.py", line 941, in do_execute
    cursor.execute(statement, parameters)
  File "C:\Users\Kevin\Desktop\KaminariApi\venv\Lib\site-packages\mysql\connector\cursor_cext.py", line 357, in execute
    result = self._connection.cmd_query(
             ^^^^^^^^^^^^^^^^^^^^^^^^^^^
  File "C:\Users\Kevin\Desktop\KaminariApi\venv\Lib\site-packages\mysql\connector\opentelemetry\context_propagation.py", line 97, in wrapper
    return method(cnx, *args, **kwargs)
           ^^^^^^^^^^^^^^^^^^^^^^^^^^^^
  File "C:\Users\Kevin\Desktop\KaminariApi\venv\Lib\site-packages\mysql\connector\connection_cext.py", line 714, in cmd_query
    raise get_mysql_exception(
sqlalchemy.exc.IntegrityError: (mysql.connector.errors.IntegrityError) 1062 (23000): Duplicate entry 'kvnn' for key 'cliente.username'
[SQL: INSERT INTO `Cliente` (nombre, apellido, username, email, pwd, fecha_registro) VALUES (%(nombre)s, %(apellido)s, %(username)s, %(email)s, %(pwd)s, CURRENT_TIMESTAMP)]
[parameters: {'nombre': 'kevin', 'apellido': 'herrera', 'username': 'kvnn', 'email': 'kvn@gmail.com', 'pwd': 'Hola1234'}]
(Background on this error at: https://sqlalche.me/e/20/gkpj)
2024-11-28 16:27:01,326 - ERROR - Excepción capturada: (mysql.connector.errors.IntegrityError) 1062 (23000): Duplicate entry 'kvnn' for key 'cliente.username'
[SQL: INSERT INTO `Cliente` (nombre, apellido, username, email, pwd, fecha_registro) VALUES (%(nombre)s, %(apellido)s, %(username)s, %(email)s, %(pwd)s, CURRENT_TIMESTAMP)]
[parameters: {'nombre': 'kevin', 'apellido': 'Herrera', 'username': 'kvnn', 'email': 'kvn@gmail.com', 'pwd': 'Hola1234'}]
(Background on this error at: https://sqlalche.me/e/20/gkpj)
Traceback (most recent call last):
  File "C:\Users\Kevin\Desktop\KaminariApi\venv\Lib\site-packages\mysql\connector\connection_cext.py", line 706, in cmd_query
    self._cmysql.query(
_mysql_connector.MySQLInterfaceError: Duplicate entry 'kvnn' for key 'cliente.username'

The above exception was the direct cause of the following exception:

Traceback (most recent call last):
  File "C:\Users\Kevin\Desktop\KaminariApi\venv\Lib\site-packages\sqlalchemy\engine\base.py", line 1967, in _exec_single_context
    self.dialect.do_execute(
  File "C:\Users\Kevin\Desktop\KaminariApi\venv\Lib\site-packages\sqlalchemy\engine\default.py", line 941, in do_execute
    cursor.execute(statement, parameters)
  File "C:\Users\Kevin\Desktop\KaminariApi\venv\Lib\site-packages\mysql\connector\cursor_cext.py", line 357, in execute
    result = self._connection.cmd_query(
             ^^^^^^^^^^^^^^^^^^^^^^^^^^^
  File "C:\Users\Kevin\Desktop\KaminariApi\venv\Lib\site-packages\mysql\connector\opentelemetry\context_propagation.py", line 97, in wrapper
    return method(cnx, *args, **kwargs)
           ^^^^^^^^^^^^^^^^^^^^^^^^^^^^
  File "C:\Users\Kevin\Desktop\KaminariApi\venv\Lib\site-packages\mysql\connector\connection_cext.py", line 714, in cmd_query
    raise get_mysql_exception(
mysql.connector.errors.IntegrityError: 1062 (23000): Duplicate entry 'kvnn' for key 'cliente.username'

The above exception was the direct cause of the following exception:

Traceback (most recent call last):
  File "C:\Users\Kevin\Desktop\KaminariApi\app\src\models\dbConect.py", line 21, in guardarCambiosDb
    return Session.commit()
           ^^^^^^^^^^^^^^^^
  File "C:\Users\Kevin\Desktop\KaminariApi\venv\Lib\site-packages\sqlalchemy\orm\session.py", line 2028, in commit
    trans.commit(_to_root=True)
  File "<string>", line 2, in commit
  File "C:\Users\Kevin\Desktop\KaminariApi\venv\Lib\site-packages\sqlalchemy\orm\state_changes.py", line 139, in _go
    ret_value = fn(self, *arg, **kw)
                ^^^^^^^^^^^^^^^^^^^^
  File "C:\Users\Kevin\Desktop\KaminariApi\venv\Lib\site-packages\sqlalchemy\orm\session.py", line 1313, in commit
    self._prepare_impl()
  File "<string>", line 2, in _prepare_impl
  File "C:\Users\Kevin\Desktop\KaminariApi\venv\Lib\site-packages\sqlalchemy\orm\state_changes.py", line 139, in _go
    ret_value = fn(self, *arg, **kw)
                ^^^^^^^^^^^^^^^^^^^^
  File "C:\Users\Kevin\Desktop\KaminariApi\venv\Lib\site-packages\sqlalchemy\orm\session.py", line 1288, in _prepare_impl
    self.session.flush()
  File "C:\Users\Kevin\Desktop\KaminariApi\venv\Lib\site-packages\sqlalchemy\orm\session.py", line 4352, in flush
    self._flush(objects)
  File "C:\Users\Kevin\Desktop\KaminariApi\venv\Lib\site-packages\sqlalchemy\orm\session.py", line 4487, in _flush
    with util.safe_reraise():
  File "C:\Users\Kevin\Desktop\KaminariApi\venv\Lib\site-packages\sqlalchemy\util\langhelpers.py", line 146, in __exit__
    raise exc_value.with_traceback(exc_tb)
  File "C:\Users\Kevin\Desktop\KaminariApi\venv\Lib\site-packages\sqlalchemy\orm\session.py", line 4448, in _flush
    flush_context.execute()
  File "C:\Users\Kevin\Desktop\KaminariApi\venv\Lib\site-packages\sqlalchemy\orm\unitofwork.py", line 466, in execute
    rec.execute(self)
  File "C:\Users\Kevin\Desktop\KaminariApi\venv\Lib\site-packages\sqlalchemy\orm\unitofwork.py", line 642, in execute
    util.preloaded.orm_persistence.save_obj(
  File "C:\Users\Kevin\Desktop\KaminariApi\venv\Lib\site-packages\sqlalchemy\orm\persistence.py", line 93, in save_obj
    _emit_insert_statements(
  File "C:\Users\Kevin\Desktop\KaminariApi\venv\Lib\site-packages\sqlalchemy\orm\persistence.py", line 1233, in _emit_insert_statements
    result = connection.execute(
             ^^^^^^^^^^^^^^^^^^^
  File "C:\Users\Kevin\Desktop\KaminariApi\venv\Lib\site-packages\sqlalchemy\engine\base.py", line 1418, in execute
    return meth(
           ^^^^^
  File "C:\Users\Kevin\Desktop\KaminariApi\venv\Lib\site-packages\sqlalchemy\sql\elements.py", line 515, in _execute_on_connection
    return connection._execute_clauseelement(
           ^^^^^^^^^^^^^^^^^^^^^^^^^^^^^^^^^^
  File "C:\Users\Kevin\Desktop\KaminariApi\venv\Lib\site-packages\sqlalchemy\engine\base.py", line 1640, in _execute_clauseelement
    ret = self._execute_context(
          ^^^^^^^^^^^^^^^^^^^^^^
  File "C:\Users\Kevin\Desktop\KaminariApi\venv\Lib\site-packages\sqlalchemy\engine\base.py", line 1846, in _execute_context
    return self._exec_single_context(
           ^^^^^^^^^^^^^^^^^^^^^^^^^^
  File "C:\Users\Kevin\Desktop\KaminariApi\venv\Lib\site-packages\sqlalchemy\engine\base.py", line 1986, in _exec_single_context
    self._handle_dbapi_exception(
  File "C:\Users\Kevin\Desktop\KaminariApi\venv\Lib\site-packages\sqlalchemy\engine\base.py", line 2355, in _handle_dbapi_exception
    raise sqlalchemy_exception.with_traceback(exc_info[2]) from e
  File "C:\Users\Kevin\Desktop\KaminariApi\venv\Lib\site-packages\sqlalchemy\engine\base.py", line 1967, in _exec_single_context
    self.dialect.do_execute(
  File "C:\Users\Kevin\Desktop\KaminariApi\venv\Lib\site-packages\sqlalchemy\engine\default.py", line 941, in do_execute
    cursor.execute(statement, parameters)
  File "C:\Users\Kevin\Desktop\KaminariApi\venv\Lib\site-packages\mysql\connector\cursor_cext.py", line 357, in execute
    result = self._connection.cmd_query(
             ^^^^^^^^^^^^^^^^^^^^^^^^^^^
  File "C:\Users\Kevin\Desktop\KaminariApi\venv\Lib\site-packages\mysql\connector\opentelemetry\context_propagation.py", line 97, in wrapper
    return method(cnx, *args, **kwargs)
           ^^^^^^^^^^^^^^^^^^^^^^^^^^^^
  File "C:\Users\Kevin\Desktop\KaminariApi\venv\Lib\site-packages\mysql\connector\connection_cext.py", line 714, in cmd_query
    raise get_mysql_exception(
sqlalchemy.exc.IntegrityError: (mysql.connector.errors.IntegrityError) 1062 (23000): Duplicate entry 'kvnn' for key 'cliente.username'
[SQL: INSERT INTO `Cliente` (nombre, apellido, username, email, pwd, fecha_registro) VALUES (%(nombre)s, %(apellido)s, %(username)s, %(email)s, %(pwd)s, CURRENT_TIMESTAMP)]
[parameters: {'nombre': 'kevin', 'apellido': 'Herrera', 'username': 'kvnn', 'email': 'kvn@gmail.com', 'pwd': 'Hola1234'}]
(Background on this error at: https://sqlalche.me/e/20/gkpj)
2024-12-10 14:17:29,398 - ERROR - Excepción capturada: 'InstrumentedList' object has no attribute 'talle'
Traceback (most recent call last):
  File "C:\Users\Kevin\Desktop\KaminariApi\app\src\models\productoModels\readProductoModels.py", line 104, in getProductoByTalleAndColor
    "talle": producto.variantes.talle,
             ^^^^^^^^^^^^^^^^^^^^^^^^
AttributeError: 'InstrumentedList' object has no attribute 'talle'
2024-12-10 14:23:30,869 - ERROR - Excepción capturada: PropComparator.any() takes from 1 to 2 positional arguments but 3 were given
Traceback (most recent call last):
  File "C:\Users\Kevin\Desktop\KaminariApi\app\src\models\productoModels\readProductoModels.py", line 90, in getProductoByTalleAndColor
    ProductoIndumentaria.variantes.any(
TypeError: PropComparator.any() takes from 1 to 2 positional arguments but 3 were given
2024-12-10 14:24:16,795 - ERROR - Excepción capturada: PropComparator.any() takes from 1 to 2 positional arguments but 3 were given
Traceback (most recent call last):
  File "C:\Users\Kevin\Desktop\KaminariApi\app\src\models\productoModels\readProductoModels.py", line 91, in getProductoByTalleAndColor
    ProductoIndumentaria.variantes.any(
TypeError: PropComparator.any() takes from 1 to 2 positional arguments but 3 were given
2024-12-19 12:33:43,114 - ERROR - Excepción capturada: list.append() takes exactly one argument (0 given)
Traceback (most recent call last):
  File "C:\Users\Kevin\Desktop\KaminariApi\app\src\models\productoModels\readProductoModels.py", line 168, in getPriceByListIdProducto
    dataMappeado['data'].append()
TypeError: list.append() takes exactly one argument (0 given)
2024-12-27 17:27:46,522 - ERROR - Excepción capturada: GetCLienteInDB.consultarClienteForEmail() got an unexpected keyword argument 'username'
Traceback (most recent call last):
  File "C:\Users\Kevin\Desktop\KaminariApi\main.py", line 69, in login2
    userInDb = ClienteHandler().crearGetClienteInDb().consultarClienteForEmail(username=formData.email, pwd=formData.pwd)
               ^^^^^^^^^^^^^^^^^^^^^^^^^^^^^^^^^^^^^^^^^^^^^^^^^^^^^^^^^^^^^^^^^^^^^^^^^^^^^^^^^^^^^^^^^^^^^^^^^^^^^^^^^^
TypeError: GetCLienteInDB.consultarClienteForEmail() got an unexpected keyword argument 'username'
2024-12-27 17:38:24,882 - ERROR - Excepción capturada: Invalid crypto padding
Traceback (most recent call last):
  File "C:\Users\Kevin\Desktop\KaminariApi\venv\Lib\site-packages\jose\jws.py", line 198, in _load
    signature = base64url_decode(crypto_segment)
                ^^^^^^^^^^^^^^^^^^^^^^^^^^^^^^^^
  File "C:\Users\Kevin\Desktop\KaminariApi\venv\Lib\site-packages\jose\utils.py", line 78, in base64url_decode
    return base64.urlsafe_b64decode(input)
           ^^^^^^^^^^^^^^^^^^^^^^^^^^^^^^^
  File "C:\Python312\Lib\base64.py", line 134, in urlsafe_b64decode
    return b64decode(s)
           ^^^^^^^^^^^^
  File "C:\Python312\Lib\base64.py", line 88, in b64decode
    return binascii.a2b_base64(s, strict_mode=validate)
           ^^^^^^^^^^^^^^^^^^^^^^^^^^^^^^^^^^^^^^^^^^^^
binascii.Error: Incorrect padding

During handling of the above exception, another exception occurred:

Traceback (most recent call last):
  File "C:\Users\Kevin\Desktop\KaminariApi\venv\Lib\site-packages\jose\jwt.py", line 142, in decode
    payload = jws.verify(token, key, algorithms, verify=verify_signature)
              ^^^^^^^^^^^^^^^^^^^^^^^^^^^^^^^^^^^^^^^^^^^^^^^^^^^^^^^^^^^
  File "C:\Users\Kevin\Desktop\KaminariApi\venv\Lib\site-packages\jose\jws.py", line 70, in verify
    header, payload, signing_input, signature = _load(token)
                                                ^^^^^^^^^^^^
  File "C:\Users\Kevin\Desktop\KaminariApi\venv\Lib\site-packages\jose\jws.py", line 200, in _load
    raise JWSError("Invalid crypto padding")
jose.exceptions.JWSError: Invalid crypto padding

During handling of the above exception, another exception occurred:

Traceback (most recent call last):
  File "C:\Users\Kevin\Desktop\KaminariApi\app\oauthJWT\decodeJwt.py", line 22, in decodeToken
    return decode(
           ^^^^^^^
  File "C:\Users\Kevin\Desktop\KaminariApi\venv\Lib\site-packages\jose\jwt.py", line 144, in decode
    raise JWTError(e)
jose.exceptions.JWTError: Invalid crypto padding
2024-12-27 17:40:09,298 - ERROR - Excepción capturada: Signature verification failed.
Traceback (most recent call last):
  File "C:\Users\Kevin\Desktop\KaminariApi\venv\Lib\site-packages\jose\jws.py", line 262, in _verify_signature
    raise JWSSignatureError()
jose.exceptions.JWSSignatureError

During handling of the above exception, another exception occurred:

Traceback (most recent call last):
  File "C:\Users\Kevin\Desktop\KaminariApi\venv\Lib\site-packages\jose\jwt.py", line 142, in decode
    payload = jws.verify(token, key, algorithms, verify=verify_signature)
              ^^^^^^^^^^^^^^^^^^^^^^^^^^^^^^^^^^^^^^^^^^^^^^^^^^^^^^^^^^^
  File "C:\Users\Kevin\Desktop\KaminariApi\venv\Lib\site-packages\jose\jws.py", line 73, in verify
    _verify_signature(signing_input, header, signature, key, algorithms)
  File "C:\Users\Kevin\Desktop\KaminariApi\venv\Lib\site-packages\jose\jws.py", line 264, in _verify_signature
    raise JWSError("Signature verification failed.")
jose.exceptions.JWSError: Signature verification failed.

During handling of the above exception, another exception occurred:

Traceback (most recent call last):
  File "C:\Users\Kevin\Desktop\KaminariApi\app\oauthJWT\decodeJwt.py", line 49, in decodeToken2
    return decode(
           ^^^^^^^
  File "C:\Users\Kevin\Desktop\KaminariApi\venv\Lib\site-packages\jose\jwt.py", line 144, in decode
    raise JWTError(e)
jose.exceptions.JWTError: Signature verification failed.
2024-12-27 19:56:54,278 - ERROR - Excepción capturada: Signature verification failed.
Traceback (most recent call last):
  File "C:\Users\Kevin\Desktop\KaminariApi\venv\Lib\site-packages\jose\jws.py", line 262, in _verify_signature
    raise JWSSignatureError()
jose.exceptions.JWSSignatureError

During handling of the above exception, another exception occurred:

Traceback (most recent call last):
  File "C:\Users\Kevin\Desktop\KaminariApi\venv\Lib\site-packages\jose\jwt.py", line 142, in decode
    payload = jws.verify(token, key, algorithms, verify=verify_signature)
              ^^^^^^^^^^^^^^^^^^^^^^^^^^^^^^^^^^^^^^^^^^^^^^^^^^^^^^^^^^^
  File "C:\Users\Kevin\Desktop\KaminariApi\venv\Lib\site-packages\jose\jws.py", line 73, in verify
    _verify_signature(signing_input, header, signature, key, algorithms)
  File "C:\Users\Kevin\Desktop\KaminariApi\venv\Lib\site-packages\jose\jws.py", line 264, in _verify_signature
    raise JWSError("Signature verification failed.")
jose.exceptions.JWSError: Signature verification failed.

During handling of the above exception, another exception occurred:

Traceback (most recent call last):
  File "C:\Users\Kevin\Desktop\KaminariApi\app\oauthJWT\decodeJwt.py", line 50, in decodeToken2
    return decode(
           ^^^^^^^
  File "C:\Users\Kevin\Desktop\KaminariApi\venv\Lib\site-packages\jose\jwt.py", line 144, in decode
    raise JWTError(e)
jose.exceptions.JWTError: Signature verification failed.
2024-12-27 19:59:04,923 - ERROR - Excepción capturada: Signature verification failed.
Traceback (most recent call last):
  File "C:\Users\Kevin\Desktop\KaminariApi\venv\Lib\site-packages\jose\jws.py", line 262, in _verify_signature
    raise JWSSignatureError()
jose.exceptions.JWSSignatureError

During handling of the above exception, another exception occurred:

Traceback (most recent call last):
  File "C:\Users\Kevin\Desktop\KaminariApi\venv\Lib\site-packages\jose\jwt.py", line 142, in decode
    payload = jws.verify(token, key, algorithms, verify=verify_signature)
              ^^^^^^^^^^^^^^^^^^^^^^^^^^^^^^^^^^^^^^^^^^^^^^^^^^^^^^^^^^^
  File "C:\Users\Kevin\Desktop\KaminariApi\venv\Lib\site-packages\jose\jws.py", line 73, in verify
    _verify_signature(signing_input, header, signature, key, algorithms)
  File "C:\Users\Kevin\Desktop\KaminariApi\venv\Lib\site-packages\jose\jws.py", line 264, in _verify_signature
    raise JWSError("Signature verification failed.")
jose.exceptions.JWSError: Signature verification failed.

During handling of the above exception, another exception occurred:

Traceback (most recent call last):
  File "C:\Users\Kevin\Desktop\KaminariApi\app\oauthJWT\decodeJwt.py", line 50, in decodeToken2
    return decode(
           ^^^^^^^
  File "C:\Users\Kevin\Desktop\KaminariApi\venv\Lib\site-packages\jose\jwt.py", line 144, in decode
    raise JWTError(e)
jose.exceptions.JWTError: Signature verification failed.
2024-12-27 20:03:51,732 - ERROR - Excepción capturada: Not enough segments
Traceback (most recent call last):
  File "C:\Users\Kevin\Desktop\KaminariApi\venv\Lib\site-packages\jose\jws.py", line 176, in _load
    signing_input, crypto_segment = jwt.rsplit(b".", 1)
    ^^^^^^^^^^^^^^^^^^^^^^^^^^^^^
ValueError: not enough values to unpack (expected 2, got 1)

During handling of the above exception, another exception occurred:

Traceback (most recent call last):
  File "C:\Users\Kevin\Desktop\KaminariApi\venv\Lib\site-packages\jose\jwt.py", line 142, in decode
    payload = jws.verify(token, key, algorithms, verify=verify_signature)
              ^^^^^^^^^^^^^^^^^^^^^^^^^^^^^^^^^^^^^^^^^^^^^^^^^^^^^^^^^^^
  File "C:\Users\Kevin\Desktop\KaminariApi\venv\Lib\site-packages\jose\jws.py", line 70, in verify
    header, payload, signing_input, signature = _load(token)
                                                ^^^^^^^^^^^^
  File "C:\Users\Kevin\Desktop\KaminariApi\venv\Lib\site-packages\jose\jws.py", line 180, in _load
    raise JWSError("Not enough segments")
jose.exceptions.JWSError: Not enough segments

During handling of the above exception, another exception occurred:

Traceback (most recent call last):
  File "C:\Users\Kevin\Desktop\KaminariApi\app\oauthJWT\decodeJwt.py", line 50, in decodeToken2
    return decode(
           ^^^^^^^
  File "C:\Users\Kevin\Desktop\KaminariApi\venv\Lib\site-packages\jose\jwt.py", line 144, in decode
    raise JWTError(e)
jose.exceptions.JWTError: Not enough segments
2024-12-28 00:14:52,551 - ERROR - Excepción capturada: 'OAuth2PasswordRequestForm' object has no attribute 'username'
Traceback (most recent call last):
  File "C:\Users\Kevin\Desktop\KaminariApi\main.py", line 43, in login
    userInDb = ClienteHandler().crearGetClienteInDb().consultarCliente(username=form_data.username, pwd=form_data.password)
                                                                                ^^^^^^^^^^^^^^^^^^
AttributeError: 'OAuth2PasswordRequestForm' object has no attribute 'username'
2024-12-28 00:28:21,017 - ERROR - Excepción capturada: 'OAuth2PasswordRequestForm' object has no attribute 'email'
Traceback (most recent call last):
  File "C:\Users\Kevin\Desktop\KaminariApi\main.py", line 69, in login
    userInDb = ClienteHandler().crearGetClienteInDb().consultarClienteForEmail(email=formData.email, pwd=formData.password)
                                                                                     ^^^^^^^^^^^^^^
AttributeError: 'OAuth2PasswordRequestForm' object has no attribute 'email'
2024-12-28 00:28:50,124 - ERROR - Excepción capturada: 'OAuth2PasswordRequestForm' object has no attribute 'email'
Traceback (most recent call last):
  File "C:\Users\Kevin\Desktop\KaminariApi\main.py", line 69, in login
    userInDb = ClienteHandler().crearGetClienteInDb().consultarClienteForEmail(email=formData.email, pwd=formData.password)
                                                                                     ^^^^^^^^^^^^^^
AttributeError: 'OAuth2PasswordRequestForm' object has no attribute 'email'
2024-12-28 00:29:15,428 - ERROR - Excepción capturada: 'OAuth2PasswordRequestForm' object has no attribute 'email'
Traceback (most recent call last):
  File "C:\Users\Kevin\Desktop\KaminariApi\main.py", line 69, in login
    userInDb = ClienteHandler().crearGetClienteInDb().consultarClienteForEmail(email=formData.email, pwd=formData.password)
                                                                                     ^^^^^^^^^^^^^^
AttributeError: 'OAuth2PasswordRequestForm' object has no attribute 'email'
2024-12-28 00:31:09,071 - ERROR - Excepción capturada: 'OAuth2PasswordRequestForm' object has no attribute 'email'
Traceback (most recent call last):
  File "C:\Users\Kevin\Desktop\KaminariApi\main.py", line 69, in login
    userInDb = ClienteHandler().crearGetClienteInDb().consultarClienteForEmail(email=formData.email, pwd=formData.password)
                                                                                     ^^^^^^^^^^^^^^
AttributeError: 'OAuth2PasswordRequestForm' object has no attribute 'email'
2024-12-28 00:32:20,428 - ERROR - Excepción capturada: 'OAuth2PasswordRequestForm' object has no attribute 'email'
Traceback (most recent call last):
  File "C:\Users\Kevin\Desktop\KaminariApi\main.py", line 69, in login
    userInDb = ClienteHandler().crearGetClienteInDb().consultarClienteForEmail(email=formData.email, pwd=formData.password)
                                                                                     ^^^^^^^^^^^^^^
AttributeError: 'OAuth2PasswordRequestForm' object has no attribute 'email'
2024-12-28 02:50:29,334 - ERROR - Excepción capturada: Column type NULL on column 'ImagenProductos.id' is not compatible with autoincrement=True
Traceback (most recent call last):
  File "C:\Users\Kevin\Desktop\KaminariApi\app\src\models\dbConect.py", line 21, in guardarCambiosDb
    return Session.commit()
           ^^^^^^^^^^^^^^^^
  File "C:\Users\Kevin\Desktop\KaminariApi\venv\Lib\site-packages\sqlalchemy\orm\session.py", line 2028, in commit
    trans.commit(_to_root=True)
  File "<string>", line 2, in commit
  File "C:\Users\Kevin\Desktop\KaminariApi\venv\Lib\site-packages\sqlalchemy\orm\state_changes.py", line 139, in _go
    ret_value = fn(self, *arg, **kw)
                ^^^^^^^^^^^^^^^^^^^^
  File "C:\Users\Kevin\Desktop\KaminariApi\venv\Lib\site-packages\sqlalchemy\orm\session.py", line 1313, in commit
    self._prepare_impl()
  File "<string>", line 2, in _prepare_impl
  File "C:\Users\Kevin\Desktop\KaminariApi\venv\Lib\site-packages\sqlalchemy\orm\state_changes.py", line 139, in _go
    ret_value = fn(self, *arg, **kw)
                ^^^^^^^^^^^^^^^^^^^^
  File "C:\Users\Kevin\Desktop\KaminariApi\venv\Lib\site-packages\sqlalchemy\orm\session.py", line 1288, in _prepare_impl
    self.session.flush()
  File "C:\Users\Kevin\Desktop\KaminariApi\venv\Lib\site-packages\sqlalchemy\orm\session.py", line 4352, in flush
    self._flush(objects)
  File "C:\Users\Kevin\Desktop\KaminariApi\venv\Lib\site-packages\sqlalchemy\orm\session.py", line 4487, in _flush
    with util.safe_reraise():
  File "C:\Users\Kevin\Desktop\KaminariApi\venv\Lib\site-packages\sqlalchemy\util\langhelpers.py", line 146, in __exit__
    raise exc_value.with_traceback(exc_tb)
  File "C:\Users\Kevin\Desktop\KaminariApi\venv\Lib\site-packages\sqlalchemy\orm\session.py", line 4448, in _flush
    flush_context.execute()
  File "C:\Users\Kevin\Desktop\KaminariApi\venv\Lib\site-packages\sqlalchemy\orm\unitofwork.py", line 466, in execute
    rec.execute(self)
  File "C:\Users\Kevin\Desktop\KaminariApi\venv\Lib\site-packages\sqlalchemy\orm\unitofwork.py", line 642, in execute
    util.preloaded.orm_persistence.save_obj(
  File "C:\Users\Kevin\Desktop\KaminariApi\venv\Lib\site-packages\sqlalchemy\orm\persistence.py", line 93, in save_obj
    _emit_insert_statements(
  File "C:\Users\Kevin\Desktop\KaminariApi\venv\Lib\site-packages\sqlalchemy\orm\persistence.py", line 1233, in _emit_insert_statements
    result = connection.execute(
             ^^^^^^^^^^^^^^^^^^^
  File "C:\Users\Kevin\Desktop\KaminariApi\venv\Lib\site-packages\sqlalchemy\engine\base.py", line 1418, in execute
    return meth(
           ^^^^^
  File "C:\Users\Kevin\Desktop\KaminariApi\venv\Lib\site-packages\sqlalchemy\sql\elements.py", line 515, in _execute_on_connection
    return connection._execute_clauseelement(
           ^^^^^^^^^^^^^^^^^^^^^^^^^^^^^^^^^^
  File "C:\Users\Kevin\Desktop\KaminariApi\venv\Lib\site-packages\sqlalchemy\engine\base.py", line 1632, in _execute_clauseelement
    compiled_sql, extracted_params, cache_hit = elem._compile_w_cache(
                                                ^^^^^^^^^^^^^^^^^^^^^^
  File "C:\Users\Kevin\Desktop\KaminariApi\venv\Lib\site-packages\sqlalchemy\sql\elements.py", line 703, in _compile_w_cache
    compiled_sql = self._compiler(
                   ^^^^^^^^^^^^^^^
  File "C:\Users\Kevin\Desktop\KaminariApi\venv\Lib\site-packages\sqlalchemy\sql\elements.py", line 316, in _compiler
    return dialect.statement_compiler(dialect, self, **kw)
           ^^^^^^^^^^^^^^^^^^^^^^^^^^^^^^^^^^^^^^^^^^^^^^^
  File "C:\Users\Kevin\Desktop\KaminariApi\venv\Lib\site-packages\sqlalchemy\sql\compiler.py", line 1429, in __init__
    Compiled.__init__(self, dialect, statement, **kwargs)
  File "C:\Users\Kevin\Desktop\KaminariApi\venv\Lib\site-packages\sqlalchemy\sql\compiler.py", line 870, in __init__
    self.string = self.process(self.statement, **compile_kwargs)
                  ^^^^^^^^^^^^^^^^^^^^^^^^^^^^^^^^^^^^^^^^^^^^^^
  File "C:\Users\Kevin\Desktop\KaminariApi\venv\Lib\site-packages\sqlalchemy\sql\compiler.py", line 915, in process
    return obj._compiler_dispatch(self, **kwargs)
           ^^^^^^^^^^^^^^^^^^^^^^^^^^^^^^^^^^^^^^
  File "C:\Users\Kevin\Desktop\KaminariApi\venv\Lib\site-packages\sqlalchemy\sql\visitors.py", line 141, in _compiler_dispatch
    return meth(self, **kw)  # type: ignore  # noqa: E501
           ^^^^^^^^^^^^^^^^
  File "C:\Users\Kevin\Desktop\KaminariApi\venv\Lib\site-packages\sqlalchemy\sql\compiler.py", line 5789, in visit_insert
    crud_params_struct = crud._get_crud_params(
                         ^^^^^^^^^^^^^^^^^^^^^^
  File "C:\Users\Kevin\Desktop\KaminariApi\venv\Lib\site-packages\sqlalchemy\sql\crud.py", line 314, in _get_crud_params
    use_insertmanyvalues, use_sentinel_columns = _scan_cols(
                                                 ^^^^^^^^^^^
  File "C:\Users\Kevin\Desktop\KaminariApi\venv\Lib\site-packages\sqlalchemy\sql\crud.py", line 611, in _scan_cols
    ) = _get_returning_modifiers(compiler, stmt, compile_state, toplevel)
        ^^^^^^^^^^^^^^^^^^^^^^^^^^^^^^^^^^^^^^^^^^^^^^^^^^^^^^^^^^^^^^^^^
  File "C:\Users\Kevin\Desktop\KaminariApi\venv\Lib\site-packages\sqlalchemy\sql\crud.py", line 1541, in _get_returning_modifiers
    and stmt.table._autoincrement_column is not None
        ^^^^^^^^^^^^^^^^^^^^^^^^^^^^^^^^
  File "C:\Users\Kevin\Desktop\KaminariApi\venv\Lib\site-packages\sqlalchemy\util\langhelpers.py", line 1130, in __get__
    return self.fget(obj)
           ^^^^^^^^^^^^^^
  File "C:\Users\Kevin\Desktop\KaminariApi\venv\Lib\site-packages\sqlalchemy\sql\schema.py", line 1009, in _autoincrement_column
    return self.primary_key._autoincrement_column
           ^^^^^^^^^^^^^^^^^^^^^^^^^^^^^^^^^^^^^^
  File "C:\Users\Kevin\Desktop\KaminariApi\venv\Lib\site-packages\sqlalchemy\util\langhelpers.py", line 1141, in __get__
    obj.__dict__[self.__name__] = result = self.fget(obj)
                                           ^^^^^^^^^^^^^^
  File "C:\Users\Kevin\Desktop\KaminariApi\venv\Lib\site-packages\sqlalchemy\sql\schema.py", line 5057, in _autoincrement_column
    _validate_autoinc(col, True)
  File "C:\Users\Kevin\Desktop\KaminariApi\venv\Lib\site-packages\sqlalchemy\sql\schema.py", line 5029, in _validate_autoinc
    raise exc.ArgumentError(
sqlalchemy.exc.ArgumentError: Column type NULL on column 'ImagenProductos.id' is not compatible with autoincrement=True
2024-12-28 02:51:53,656 - ERROR - Excepción capturada: Column type NULL on column 'ImagenProductos.id' is not compatible with autoincrement=True
Traceback (most recent call last):
  File "C:\Users\Kevin\Desktop\KaminariApi\app\src\models\dbConect.py", line 21, in guardarCambiosDb
    return Session.commit()
           ^^^^^^^^^^^^^^^^
  File "C:\Users\Kevin\Desktop\KaminariApi\venv\Lib\site-packages\sqlalchemy\orm\session.py", line 2028, in commit
    trans.commit(_to_root=True)
  File "<string>", line 2, in commit
  File "C:\Users\Kevin\Desktop\KaminariApi\venv\Lib\site-packages\sqlalchemy\orm\state_changes.py", line 139, in _go
    ret_value = fn(self, *arg, **kw)
                ^^^^^^^^^^^^^^^^^^^^
  File "C:\Users\Kevin\Desktop\KaminariApi\venv\Lib\site-packages\sqlalchemy\orm\session.py", line 1313, in commit
    self._prepare_impl()
  File "<string>", line 2, in _prepare_impl
  File "C:\Users\Kevin\Desktop\KaminariApi\venv\Lib\site-packages\sqlalchemy\orm\state_changes.py", line 139, in _go
    ret_value = fn(self, *arg, **kw)
                ^^^^^^^^^^^^^^^^^^^^
  File "C:\Users\Kevin\Desktop\KaminariApi\venv\Lib\site-packages\sqlalchemy\orm\session.py", line 1288, in _prepare_impl
    self.session.flush()
  File "C:\Users\Kevin\Desktop\KaminariApi\venv\Lib\site-packages\sqlalchemy\orm\session.py", line 4352, in flush
    self._flush(objects)
  File "C:\Users\Kevin\Desktop\KaminariApi\venv\Lib\site-packages\sqlalchemy\orm\session.py", line 4487, in _flush
    with util.safe_reraise():
  File "C:\Users\Kevin\Desktop\KaminariApi\venv\Lib\site-packages\sqlalchemy\util\langhelpers.py", line 146, in __exit__
    raise exc_value.with_traceback(exc_tb)
  File "C:\Users\Kevin\Desktop\KaminariApi\venv\Lib\site-packages\sqlalchemy\orm\session.py", line 4448, in _flush
    flush_context.execute()
  File "C:\Users\Kevin\Desktop\KaminariApi\venv\Lib\site-packages\sqlalchemy\orm\unitofwork.py", line 466, in execute
    rec.execute(self)
  File "C:\Users\Kevin\Desktop\KaminariApi\venv\Lib\site-packages\sqlalchemy\orm\unitofwork.py", line 642, in execute
    util.preloaded.orm_persistence.save_obj(
  File "C:\Users\Kevin\Desktop\KaminariApi\venv\Lib\site-packages\sqlalchemy\orm\persistence.py", line 93, in save_obj
    _emit_insert_statements(
  File "C:\Users\Kevin\Desktop\KaminariApi\venv\Lib\site-packages\sqlalchemy\orm\persistence.py", line 1233, in _emit_insert_statements
    result = connection.execute(
             ^^^^^^^^^^^^^^^^^^^
  File "C:\Users\Kevin\Desktop\KaminariApi\venv\Lib\site-packages\sqlalchemy\engine\base.py", line 1418, in execute
    return meth(
           ^^^^^
  File "C:\Users\Kevin\Desktop\KaminariApi\venv\Lib\site-packages\sqlalchemy\sql\elements.py", line 515, in _execute_on_connection
    return connection._execute_clauseelement(
           ^^^^^^^^^^^^^^^^^^^^^^^^^^^^^^^^^^
  File "C:\Users\Kevin\Desktop\KaminariApi\venv\Lib\site-packages\sqlalchemy\engine\base.py", line 1632, in _execute_clauseelement
    compiled_sql, extracted_params, cache_hit = elem._compile_w_cache(
                                                ^^^^^^^^^^^^^^^^^^^^^^
  File "C:\Users\Kevin\Desktop\KaminariApi\venv\Lib\site-packages\sqlalchemy\sql\elements.py", line 703, in _compile_w_cache
    compiled_sql = self._compiler(
                   ^^^^^^^^^^^^^^^
  File "C:\Users\Kevin\Desktop\KaminariApi\venv\Lib\site-packages\sqlalchemy\sql\elements.py", line 316, in _compiler
    return dialect.statement_compiler(dialect, self, **kw)
           ^^^^^^^^^^^^^^^^^^^^^^^^^^^^^^^^^^^^^^^^^^^^^^^
  File "C:\Users\Kevin\Desktop\KaminariApi\venv\Lib\site-packages\sqlalchemy\sql\compiler.py", line 1429, in __init__
    Compiled.__init__(self, dialect, statement, **kwargs)
  File "C:\Users\Kevin\Desktop\KaminariApi\venv\Lib\site-packages\sqlalchemy\sql\compiler.py", line 870, in __init__
    self.string = self.process(self.statement, **compile_kwargs)
                  ^^^^^^^^^^^^^^^^^^^^^^^^^^^^^^^^^^^^^^^^^^^^^^
  File "C:\Users\Kevin\Desktop\KaminariApi\venv\Lib\site-packages\sqlalchemy\sql\compiler.py", line 915, in process
    return obj._compiler_dispatch(self, **kwargs)
           ^^^^^^^^^^^^^^^^^^^^^^^^^^^^^^^^^^^^^^
  File "C:\Users\Kevin\Desktop\KaminariApi\venv\Lib\site-packages\sqlalchemy\sql\visitors.py", line 141, in _compiler_dispatch
    return meth(self, **kw)  # type: ignore  # noqa: E501
           ^^^^^^^^^^^^^^^^
  File "C:\Users\Kevin\Desktop\KaminariApi\venv\Lib\site-packages\sqlalchemy\sql\compiler.py", line 5789, in visit_insert
    crud_params_struct = crud._get_crud_params(
                         ^^^^^^^^^^^^^^^^^^^^^^
  File "C:\Users\Kevin\Desktop\KaminariApi\venv\Lib\site-packages\sqlalchemy\sql\crud.py", line 314, in _get_crud_params
    use_insertmanyvalues, use_sentinel_columns = _scan_cols(
                                                 ^^^^^^^^^^^
  File "C:\Users\Kevin\Desktop\KaminariApi\venv\Lib\site-packages\sqlalchemy\sql\crud.py", line 611, in _scan_cols
    ) = _get_returning_modifiers(compiler, stmt, compile_state, toplevel)
        ^^^^^^^^^^^^^^^^^^^^^^^^^^^^^^^^^^^^^^^^^^^^^^^^^^^^^^^^^^^^^^^^^
  File "C:\Users\Kevin\Desktop\KaminariApi\venv\Lib\site-packages\sqlalchemy\sql\crud.py", line 1541, in _get_returning_modifiers
    and stmt.table._autoincrement_column is not None
        ^^^^^^^^^^^^^^^^^^^^^^^^^^^^^^^^
  File "C:\Users\Kevin\Desktop\KaminariApi\venv\Lib\site-packages\sqlalchemy\util\langhelpers.py", line 1130, in __get__
    return self.fget(obj)
           ^^^^^^^^^^^^^^
  File "C:\Users\Kevin\Desktop\KaminariApi\venv\Lib\site-packages\sqlalchemy\sql\schema.py", line 1009, in _autoincrement_column
    return self.primary_key._autoincrement_column
           ^^^^^^^^^^^^^^^^^^^^^^^^^^^^^^^^^^^^^^
  File "C:\Users\Kevin\Desktop\KaminariApi\venv\Lib\site-packages\sqlalchemy\util\langhelpers.py", line 1141, in __get__
    obj.__dict__[self.__name__] = result = self.fget(obj)
                                           ^^^^^^^^^^^^^^
  File "C:\Users\Kevin\Desktop\KaminariApi\venv\Lib\site-packages\sqlalchemy\sql\schema.py", line 5057, in _autoincrement_column
    _validate_autoinc(col, True)
  File "C:\Users\Kevin\Desktop\KaminariApi\venv\Lib\site-packages\sqlalchemy\sql\schema.py", line 5029, in _validate_autoinc
    raise exc.ArgumentError(
sqlalchemy.exc.ArgumentError: Column type NULL on column 'ImagenProductos.id' is not compatible with autoincrement=True
2024-12-28 02:54:24,959 - ERROR - Excepción capturada: (mysql.connector.errors.ProgrammingError) 1146 (42S02): Table 'kaminari.imagenproductos' doesn't exist
[SQL: INSERT INTO `ImagenProductos` (imagen, `idProductoIndumentaria`) VALUES (%(imagen)s, %(idProductoIndumentaria)s)]
[parameters: {'imagen': 'https://geekzilla.tech/todo-lo-que-necesitan-conocer-de-imagen-3-el-generador-de-imagenes-por-ia-de-google/', 'idProductoIndumentaria': 1}]
(Background on this error at: https://sqlalche.me/e/20/f405)
Traceback (most recent call last):
  File "C:\Users\Kevin\Desktop\KaminariApi\venv\Lib\site-packages\mysql\connector\connection_cext.py", line 706, in cmd_query
    self._cmysql.query(
_mysql_connector.MySQLInterfaceError: Table 'kaminari.imagenproductos' doesn't exist

The above exception was the direct cause of the following exception:

Traceback (most recent call last):
  File "C:\Users\Kevin\Desktop\KaminariApi\venv\Lib\site-packages\sqlalchemy\engine\base.py", line 1967, in _exec_single_context
    self.dialect.do_execute(
  File "C:\Users\Kevin\Desktop\KaminariApi\venv\Lib\site-packages\sqlalchemy\engine\default.py", line 941, in do_execute
    cursor.execute(statement, parameters)
  File "C:\Users\Kevin\Desktop\KaminariApi\venv\Lib\site-packages\mysql\connector\cursor_cext.py", line 357, in execute
    result = self._connection.cmd_query(
             ^^^^^^^^^^^^^^^^^^^^^^^^^^^
  File "C:\Users\Kevin\Desktop\KaminariApi\venv\Lib\site-packages\mysql\connector\opentelemetry\context_propagation.py", line 97, in wrapper
    return method(cnx, *args, **kwargs)
           ^^^^^^^^^^^^^^^^^^^^^^^^^^^^
  File "C:\Users\Kevin\Desktop\KaminariApi\venv\Lib\site-packages\mysql\connector\connection_cext.py", line 714, in cmd_query
    raise get_mysql_exception(
mysql.connector.errors.ProgrammingError: 1146 (42S02): Table 'kaminari.imagenproductos' doesn't exist

The above exception was the direct cause of the following exception:

Traceback (most recent call last):
  File "C:\Users\Kevin\Desktop\KaminariApi\app\src\models\dbConect.py", line 21, in guardarCambiosDb
    return Session.commit()
           ^^^^^^^^^^^^^^^^
  File "C:\Users\Kevin\Desktop\KaminariApi\venv\Lib\site-packages\sqlalchemy\orm\session.py", line 2028, in commit
    trans.commit(_to_root=True)
  File "<string>", line 2, in commit
  File "C:\Users\Kevin\Desktop\KaminariApi\venv\Lib\site-packages\sqlalchemy\orm\state_changes.py", line 139, in _go
    ret_value = fn(self, *arg, **kw)
                ^^^^^^^^^^^^^^^^^^^^
  File "C:\Users\Kevin\Desktop\KaminariApi\venv\Lib\site-packages\sqlalchemy\orm\session.py", line 1313, in commit
    self._prepare_impl()
  File "<string>", line 2, in _prepare_impl
  File "C:\Users\Kevin\Desktop\KaminariApi\venv\Lib\site-packages\sqlalchemy\orm\state_changes.py", line 139, in _go
    ret_value = fn(self, *arg, **kw)
                ^^^^^^^^^^^^^^^^^^^^
  File "C:\Users\Kevin\Desktop\KaminariApi\venv\Lib\site-packages\sqlalchemy\orm\session.py", line 1288, in _prepare_impl
    self.session.flush()
  File "C:\Users\Kevin\Desktop\KaminariApi\venv\Lib\site-packages\sqlalchemy\orm\session.py", line 4352, in flush
    self._flush(objects)
  File "C:\Users\Kevin\Desktop\KaminariApi\venv\Lib\site-packages\sqlalchemy\orm\session.py", line 4487, in _flush
    with util.safe_reraise():
  File "C:\Users\Kevin\Desktop\KaminariApi\venv\Lib\site-packages\sqlalchemy\util\langhelpers.py", line 146, in __exit__
    raise exc_value.with_traceback(exc_tb)
  File "C:\Users\Kevin\Desktop\KaminariApi\venv\Lib\site-packages\sqlalchemy\orm\session.py", line 4448, in _flush
    flush_context.execute()
  File "C:\Users\Kevin\Desktop\KaminariApi\venv\Lib\site-packages\sqlalchemy\orm\unitofwork.py", line 466, in execute
    rec.execute(self)
  File "C:\Users\Kevin\Desktop\KaminariApi\venv\Lib\site-packages\sqlalchemy\orm\unitofwork.py", line 642, in execute
    util.preloaded.orm_persistence.save_obj(
  File "C:\Users\Kevin\Desktop\KaminariApi\venv\Lib\site-packages\sqlalchemy\orm\persistence.py", line 93, in save_obj
    _emit_insert_statements(
  File "C:\Users\Kevin\Desktop\KaminariApi\venv\Lib\site-packages\sqlalchemy\orm\persistence.py", line 1233, in _emit_insert_statements
    result = connection.execute(
             ^^^^^^^^^^^^^^^^^^^
  File "C:\Users\Kevin\Desktop\KaminariApi\venv\Lib\site-packages\sqlalchemy\engine\base.py", line 1418, in execute
    return meth(
           ^^^^^
  File "C:\Users\Kevin\Desktop\KaminariApi\venv\Lib\site-packages\sqlalchemy\sql\elements.py", line 515, in _execute_on_connection
    return connection._execute_clauseelement(
           ^^^^^^^^^^^^^^^^^^^^^^^^^^^^^^^^^^
  File "C:\Users\Kevin\Desktop\KaminariApi\venv\Lib\site-packages\sqlalchemy\engine\base.py", line 1640, in _execute_clauseelement
    ret = self._execute_context(
          ^^^^^^^^^^^^^^^^^^^^^^
  File "C:\Users\Kevin\Desktop\KaminariApi\venv\Lib\site-packages\sqlalchemy\engine\base.py", line 1846, in _execute_context
    return self._exec_single_context(
           ^^^^^^^^^^^^^^^^^^^^^^^^^^
  File "C:\Users\Kevin\Desktop\KaminariApi\venv\Lib\site-packages\sqlalchemy\engine\base.py", line 1986, in _exec_single_context
    self._handle_dbapi_exception(
  File "C:\Users\Kevin\Desktop\KaminariApi\venv\Lib\site-packages\sqlalchemy\engine\base.py", line 2355, in _handle_dbapi_exception
    raise sqlalchemy_exception.with_traceback(exc_info[2]) from e
  File "C:\Users\Kevin\Desktop\KaminariApi\venv\Lib\site-packages\sqlalchemy\engine\base.py", line 1967, in _exec_single_context
    self.dialect.do_execute(
  File "C:\Users\Kevin\Desktop\KaminariApi\venv\Lib\site-packages\sqlalchemy\engine\default.py", line 941, in do_execute
    cursor.execute(statement, parameters)
  File "C:\Users\Kevin\Desktop\KaminariApi\venv\Lib\site-packages\mysql\connector\cursor_cext.py", line 357, in execute
    result = self._connection.cmd_query(
             ^^^^^^^^^^^^^^^^^^^^^^^^^^^
  File "C:\Users\Kevin\Desktop\KaminariApi\venv\Lib\site-packages\mysql\connector\opentelemetry\context_propagation.py", line 97, in wrapper
    return method(cnx, *args, **kwargs)
           ^^^^^^^^^^^^^^^^^^^^^^^^^^^^
  File "C:\Users\Kevin\Desktop\KaminariApi\venv\Lib\site-packages\mysql\connector\connection_cext.py", line 714, in cmd_query
    raise get_mysql_exception(
sqlalchemy.exc.ProgrammingError: (mysql.connector.errors.ProgrammingError) 1146 (42S02): Table 'kaminari.imagenproductos' doesn't exist
[SQL: INSERT INTO `ImagenProductos` (imagen, `idProductoIndumentaria`) VALUES (%(imagen)s, %(idProductoIndumentaria)s)]
[parameters: {'imagen': 'https://geekzilla.tech/todo-lo-que-necesitan-conocer-de-imagen-3-el-generador-de-imagenes-por-ia-de-google/', 'idProductoIndumentaria': 1}]
(Background on this error at: https://sqlalche.me/e/20/f405)
2024-12-28 03:13:42,154 - ERROR - Excepción capturada: Mapper 'Mapper[ProductoIndumentaria(ProductoIndumentaria)]' has no property 'Imagenes'.  If this property was indicated from other mappers or configure events, ensure registry.configure() has been called.
Traceback (most recent call last):
  File "C:\Users\Kevin\Desktop\KaminariApi\venv\Lib\site-packages\sqlalchemy\orm\mapper.py", line 2520, in get_property
    return self._props[key]
           ~~~~~~~~~~~^^^^^
KeyError: 'Imagenes'

The above exception was the direct cause of the following exception:

Traceback (most recent call last):
  File "C:\Users\Kevin\Desktop\KaminariApi\app\src\models\productoModels\readProductoModels.py", line 18, in getProductoInDb
    session.query(ProductoIndumentaria)
  File "C:\Users\Kevin\Desktop\KaminariApi\venv\Lib\site-packages\sqlalchemy\orm\session.py", line 2952, in query
    return self._query_cls(entities, self, **kwargs)
           ^^^^^^^^^^^^^^^^^^^^^^^^^^^^^^^^^^^^^^^^^
  File "C:\Users\Kevin\Desktop\KaminariApi\venv\Lib\site-packages\sqlalchemy\orm\query.py", line 275, in __init__
    self._set_entities(entities)
  File "C:\Users\Kevin\Desktop\KaminariApi\venv\Lib\site-packages\sqlalchemy\orm\query.py", line 288, in _set_entities
    coercions.expect(
  File "C:\Users\Kevin\Desktop\KaminariApi\venv\Lib\site-packages\sqlalchemy\sql\coercions.py", line 388, in expect
    insp._post_inspect
  File "C:\Users\Kevin\Desktop\KaminariApi\venv\Lib\site-packages\sqlalchemy\util\langhelpers.py", line 1253, in __get__
    obj.__dict__[self.__name__] = result = self.fget(obj)
                                           ^^^^^^^^^^^^^^
  File "C:\Users\Kevin\Desktop\KaminariApi\venv\Lib\site-packages\sqlalchemy\orm\mapper.py", line 2722, in _post_inspect
    self._check_configure()
  File "C:\Users\Kevin\Desktop\KaminariApi\venv\Lib\site-packages\sqlalchemy\orm\mapper.py", line 2399, in _check_configure
    _configure_registries({self.registry}, cascade=True)
  File "C:\Users\Kevin\Desktop\KaminariApi\venv\Lib\site-packages\sqlalchemy\orm\mapper.py", line 4215, in _configure_registries
    _do_configure_registries(registries, cascade)
  File "C:\Users\Kevin\Desktop\KaminariApi\venv\Lib\site-packages\sqlalchemy\orm\mapper.py", line 4256, in _do_configure_registries
    mapper._post_configure_properties()
  File "C:\Users\Kevin\Desktop\KaminariApi\venv\Lib\site-packages\sqlalchemy\orm\mapper.py", line 2416, in _post_configure_properties
    prop.init()
  File "C:\Users\Kevin\Desktop\KaminariApi\venv\Lib\site-packages\sqlalchemy\orm\interfaces.py", line 589, in init
    self.do_init()
  File "C:\Users\Kevin\Desktop\KaminariApi\venv\Lib\site-packages\sqlalchemy\orm\relationships.py", line 1647, in do_init
    self._generate_backref()
  File "C:\Users\Kevin\Desktop\KaminariApi\venv\Lib\site-packages\sqlalchemy\orm\relationships.py", line 2133, in _generate_backref
    self._add_reverse_property(self.back_populates)
  File "C:\Users\Kevin\Desktop\KaminariApi\venv\Lib\site-packages\sqlalchemy\orm\relationships.py", line 1578, in _add_reverse_property
    other = self.mapper.get_property(key, _configure_mappers=False)
            ^^^^^^^^^^^^^^^^^^^^^^^^^^^^^^^^^^^^^^^^^^^^^^^^^^^^^^^
  File "C:\Users\Kevin\Desktop\KaminariApi\venv\Lib\site-packages\sqlalchemy\orm\mapper.py", line 2522, in get_property
    raise sa_exc.InvalidRequestError(
sqlalchemy.exc.InvalidRequestError: Mapper 'Mapper[ProductoIndumentaria(ProductoIndumentaria)]' has no property 'Imagenes'.  If this property was indicated from other mappers or configure events, ensure registry.configure() has been called.
2024-12-30 14:28:18,881 - ERROR - Excepción capturada: Signature has expired.
Traceback (most recent call last):
  File "C:\Users\Kevin\Desktop\KaminariApi\app\oauthJWT\decodeJwt.py", line 22, in decodeToken
    return decode(
           ^^^^^^^
  File "C:\Users\Kevin\Desktop\KaminariApi\venv\Lib\site-packages\jose\jwt.py", line 157, in decode
    _validate_claims(
  File "C:\Users\Kevin\Desktop\KaminariApi\venv\Lib\site-packages\jose\jwt.py", line 481, in _validate_claims
    _validate_exp(claims, leeway=leeway)
  File "C:\Users\Kevin\Desktop\KaminariApi\venv\Lib\site-packages\jose\jwt.py", line 314, in _validate_exp
    raise ExpiredSignatureError("Signature has expired.")
jose.exceptions.ExpiredSignatureError: Signature has expired.
