2024-11-07 15:56:39,273 - app.src.utils.hanlerError - ERROR - Excepción capturada: 'InfomacionToEncodear' object has no attribute 'valu'
Traceback (most recent call last):
  File "C:\Users\Kevin\Desktop\KaminariApi\app\src\utils\jwtUtils.py", line 25, in encode
    key=InfomacionToEncodear.SECRETKEY.valu,
        ^^^^^^^^^^^^^^^^^^^^^^^^^^^^^^^^^^^
AttributeError: 'InfomacionToEncodear' object has no attribute 'valu'. Did you mean: 'value'?
2024-11-11 12:33:14,247 - ERROR - Excepción capturada: 'InfomacionToEncodear' object has no attribute 'valu'
Traceback (most recent call last):
  File "C:\Users\Kevin\Desktop\KaminariApi\app\src\utils\jwtUtils.py", line 25, in encode
    key=InfomacionToEncodear.SECRETKEY.valu,
        ^^^^^^^^^^^^^^^^^^^^^^^^^^^^^^^^^^^
AttributeError: 'InfomacionToEncodear' object has no attribute 'valu'. Did you mean: 'value'?
2024-11-11 12:33:42,590 - ERROR - Excepción capturada: 'InfomacionToEncodear' object has no attribute 'valu'
Traceback (most recent call last):
  File "C:\Users\Kevin\Desktop\KaminariApi\app\src\utils\jwtUtils.py", line 25, in encode
    key=InfomacionToEncodear.SECRETKEY.valu,
        ^^^^^^^^^^^^^^^^^^^^^^^^^^^^^^^^^^^
AttributeError: 'InfomacionToEncodear' object has no attribute 'valu'. Did you mean: 'value'?
2024-11-11 12:50:38,684 - ERROR - Excepción capturada: 'InfomacionToEncodear' object has no attribute 'valu'
Traceback (most recent call last):
  File "C:\Users\Kevin\Desktop\KaminariApi\app\src\utils\jwtUtils.py", line 26, in encode
    algorithm=InfomacionToEncodear.ALGORITH.valu[0] # para encriptar va en formato str y para desencriptar va en lista
              ^^^^^^^^^^^^^^^^^^^^^^^^^^^^^^^^^^
AttributeError: 'InfomacionToEncodear' object has no attribute 'valu'. Did you mean: 'value'?
2024-11-11 12:53:03,902 - ERROR - Excepción capturada: 'InfomacionToEncodear' object has no attribute 'valu'
Traceback (most recent call last):
  File "C:\Users\Kevin\Desktop\KaminariApi\app\src\utils\jwtUtils.py", line 26, in encode
    algorithm=InfomacionToEncodear.ALGORITH.valu[0] # para encriptar va en formato str y para desencriptar va en lista
              ^^^^^^^^^^^^^^^^^^^^^^^^^^^^^^^^^^
AttributeError: 'InfomacionToEncodear' object has no attribute 'valu'. Did you mean: 'value'?
2024-11-11 14:34:09,140 - ERROR - Form data requires "python-multipart" to be installed. 
You can install "python-multipart" with: 

pip install python-multipart

2024-11-11 15:26:32,935 - ERROR - Excepción capturada: Not enough segments
Traceback (most recent call last):
  File "C:\Users\Kevin\Desktop\KaminariApi\venv\Lib\site-packages\jose\jws.py", line 176, in _load
    signing_input, crypto_segment = jwt.rsplit(b".", 1)
    ^^^^^^^^^^^^^^^^^^^^^^^^^^^^^
ValueError: not enough values to unpack (expected 2, got 1)

During handling of the above exception, another exception occurred:

Traceback (most recent call last):
  File "C:\Users\Kevin\Desktop\KaminariApi\venv\Lib\site-packages\jose\jwt.py", line 142, in decode
    payload = jws.verify(token, key, algorithms, verify=verify_signature)
              ^^^^^^^^^^^^^^^^^^^^^^^^^^^^^^^^^^^^^^^^^^^^^^^^^^^^^^^^^^^
  File "C:\Users\Kevin\Desktop\KaminariApi\venv\Lib\site-packages\jose\jws.py", line 70, in verify
    header, payload, signing_input, signature = _load(token)
                                                ^^^^^^^^^^^^
  File "C:\Users\Kevin\Desktop\KaminariApi\venv\Lib\site-packages\jose\jws.py", line 180, in _load
    raise JWSError("Not enough segments")
jose.exceptions.JWSError: Not enough segments

During handling of the above exception, another exception occurred:

Traceback (most recent call last):
  File "C:\Users\Kevin\Desktop\KaminariApi\app\src\utils\jwtUtils.py", line 48, in decodeToken
    return decode(
           ^^^^^^^
  File "C:\Users\Kevin\Desktop\KaminariApi\venv\Lib\site-packages\jose\jwt.py", line 144, in decode
    raise JWTError(e)
jose.exceptions.JWTError: Not enough segments
2024-11-11 15:30:23,784 - ERROR - Excepción capturada: Not enough segments
Traceback (most recent call last):
  File "C:\Users\Kevin\Desktop\KaminariApi\venv\Lib\site-packages\jose\jws.py", line 176, in _load
    signing_input, crypto_segment = jwt.rsplit(b".", 1)
    ^^^^^^^^^^^^^^^^^^^^^^^^^^^^^
ValueError: not enough values to unpack (expected 2, got 1)

During handling of the above exception, another exception occurred:

Traceback (most recent call last):
  File "C:\Users\Kevin\Desktop\KaminariApi\venv\Lib\site-packages\jose\jwt.py", line 142, in decode
    payload = jws.verify(token, key, algorithms, verify=verify_signature)
              ^^^^^^^^^^^^^^^^^^^^^^^^^^^^^^^^^^^^^^^^^^^^^^^^^^^^^^^^^^^
  File "C:\Users\Kevin\Desktop\KaminariApi\venv\Lib\site-packages\jose\jws.py", line 70, in verify
    header, payload, signing_input, signature = _load(token)
                                                ^^^^^^^^^^^^
  File "C:\Users\Kevin\Desktop\KaminariApi\venv\Lib\site-packages\jose\jws.py", line 180, in _load
    raise JWSError("Not enough segments")
jose.exceptions.JWSError: Not enough segments

During handling of the above exception, another exception occurred:

Traceback (most recent call last):
  File "C:\Users\Kevin\Desktop\KaminariApi\app\src\utils\jwtUtils.py", line 48, in decodeToken
    return decode(
           ^^^^^^^
  File "C:\Users\Kevin\Desktop\KaminariApi\venv\Lib\site-packages\jose\jwt.py", line 144, in decode
    raise JWTError(e)
jose.exceptions.JWTError: Not enough segments
2024-11-11 15:42:15,757 - ERROR - Excepción capturada: Not enough segments
Traceback (most recent call last):
  File "C:\Users\Kevin\Desktop\KaminariApi\venv\Lib\site-packages\jose\jws.py", line 176, in _load
    signing_input, crypto_segment = jwt.rsplit(b".", 1)
    ^^^^^^^^^^^^^^^^^^^^^^^^^^^^^
ValueError: not enough values to unpack (expected 2, got 1)

During handling of the above exception, another exception occurred:

Traceback (most recent call last):
  File "C:\Users\Kevin\Desktop\KaminariApi\venv\Lib\site-packages\jose\jwt.py", line 142, in decode
    payload = jws.verify(token, key, algorithms, verify=verify_signature)
              ^^^^^^^^^^^^^^^^^^^^^^^^^^^^^^^^^^^^^^^^^^^^^^^^^^^^^^^^^^^
  File "C:\Users\Kevin\Desktop\KaminariApi\venv\Lib\site-packages\jose\jws.py", line 70, in verify
    header, payload, signing_input, signature = _load(token)
                                                ^^^^^^^^^^^^
  File "C:\Users\Kevin\Desktop\KaminariApi\venv\Lib\site-packages\jose\jws.py", line 180, in _load
    raise JWSError("Not enough segments")
jose.exceptions.JWSError: Not enough segments

During handling of the above exception, another exception occurred:

Traceback (most recent call last):
  File "C:\Users\Kevin\Desktop\KaminariApi\app\src\utils\jwtUtils.py", line 48, in decodeToken
    return decode(
           ^^^^^^^
  File "C:\Users\Kevin\Desktop\KaminariApi\venv\Lib\site-packages\jose\jwt.py", line 144, in decode
    raise JWTError(e)
jose.exceptions.JWTError: Not enough segments
2024-11-11 15:50:26,941 - ERROR - Excepción capturada: Not enough segments
Traceback (most recent call last):
  File "C:\Users\Kevin\Desktop\KaminariApi\venv\Lib\site-packages\jose\jws.py", line 176, in _load
    signing_input, crypto_segment = jwt.rsplit(b".", 1)
    ^^^^^^^^^^^^^^^^^^^^^^^^^^^^^
ValueError: not enough values to unpack (expected 2, got 1)

During handling of the above exception, another exception occurred:

Traceback (most recent call last):
  File "C:\Users\Kevin\Desktop\KaminariApi\venv\Lib\site-packages\jose\jwt.py", line 142, in decode
    payload = jws.verify(token, key, algorithms, verify=verify_signature)
              ^^^^^^^^^^^^^^^^^^^^^^^^^^^^^^^^^^^^^^^^^^^^^^^^^^^^^^^^^^^
  File "C:\Users\Kevin\Desktop\KaminariApi\venv\Lib\site-packages\jose\jws.py", line 70, in verify
    header, payload, signing_input, signature = _load(token)
                                                ^^^^^^^^^^^^
  File "C:\Users\Kevin\Desktop\KaminariApi\venv\Lib\site-packages\jose\jws.py", line 180, in _load
    raise JWSError("Not enough segments")
jose.exceptions.JWSError: Not enough segments

During handling of the above exception, another exception occurred:

Traceback (most recent call last):
  File "C:\Users\Kevin\Desktop\KaminariApi\app\src\utils\jwtUtils.py", line 48, in decodeToken
    return decode(
           ^^^^^^^
  File "C:\Users\Kevin\Desktop\KaminariApi\venv\Lib\site-packages\jose\jwt.py", line 144, in decode
    raise JWTError(e)
jose.exceptions.JWTError: Not enough segments
2024-11-11 15:53:40,333 - ERROR - Excepción capturada: Not enough segments
Traceback (most recent call last):
  File "C:\Users\Kevin\Desktop\KaminariApi\venv\Lib\site-packages\jose\jws.py", line 176, in _load
    signing_input, crypto_segment = jwt.rsplit(b".", 1)
    ^^^^^^^^^^^^^^^^^^^^^^^^^^^^^
ValueError: not enough values to unpack (expected 2, got 1)

During handling of the above exception, another exception occurred:

Traceback (most recent call last):
  File "C:\Users\Kevin\Desktop\KaminariApi\venv\Lib\site-packages\jose\jwt.py", line 142, in decode
    payload = jws.verify(token, key, algorithms, verify=verify_signature)
              ^^^^^^^^^^^^^^^^^^^^^^^^^^^^^^^^^^^^^^^^^^^^^^^^^^^^^^^^^^^
  File "C:\Users\Kevin\Desktop\KaminariApi\venv\Lib\site-packages\jose\jws.py", line 70, in verify
    header, payload, signing_input, signature = _load(token)
                                                ^^^^^^^^^^^^
  File "C:\Users\Kevin\Desktop\KaminariApi\venv\Lib\site-packages\jose\jws.py", line 180, in _load
    raise JWSError("Not enough segments")
jose.exceptions.JWSError: Not enough segments

During handling of the above exception, another exception occurred:

Traceback (most recent call last):
  File "C:\Users\Kevin\Desktop\KaminariApi\app\src\utils\jwtUtils.py", line 51, in decodeToken
    return decode(
           ^^^^^^^
  File "C:\Users\Kevin\Desktop\KaminariApi\venv\Lib\site-packages\jose\jwt.py", line 144, in decode
    raise JWTError(e)
jose.exceptions.JWTError: Not enough segments
2024-11-15 12:30:40,822 - ERROR - Excepción capturada: cannot access local variable 'datosRequired' where it is not associated with a value
Traceback (most recent call last):
  File "C:\Users\Kevin\Desktop\KaminariApi\main.py", line 28, in login
    userInDb = ClienteHandler().consultarClienteInDb(username=form_data.username, pwd=form_data.password)
               ^^^^^^^^^^^^^^^^^^^^^^^^^^^^^^^^^^^^^^^^^^^^^^^^^^^^^^^^^^^^^^^^^^^^^^^^^^^^^^^^^^^^^^^^^^
  File "C:\Users\Kevin\Desktop\KaminariApi\app\src\schemas\cliente.py", line 127, in consultarClienteInDb
    return datosRequired
           ^^^^^^^^^^^^^
UnboundLocalError: cannot access local variable 'datosRequired' where it is not associated with a value
2024-11-15 12:30:47,610 - ERROR - Excepción capturada: Not enough segments
Traceback (most recent call last):
  File "C:\Users\Kevin\Desktop\KaminariApi\venv\Lib\site-packages\jose\jws.py", line 176, in _load
    signing_input, crypto_segment = jwt.rsplit(b".", 1)
    ^^^^^^^^^^^^^^^^^^^^^^^^^^^^^
ValueError: not enough values to unpack (expected 2, got 1)

During handling of the above exception, another exception occurred:

Traceback (most recent call last):
  File "C:\Users\Kevin\Desktop\KaminariApi\venv\Lib\site-packages\jose\jwt.py", line 142, in decode
    payload = jws.verify(token, key, algorithms, verify=verify_signature)
              ^^^^^^^^^^^^^^^^^^^^^^^^^^^^^^^^^^^^^^^^^^^^^^^^^^^^^^^^^^^
  File "C:\Users\Kevin\Desktop\KaminariApi\venv\Lib\site-packages\jose\jws.py", line 70, in verify
    header, payload, signing_input, signature = _load(token)
                                                ^^^^^^^^^^^^
  File "C:\Users\Kevin\Desktop\KaminariApi\venv\Lib\site-packages\jose\jws.py", line 180, in _load
    raise JWSError("Not enough segments")
jose.exceptions.JWSError: Not enough segments

During handling of the above exception, another exception occurred:

Traceback (most recent call last):
  File "C:\Users\Kevin\Desktop\KaminariApi\app\src\utils\jwtUtils.py", line 50, in decodeToken
    return decode(
           ^^^^^^^
  File "C:\Users\Kevin\Desktop\KaminariApi\venv\Lib\site-packages\jose\jwt.py", line 144, in decode
    raise JWTError(e)
jose.exceptions.JWTError: Not enough segments
2024-11-15 12:31:30,400 - ERROR - Excepción capturada: cannot access local variable 'datosRequired' where it is not associated with a value
Traceback (most recent call last):
  File "C:\Users\Kevin\Desktop\KaminariApi\main.py", line 28, in login
    userInDb = ClienteHandler().consultarClienteInDb(username=form_data.username, pwd=form_data.password)
               ^^^^^^^^^^^^^^^^^^^^^^^^^^^^^^^^^^^^^^^^^^^^^^^^^^^^^^^^^^^^^^^^^^^^^^^^^^^^^^^^^^^^^^^^^^
  File "C:\Users\Kevin\Desktop\KaminariApi\app\src\schemas\cliente.py", line 127, in consultarClienteInDb
    return datosRequired
           ^^^^^^^^^^^^^
UnboundLocalError: cannot access local variable 'datosRequired' where it is not associated with a value
2024-11-15 12:31:38,506 - ERROR - Excepción capturada: Not enough segments
Traceback (most recent call last):
  File "C:\Users\Kevin\Desktop\KaminariApi\venv\Lib\site-packages\jose\jws.py", line 176, in _load
    signing_input, crypto_segment = jwt.rsplit(b".", 1)
    ^^^^^^^^^^^^^^^^^^^^^^^^^^^^^
ValueError: not enough values to unpack (expected 2, got 1)

During handling of the above exception, another exception occurred:

Traceback (most recent call last):
  File "C:\Users\Kevin\Desktop\KaminariApi\venv\Lib\site-packages\jose\jwt.py", line 142, in decode
    payload = jws.verify(token, key, algorithms, verify=verify_signature)
              ^^^^^^^^^^^^^^^^^^^^^^^^^^^^^^^^^^^^^^^^^^^^^^^^^^^^^^^^^^^
  File "C:\Users\Kevin\Desktop\KaminariApi\venv\Lib\site-packages\jose\jws.py", line 70, in verify
    header, payload, signing_input, signature = _load(token)
                                                ^^^^^^^^^^^^
  File "C:\Users\Kevin\Desktop\KaminariApi\venv\Lib\site-packages\jose\jws.py", line 180, in _load
    raise JWSError("Not enough segments")
jose.exceptions.JWSError: Not enough segments

During handling of the above exception, another exception occurred:

Traceback (most recent call last):
  File "C:\Users\Kevin\Desktop\KaminariApi\app\src\utils\jwtUtils.py", line 50, in decodeToken
    return decode(
           ^^^^^^^
  File "C:\Users\Kevin\Desktop\KaminariApi\venv\Lib\site-packages\jose\jwt.py", line 144, in decode
    raise JWTError(e)
jose.exceptions.JWTError: Not enough segments
2024-11-15 12:32:07,477 - ERROR - Excepción capturada: cannot access local variable 'datosRequired' where it is not associated with a value
Traceback (most recent call last):
  File "C:\Users\Kevin\Desktop\KaminariApi\main.py", line 28, in login
    userInDb = ClienteHandler().consultarClienteInDb(username=form_data.username, pwd=form_data.password)
               ^^^^^^^^^^^^^^^^^^^^^^^^^^^^^^^^^^^^^^^^^^^^^^^^^^^^^^^^^^^^^^^^^^^^^^^^^^^^^^^^^^^^^^^^^^
  File "C:\Users\Kevin\Desktop\KaminariApi\app\src\schemas\cliente.py", line 127, in consultarClienteInDb
    return datosRequired
           ^^^^^^^^^^^^^
UnboundLocalError: cannot access local variable 'datosRequired' where it is not associated with a value
2024-11-15 12:32:16,744 - ERROR - Excepción capturada: Not enough segments
Traceback (most recent call last):
  File "C:\Users\Kevin\Desktop\KaminariApi\venv\Lib\site-packages\jose\jws.py", line 176, in _load
    signing_input, crypto_segment = jwt.rsplit(b".", 1)
    ^^^^^^^^^^^^^^^^^^^^^^^^^^^^^
ValueError: not enough values to unpack (expected 2, got 1)

During handling of the above exception, another exception occurred:

Traceback (most recent call last):
  File "C:\Users\Kevin\Desktop\KaminariApi\venv\Lib\site-packages\jose\jwt.py", line 142, in decode
    payload = jws.verify(token, key, algorithms, verify=verify_signature)
              ^^^^^^^^^^^^^^^^^^^^^^^^^^^^^^^^^^^^^^^^^^^^^^^^^^^^^^^^^^^
  File "C:\Users\Kevin\Desktop\KaminariApi\venv\Lib\site-packages\jose\jws.py", line 70, in verify
    header, payload, signing_input, signature = _load(token)
                                                ^^^^^^^^^^^^
  File "C:\Users\Kevin\Desktop\KaminariApi\venv\Lib\site-packages\jose\jws.py", line 180, in _load
    raise JWSError("Not enough segments")
jose.exceptions.JWSError: Not enough segments

During handling of the above exception, another exception occurred:

Traceback (most recent call last):
  File "C:\Users\Kevin\Desktop\KaminariApi\app\src\utils\jwtUtils.py", line 50, in decodeToken
    return decode(
           ^^^^^^^
  File "C:\Users\Kevin\Desktop\KaminariApi\venv\Lib\site-packages\jose\jwt.py", line 144, in decode
    raise JWTError(e)
jose.exceptions.JWTError: Not enough segments
2024-11-15 12:33:08,933 - ERROR - Excepción capturada: Not enough segments
Traceback (most recent call last):
  File "C:\Users\Kevin\Desktop\KaminariApi\venv\Lib\site-packages\jose\jws.py", line 176, in _load
    signing_input, crypto_segment = jwt.rsplit(b".", 1)
    ^^^^^^^^^^^^^^^^^^^^^^^^^^^^^
ValueError: not enough values to unpack (expected 2, got 1)

During handling of the above exception, another exception occurred:

Traceback (most recent call last):
  File "C:\Users\Kevin\Desktop\KaminariApi\venv\Lib\site-packages\jose\jwt.py", line 142, in decode
    payload = jws.verify(token, key, algorithms, verify=verify_signature)
              ^^^^^^^^^^^^^^^^^^^^^^^^^^^^^^^^^^^^^^^^^^^^^^^^^^^^^^^^^^^
  File "C:\Users\Kevin\Desktop\KaminariApi\venv\Lib\site-packages\jose\jws.py", line 70, in verify
    header, payload, signing_input, signature = _load(token)
                                                ^^^^^^^^^^^^
  File "C:\Users\Kevin\Desktop\KaminariApi\venv\Lib\site-packages\jose\jws.py", line 180, in _load
    raise JWSError("Not enough segments")
jose.exceptions.JWSError: Not enough segments

During handling of the above exception, another exception occurred:

Traceback (most recent call last):
  File "C:\Users\Kevin\Desktop\KaminariApi\app\src\utils\jwtUtils.py", line 50, in decodeToken
    return decode(
           ^^^^^^^
  File "C:\Users\Kevin\Desktop\KaminariApi\venv\Lib\site-packages\jose\jwt.py", line 144, in decode
    raise JWTError(e)
jose.exceptions.JWTError: Not enough segments
2024-11-15 12:34:40,453 - ERROR - Excepción capturada: cannot access local variable 'datosRequired' where it is not associated with a value
Traceback (most recent call last):
  File "C:\Users\Kevin\Desktop\KaminariApi\main.py", line 28, in login
    userInDb = ClienteHandler().consultarClienteInDb(username=form_data.username, pwd=form_data.password)
               ^^^^^^^^^^^^^^^^^^^^^^^^^^^^^^^^^^^^^^^^^^^^^^^^^^^^^^^^^^^^^^^^^^^^^^^^^^^^^^^^^^^^^^^^^^
  File "C:\Users\Kevin\Desktop\KaminariApi\app\src\schemas\cliente.py", line 127, in consultarClienteInDb
    return datosRequired
           ^^^^^^^^^^^^^
UnboundLocalError: cannot access local variable 'datosRequired' where it is not associated with a value
2024-11-15 12:36:37,840 - ERROR - Excepción capturada: cannot access local variable 'datosRequired' where it is not associated with a value
Traceback (most recent call last):
  File "C:\Users\Kevin\Desktop\KaminariApi\main.py", line 28, in login
    userInDb = ClienteHandler().consultarClienteInDb(username=form_data.username, pwd=form_data.password)
               ^^^^^^^^^^^^^^^^^^^^^^^^^^^^^^^^^^^^^^^^^^^^^^^^^^^^^^^^^^^^^^^^^^^^^^^^^^^^^^^^^^^^^^^^^^
  File "C:\Users\Kevin\Desktop\KaminariApi\app\src\schemas\cliente.py", line 127, in consultarClienteInDb
    return datosRequired
           ^^^^^^^^^^^^^
UnboundLocalError: cannot access local variable 'datosRequired' where it is not associated with a value
2024-11-15 12:39:16,628 - ERROR - Excepción capturada: cannot access local variable 'datosRequired' where it is not associated with a value
Traceback (most recent call last):
  File "C:\Users\Kevin\Desktop\KaminariApi\main.py", line 28, in login
    userInDb = ClienteHandler().consultarClienteInDb(username=form_data.username, pwd=form_data.password)
               ^^^^^^^^^^^^^^^^^^^^^^^^^^^^^^^^^^^^^^^^^^^^^^^^^^^^^^^^^^^^^^^^^^^^^^^^^^^^^^^^^^^^^^^^^^
  File "C:\Users\Kevin\Desktop\KaminariApi\app\src\schemas\cliente.py", line 127, in consultarClienteInDb
    return datosRequired
           ^^^^^^^^^^^^^
UnboundLocalError: cannot access local variable 'datosRequired' where it is not associated with a value
2024-11-15 12:51:33,618 - ERROR - Excepción capturada: cannot access local variable 'datosRequired' where it is not associated with a value
Traceback (most recent call last):
  File "C:\Users\Kevin\Desktop\KaminariApi\main.py", line 28, in login
    userInDb = ClienteHandler().consultarClienteInDb(username=form_data.username, pwd=form_data.password)
               ^^^^^^^^^^^^^^^^^^^^^^^^^^^^^^^^^^^^^^^^^^^^^^^^^^^^^^^^^^^^^^^^^^^^^^^^^^^^^^^^^^^^^^^^^^
  File "C:\Users\Kevin\Desktop\KaminariApi\app\src\schemas\cliente.py", line 127, in consultarClienteInDb
    return datosRequired
           ^^^^^^^^^^^^^
UnboundLocalError: cannot access local variable 'datosRequired' where it is not associated with a value
2024-11-15 13:00:49,009 - ERROR - Excepción capturada: cannot access local variable 'datosRequired' where it is not associated with a value
Traceback (most recent call last):
  File "C:\Users\Kevin\Desktop\KaminariApi\main.py", line 30, in login
    userInDb = ClienteHandler().consultarClienteInDb(username=form_data.username, pwd=form_data.password)
               ^^^^^^^^^^^^^^^^^^^^^^^^^^^^^^^^^^^^^^^^^^^^^^^^^^^^^^^^^^^^^^^^^^^^^^^^^^^^^^^^^^^^^^^^^^
  File "C:\Users\Kevin\Desktop\KaminariApi\app\src\schemas\cliente.py", line 127, in consultarClienteInDb
    return datosRequired
           ^^^^^^^^^^^^^
UnboundLocalError: cannot access local variable 'datosRequired' where it is not associated with a value
2024-11-15 13:23:23,863 - ERROR - Excepción capturada: cannot access local variable 'datosRequired' where it is not associated with a value
Traceback (most recent call last):
  File "C:\Users\Kevin\Desktop\KaminariApi\main.py", line 30, in login
    userInDb = ClienteHandler().consultarClienteInDb(username=form_data.username, pwd=form_data.password)
               ^^^^^^^^^^^^^^^^^^^^^^^^^^^^^^^^^^^^^^^^^^^^^^^^^^^^^^^^^^^^^^^^^^^^^^^^^^^^^^^^^^^^^^^^^^
  File "C:\Users\Kevin\Desktop\KaminariApi\app\src\schemas\cliente.py", line 127, in consultarClienteInDb
    return datosRequired
           ^^^^^^^^^^^^^
UnboundLocalError: cannot access local variable 'datosRequired' where it is not associated with a value
2024-11-15 13:49:36,579 - ERROR - Excepción capturada: cannot access local variable 'datosRequired' where it is not associated with a value
Traceback (most recent call last):
  File "C:\Users\Kevin\Desktop\KaminariApi\main.py", line 30, in login
    userInDb = ClienteHandler().consultarClienteInDb(username=form_data.username, pwd=form_data.password)
               ^^^^^^^^^^^^^^^^^^^^^^^^^^^^^^^^^^^^^^^^^^^^^^^^^^^^^^^^^^^^^^^^^^^^^^^^^^^^^^^^^^^^^^^^^^
  File "C:\Users\Kevin\Desktop\KaminariApi\app\src\schemas\cliente.py", line 128, in consultarClienteInDb
    return datosRequired
           ^^^^^^^^^^^^^
UnboundLocalError: cannot access local variable 'datosRequired' where it is not associated with a value
2024-11-15 13:51:35,161 - ERROR - Excepción capturada: cannot access local variable 'datosRequired' where it is not associated with a value
Traceback (most recent call last):
  File "C:\Users\Kevin\Desktop\KaminariApi\main.py", line 30, in login
    userInDb = ClienteHandler().consultarClienteInDb(username=form_data.username, pwd=form_data.password)
               ^^^^^^^^^^^^^^^^^^^^^^^^^^^^^^^^^^^^^^^^^^^^^^^^^^^^^^^^^^^^^^^^^^^^^^^^^^^^^^^^^^^^^^^^^^
  File "C:\Users\Kevin\Desktop\KaminariApi\app\src\schemas\cliente.py", line 128, in consultarClienteInDb
    return datosRequired
           ^^^^^^^^^^^^^
UnboundLocalError: cannot access local variable 'datosRequired' where it is not associated with a value
2024-11-15 13:56:32,932 - ERROR - Excepción capturada: cannot access local variable 'datosRequired' where it is not associated with a value
Traceback (most recent call last):
  File "C:\Users\Kevin\Desktop\KaminariApi\main.py", line 30, in login
    userInDb = ClienteHandler().consultarClienteInDb(username=form_data.username, pwd=form_data.password)
               ^^^^^^^^^^^^^^^^^^^^^^^^^^^^^^^^^^^^^^^^^^^^^^^^^^^^^^^^^^^^^^^^^^^^^^^^^^^^^^^^^^^^^^^^^^
  File "C:\Users\Kevin\Desktop\KaminariApi\app\src\schemas\cliente.py", line 128, in consultarClienteInDb
    return datosRequired
           ^^^^^^^^^^^^^
UnboundLocalError: cannot access local variable 'datosRequired' where it is not associated with a value
2024-11-15 14:16:43,093 - ERROR - Excepción capturada: 'NoneType' object has no attribute 'id'
Traceback (most recent call last):
  File "C:\Users\Kevin\Desktop\KaminariApi\main.py", line 30, in login
    userInDb = ClienteHandler().consultarClienteInDb(username=form_data.username, pwd=form_data.password)
               ^^^^^^^^^^^^^^^^^^^^^^^^^^^^^^^^^^^^^^^^^^^^^^^^^^^^^^^^^^^^^^^^^^^^^^^^^^^^^^^^^^^^^^^^^^
  File "C:\Users\Kevin\Desktop\KaminariApi\app\src\schemas\cliente.py", line 124, in consultarClienteInDb
    datosRequired = {'id': cliente.id, 'username': cliente.username, 'pwd': cliente.pwd}
                           ^^^^^^^^^^
AttributeError: 'NoneType' object has no attribute 'id'
2024-11-15 14:17:48,365 - ERROR - Excepción capturada: 'NoneType' object is not subscriptable
Traceback (most recent call last):
  File "C:\Users\Kevin\Desktop\KaminariApi\main.py", line 30, in login
    userInDb = ClienteHandler().consultarClienteInDb(username=form_data.username, pwd=form_data.password)
               ^^^^^^^^^^^^^^^^^^^^^^^^^^^^^^^^^^^^^^^^^^^^^^^^^^^^^^^^^^^^^^^^^^^^^^^^^^^^^^^^^^^^^^^^^^
  File "C:\Users\Kevin\Desktop\KaminariApi\app\src\schemas\cliente.py", line 124, in consultarClienteInDb
    datosRequired = {'id': cliente['id'], 'username': cliente['username'], 'pwd': cliente['pwd']}
                           ~~~~~~~^^^^^^
TypeError: 'NoneType' object is not subscriptable
2024-11-15 14:20:25,491 - ERROR - Excepción capturada: Not enough segments
Traceback (most recent call last):
  File "C:\Users\Kevin\Desktop\KaminariApi\venv\Lib\site-packages\jose\jws.py", line 176, in _load
    signing_input, crypto_segment = jwt.rsplit(b".", 1)
    ^^^^^^^^^^^^^^^^^^^^^^^^^^^^^
ValueError: not enough values to unpack (expected 2, got 1)

During handling of the above exception, another exception occurred:

Traceback (most recent call last):
  File "C:\Users\Kevin\Desktop\KaminariApi\venv\Lib\site-packages\jose\jwt.py", line 142, in decode
    payload = jws.verify(token, key, algorithms, verify=verify_signature)
              ^^^^^^^^^^^^^^^^^^^^^^^^^^^^^^^^^^^^^^^^^^^^^^^^^^^^^^^^^^^
  File "C:\Users\Kevin\Desktop\KaminariApi\venv\Lib\site-packages\jose\jws.py", line 70, in verify
    header, payload, signing_input, signature = _load(token)
                                                ^^^^^^^^^^^^
  File "C:\Users\Kevin\Desktop\KaminariApi\venv\Lib\site-packages\jose\jws.py", line 180, in _load
    raise JWSError("Not enough segments")
jose.exceptions.JWSError: Not enough segments

During handling of the above exception, another exception occurred:

Traceback (most recent call last):
  File "C:\Users\Kevin\Desktop\KaminariApi\app\src\utils\jwtUtils.py", line 51, in decodeToken
    return decode(
           ^^^^^^^
  File "C:\Users\Kevin\Desktop\KaminariApi\venv\Lib\site-packages\jose\jwt.py", line 144, in decode
    raise JWTError(e)
jose.exceptions.JWTError: Not enough segments
2024-11-15 14:23:52,173 - ERROR - Excepción capturada: 401: Credenciales inválidas
Traceback (most recent call last):
  File "C:\Users\Kevin\Desktop\KaminariApi\main.py", line 34, in login
    raise HTTPException(
fastapi.exceptions.HTTPException: 401: Credenciales inválidas
2024-11-15 14:24:34,195 - ERROR - Excepción capturada: Not enough segments
Traceback (most recent call last):
  File "C:\Users\Kevin\Desktop\KaminariApi\venv\Lib\site-packages\jose\jws.py", line 176, in _load
    signing_input, crypto_segment = jwt.rsplit(b".", 1)
    ^^^^^^^^^^^^^^^^^^^^^^^^^^^^^
ValueError: not enough values to unpack (expected 2, got 1)

During handling of the above exception, another exception occurred:

Traceback (most recent call last):
  File "C:\Users\Kevin\Desktop\KaminariApi\venv\Lib\site-packages\jose\jwt.py", line 142, in decode
    payload = jws.verify(token, key, algorithms, verify=verify_signature)
              ^^^^^^^^^^^^^^^^^^^^^^^^^^^^^^^^^^^^^^^^^^^^^^^^^^^^^^^^^^^
  File "C:\Users\Kevin\Desktop\KaminariApi\venv\Lib\site-packages\jose\jws.py", line 70, in verify
    header, payload, signing_input, signature = _load(token)
                                                ^^^^^^^^^^^^
  File "C:\Users\Kevin\Desktop\KaminariApi\venv\Lib\site-packages\jose\jws.py", line 180, in _load
    raise JWSError("Not enough segments")
jose.exceptions.JWSError: Not enough segments

During handling of the above exception, another exception occurred:

Traceback (most recent call last):
  File "C:\Users\Kevin\Desktop\KaminariApi\app\src\utils\jwtUtils.py", line 51, in decodeToken
    return decode(
           ^^^^^^^
  File "C:\Users\Kevin\Desktop\KaminariApi\venv\Lib\site-packages\jose\jwt.py", line 144, in decode
    raise JWTError(e)
jose.exceptions.JWTError: Not enough segments
2024-11-15 14:30:39,908 - ERROR - Excepción capturada: 401: Credenciales inválidas
Traceback (most recent call last):
  File "C:\Users\Kevin\Desktop\KaminariApi\main.py", line 34, in login
    raise HTTPException(
fastapi.exceptions.HTTPException: 401: Credenciales inválidas
2024-11-15 14:30:44,313 - ERROR - Excepción capturada: Not enough segments
Traceback (most recent call last):
  File "C:\Users\Kevin\Desktop\KaminariApi\venv\Lib\site-packages\jose\jws.py", line 176, in _load
    signing_input, crypto_segment = jwt.rsplit(b".", 1)
    ^^^^^^^^^^^^^^^^^^^^^^^^^^^^^
ValueError: not enough values to unpack (expected 2, got 1)

During handling of the above exception, another exception occurred:

Traceback (most recent call last):
  File "C:\Users\Kevin\Desktop\KaminariApi\venv\Lib\site-packages\jose\jwt.py", line 142, in decode
    payload = jws.verify(token, key, algorithms, verify=verify_signature)
              ^^^^^^^^^^^^^^^^^^^^^^^^^^^^^^^^^^^^^^^^^^^^^^^^^^^^^^^^^^^
  File "C:\Users\Kevin\Desktop\KaminariApi\venv\Lib\site-packages\jose\jws.py", line 70, in verify
    header, payload, signing_input, signature = _load(token)
                                                ^^^^^^^^^^^^
  File "C:\Users\Kevin\Desktop\KaminariApi\venv\Lib\site-packages\jose\jws.py", line 180, in _load
    raise JWSError("Not enough segments")
jose.exceptions.JWSError: Not enough segments

During handling of the above exception, another exception occurred:

Traceback (most recent call last):
  File "C:\Users\Kevin\Desktop\KaminariApi\app\src\utils\jwtUtils.py", line 51, in decodeToken
    return decode(
           ^^^^^^^
  File "C:\Users\Kevin\Desktop\KaminariApi\venv\Lib\site-packages\jose\jwt.py", line 144, in decode
    raise JWTError(e)
jose.exceptions.JWTError: Not enough segments
2024-11-15 14:34:25,018 - ERROR - Excepción capturada: 401: Credenciales inválidas
Traceback (most recent call last):
  File "C:\Users\Kevin\Desktop\KaminariApi\main.py", line 34, in login
    raise HTTPException(
fastapi.exceptions.HTTPException: 401: Credenciales inválidas
2024-11-15 14:34:42,050 - ERROR - Excepción capturada: Not enough segments
Traceback (most recent call last):
  File "C:\Users\Kevin\Desktop\KaminariApi\venv\Lib\site-packages\jose\jws.py", line 176, in _load
    signing_input, crypto_segment = jwt.rsplit(b".", 1)
    ^^^^^^^^^^^^^^^^^^^^^^^^^^^^^
ValueError: not enough values to unpack (expected 2, got 1)

During handling of the above exception, another exception occurred:

Traceback (most recent call last):
  File "C:\Users\Kevin\Desktop\KaminariApi\venv\Lib\site-packages\jose\jwt.py", line 142, in decode
    payload = jws.verify(token, key, algorithms, verify=verify_signature)
              ^^^^^^^^^^^^^^^^^^^^^^^^^^^^^^^^^^^^^^^^^^^^^^^^^^^^^^^^^^^
  File "C:\Users\Kevin\Desktop\KaminariApi\venv\Lib\site-packages\jose\jws.py", line 70, in verify
    header, payload, signing_input, signature = _load(token)
                                                ^^^^^^^^^^^^
  File "C:\Users\Kevin\Desktop\KaminariApi\venv\Lib\site-packages\jose\jws.py", line 180, in _load
    raise JWSError("Not enough segments")
jose.exceptions.JWSError: Not enough segments

During handling of the above exception, another exception occurred:

Traceback (most recent call last):
  File "C:\Users\Kevin\Desktop\KaminariApi\app\src\utils\jwtUtils.py", line 51, in decodeToken
    return decode(
           ^^^^^^^
  File "C:\Users\Kevin\Desktop\KaminariApi\venv\Lib\site-packages\jose\jwt.py", line 144, in decode
    raise JWTError(e)
jose.exceptions.JWTError: Not enough segments
2024-11-15 15:31:35,775 - ERROR - Excepción capturada: 401: Credenciales inválidas
Traceback (most recent call last):
  File "C:\Users\Kevin\Desktop\KaminariApi\main.py", line 34, in login
    raise HTTPException(
fastapi.exceptions.HTTPException: 401: Credenciales inválidas
2024-11-15 15:32:32,011 - ERROR - Excepción capturada: Not enough segments
Traceback (most recent call last):
  File "C:\Users\Kevin\Desktop\KaminariApi\venv\Lib\site-packages\jose\jws.py", line 176, in _load
    signing_input, crypto_segment = jwt.rsplit(b".", 1)
    ^^^^^^^^^^^^^^^^^^^^^^^^^^^^^
ValueError: not enough values to unpack (expected 2, got 1)

During handling of the above exception, another exception occurred:

Traceback (most recent call last):
  File "C:\Users\Kevin\Desktop\KaminariApi\venv\Lib\site-packages\jose\jwt.py", line 142, in decode
    payload = jws.verify(token, key, algorithms, verify=verify_signature)
              ^^^^^^^^^^^^^^^^^^^^^^^^^^^^^^^^^^^^^^^^^^^^^^^^^^^^^^^^^^^
  File "C:\Users\Kevin\Desktop\KaminariApi\venv\Lib\site-packages\jose\jws.py", line 70, in verify
    header, payload, signing_input, signature = _load(token)
                                                ^^^^^^^^^^^^
  File "C:\Users\Kevin\Desktop\KaminariApi\venv\Lib\site-packages\jose\jws.py", line 180, in _load
    raise JWSError("Not enough segments")
jose.exceptions.JWSError: Not enough segments

During handling of the above exception, another exception occurred:

Traceback (most recent call last):
  File "C:\Users\Kevin\Desktop\KaminariApi\app\src\utils\jwtUtils.py", line 51, in decodeToken
    return decode(
           ^^^^^^^
  File "C:\Users\Kevin\Desktop\KaminariApi\venv\Lib\site-packages\jose\jwt.py", line 144, in decode
    raise JWTError(e)
jose.exceptions.JWTError: Not enough segments
2024-11-15 15:40:18,232 - ERROR - Excepción capturada: 401: Credenciales inválidas
Traceback (most recent call last):
  File "C:\Users\Kevin\Desktop\KaminariApi\main.py", line 34, in login
    raise HTTPException(
fastapi.exceptions.HTTPException: 401: Credenciales inválidas
2024-11-15 15:40:22,453 - ERROR - Excepción capturada: Not enough segments
Traceback (most recent call last):
  File "C:\Users\Kevin\Desktop\KaminariApi\venv\Lib\site-packages\jose\jws.py", line 176, in _load
    signing_input, crypto_segment = jwt.rsplit(b".", 1)
    ^^^^^^^^^^^^^^^^^^^^^^^^^^^^^
ValueError: not enough values to unpack (expected 2, got 1)

During handling of the above exception, another exception occurred:

Traceback (most recent call last):
  File "C:\Users\Kevin\Desktop\KaminariApi\venv\Lib\site-packages\jose\jwt.py", line 142, in decode
    payload = jws.verify(token, key, algorithms, verify=verify_signature)
              ^^^^^^^^^^^^^^^^^^^^^^^^^^^^^^^^^^^^^^^^^^^^^^^^^^^^^^^^^^^
  File "C:\Users\Kevin\Desktop\KaminariApi\venv\Lib\site-packages\jose\jws.py", line 70, in verify
    header, payload, signing_input, signature = _load(token)
                                                ^^^^^^^^^^^^
  File "C:\Users\Kevin\Desktop\KaminariApi\venv\Lib\site-packages\jose\jws.py", line 180, in _load
    raise JWSError("Not enough segments")
jose.exceptions.JWSError: Not enough segments

During handling of the above exception, another exception occurred:

Traceback (most recent call last):
  File "C:\Users\Kevin\Desktop\KaminariApi\app\src\utils\jwtUtils.py", line 51, in decodeToken
    return decode(
           ^^^^^^^
  File "C:\Users\Kevin\Desktop\KaminariApi\venv\Lib\site-packages\jose\jwt.py", line 144, in decode
    raise JWTError(e)
jose.exceptions.JWTError: Not enough segments
2024-11-15 15:44:58,405 - ERROR - Excepción capturada: 401: Credenciales inválidas
Traceback (most recent call last):
  File "C:\Users\Kevin\Desktop\KaminariApi\main.py", line 34, in login
    raise HTTPException(
fastapi.exceptions.HTTPException: 401: Credenciales inválidas
2024-11-15 15:46:27,233 - ERROR - Excepción capturada: 401: Credenciales inválidas
Traceback (most recent call last):
  File "C:\Users\Kevin\Desktop\KaminariApi\main.py", line 34, in login
    raise HTTPException(
fastapi.exceptions.HTTPException: 401: Credenciales inválidas
2024-11-15 15:46:31,684 - ERROR - Excepción capturada: Not enough segments
Traceback (most recent call last):
  File "C:\Users\Kevin\Desktop\KaminariApi\venv\Lib\site-packages\jose\jws.py", line 176, in _load
    signing_input, crypto_segment = jwt.rsplit(b".", 1)
    ^^^^^^^^^^^^^^^^^^^^^^^^^^^^^
ValueError: not enough values to unpack (expected 2, got 1)

During handling of the above exception, another exception occurred:

Traceback (most recent call last):
  File "C:\Users\Kevin\Desktop\KaminariApi\venv\Lib\site-packages\jose\jwt.py", line 142, in decode
    payload = jws.verify(token, key, algorithms, verify=verify_signature)
              ^^^^^^^^^^^^^^^^^^^^^^^^^^^^^^^^^^^^^^^^^^^^^^^^^^^^^^^^^^^
  File "C:\Users\Kevin\Desktop\KaminariApi\venv\Lib\site-packages\jose\jws.py", line 70, in verify
    header, payload, signing_input, signature = _load(token)
                                                ^^^^^^^^^^^^
  File "C:\Users\Kevin\Desktop\KaminariApi\venv\Lib\site-packages\jose\jws.py", line 180, in _load
    raise JWSError("Not enough segments")
jose.exceptions.JWSError: Not enough segments

During handling of the above exception, another exception occurred:

Traceback (most recent call last):
  File "C:\Users\Kevin\Desktop\KaminariApi\app\src\utils\jwtUtils.py", line 51, in decodeToken
    return decode(
           ^^^^^^^
  File "C:\Users\Kevin\Desktop\KaminariApi\venv\Lib\site-packages\jose\jwt.py", line 144, in decode
    raise JWTError(e)
jose.exceptions.JWTError: Not enough segments
2024-11-15 15:47:50,045 - ERROR - Excepción capturada: 401: Credenciales inválidas
Traceback (most recent call last):
  File "C:\Users\Kevin\Desktop\KaminariApi\main.py", line 34, in login
    raise HTTPException(
fastapi.exceptions.HTTPException: 401: Credenciales inválidas
2024-11-15 15:47:57,890 - ERROR - Excepción capturada: Not enough segments
Traceback (most recent call last):
  File "C:\Users\Kevin\Desktop\KaminariApi\venv\Lib\site-packages\jose\jws.py", line 176, in _load
    signing_input, crypto_segment = jwt.rsplit(b".", 1)
    ^^^^^^^^^^^^^^^^^^^^^^^^^^^^^
ValueError: not enough values to unpack (expected 2, got 1)

During handling of the above exception, another exception occurred:

Traceback (most recent call last):
  File "C:\Users\Kevin\Desktop\KaminariApi\venv\Lib\site-packages\jose\jwt.py", line 142, in decode
    payload = jws.verify(token, key, algorithms, verify=verify_signature)
              ^^^^^^^^^^^^^^^^^^^^^^^^^^^^^^^^^^^^^^^^^^^^^^^^^^^^^^^^^^^
  File "C:\Users\Kevin\Desktop\KaminariApi\venv\Lib\site-packages\jose\jws.py", line 70, in verify
    header, payload, signing_input, signature = _load(token)
                                                ^^^^^^^^^^^^
  File "C:\Users\Kevin\Desktop\KaminariApi\venv\Lib\site-packages\jose\jws.py", line 180, in _load
    raise JWSError("Not enough segments")
jose.exceptions.JWSError: Not enough segments

During handling of the above exception, another exception occurred:

Traceback (most recent call last):
  File "C:\Users\Kevin\Desktop\KaminariApi\app\src\utils\jwtUtils.py", line 51, in decodeToken
    return decode(
           ^^^^^^^
  File "C:\Users\Kevin\Desktop\KaminariApi\venv\Lib\site-packages\jose\jwt.py", line 144, in decode
    raise JWTError(e)
jose.exceptions.JWTError: Not enough segments
2024-11-15 15:51:15,419 - ERROR - Excepción capturada: 401: Credenciales inválidas
Traceback (most recent call last):
  File "C:\Users\Kevin\Desktop\KaminariApi\main.py", line 34, in login
    raise HTTPException(
fastapi.exceptions.HTTPException: 401: Credenciales inválidas
2024-11-15 15:51:28,704 - ERROR - Excepción capturada: Not enough segments
Traceback (most recent call last):
  File "C:\Users\Kevin\Desktop\KaminariApi\venv\Lib\site-packages\jose\jws.py", line 176, in _load
    signing_input, crypto_segment = jwt.rsplit(b".", 1)
    ^^^^^^^^^^^^^^^^^^^^^^^^^^^^^
ValueError: not enough values to unpack (expected 2, got 1)

During handling of the above exception, another exception occurred:

Traceback (most recent call last):
  File "C:\Users\Kevin\Desktop\KaminariApi\venv\Lib\site-packages\jose\jwt.py", line 142, in decode
    payload = jws.verify(token, key, algorithms, verify=verify_signature)
              ^^^^^^^^^^^^^^^^^^^^^^^^^^^^^^^^^^^^^^^^^^^^^^^^^^^^^^^^^^^
  File "C:\Users\Kevin\Desktop\KaminariApi\venv\Lib\site-packages\jose\jws.py", line 70, in verify
    header, payload, signing_input, signature = _load(token)
                                                ^^^^^^^^^^^^
  File "C:\Users\Kevin\Desktop\KaminariApi\venv\Lib\site-packages\jose\jws.py", line 180, in _load
    raise JWSError("Not enough segments")
jose.exceptions.JWSError: Not enough segments

During handling of the above exception, another exception occurred:

Traceback (most recent call last):
  File "C:\Users\Kevin\Desktop\KaminariApi\app\src\utils\jwtUtils.py", line 51, in decodeToken
    return decode(
           ^^^^^^^
  File "C:\Users\Kevin\Desktop\KaminariApi\venv\Lib\site-packages\jose\jwt.py", line 144, in decode
    raise JWTError(e)
jose.exceptions.JWTError: Not enough segments
2024-11-15 15:54:04,087 - ERROR - Excepción capturada: 401: Credenciales inválidas
Traceback (most recent call last):
  File "C:\Users\Kevin\Desktop\KaminariApi\main.py", line 34, in login
    raise HTTPException(
fastapi.exceptions.HTTPException: 401: Credenciales inválidas
2024-11-15 15:55:12,610 - ERROR - Excepción capturada: 401: Credenciales inválidas
Traceback (most recent call last):
  File "C:\Users\Kevin\Desktop\KaminariApi\main.py", line 34, in login
    raise HTTPException(
fastapi.exceptions.HTTPException: 401: Credenciales inválidas
2024-11-15 17:19:28,612 - ERROR - Excepción capturada: 401: Credenciales inválidas
Traceback (most recent call last):
  File "C:\Users\Kevin\Desktop\KaminariApi\main.py", line 36, in login
    raise HTTPException(
fastapi.exceptions.HTTPException: 401: Credenciales inválidas
2024-11-15 17:19:50,363 - ERROR - Excepción capturada: 'Cliente' object is not subscriptable
Traceback (most recent call last):
  File "C:\Users\Kevin\Desktop\KaminariApi\app\src\schemas\cliente.py", line 120, in consultarClienteInDb
    datosRequired = {'id': cliente['id'], 'username': cliente['username'], 'pwd': cliente['pwd']}
                           ~~~~~~~^^^^^^
TypeError: 'Cliente' object is not subscriptable
2024-11-15 17:19:50,366 - ERROR - Excepción capturada: string indices must be integers, not 'str'
Traceback (most recent call last):
  File "C:\Users\Kevin\Desktop\KaminariApi\main.py", line 33, in login
    if not userInDb or form_data.password != userInDb['pwd']:
                                             ~~~~~~~~^^^^^^^
TypeError: string indices must be integers, not 'str'
2024-11-15 17:37:30,793 - ERROR - Excepción capturada: 401: Credenciales inválidas
Traceback (most recent call last):
  File "C:\Users\Kevin\Desktop\KaminariApi\main.py", line 36, in login
    raise HTTPException(
fastapi.exceptions.HTTPException: 401: Credenciales inválidas
2024-11-15 17:38:09,851 - ERROR - Excepción capturada: 'Cliente' object is not subscriptable
Traceback (most recent call last):
  File "C:\Users\Kevin\Desktop\KaminariApi\app\src\schemas\cliente.py", line 120, in consultarClienteInDb
    datosRequired = {'id': cliente['id'], 'username': cliente['username'], 'pwd': cliente['pwd']}
                           ~~~~~~~^^^^^^
TypeError: 'Cliente' object is not subscriptable
2024-11-15 17:38:09,854 - ERROR - Excepción capturada: 401: Credenciales inválidas
Traceback (most recent call last):
  File "C:\Users\Kevin\Desktop\KaminariApi\main.py", line 36, in login
    raise HTTPException(
fastapi.exceptions.HTTPException: 401: Credenciales inválidas
2024-11-15 17:39:07,003 - ERROR - Excepción capturada: 'Cliente' object is not subscriptable
Traceback (most recent call last):
  File "C:\Users\Kevin\Desktop\KaminariApi\app\src\schemas\cliente.py", line 120, in consultarClienteInDb
    datosRequired = {'id': cliente['id'], 'username': cliente['username'], 'pwd': cliente['pwd']}
                           ~~~~~~~^^^^^^
TypeError: 'Cliente' object is not subscriptable
2024-11-15 17:39:07,006 - ERROR - Excepción capturada: 401: Credenciales inválidas
Traceback (most recent call last):
  File "C:\Users\Kevin\Desktop\KaminariApi\main.py", line 36, in login
    raise HTTPException(
fastapi.exceptions.HTTPException: 401: Credenciales inválidas
2024-11-16 19:19:26,507 - ERROR - Excepción capturada: GetProducto.__init__() got an unexpected keyword argument 'session'
Traceback (most recent call last):
  File "C:\Users\Kevin\Desktop\KaminariApi\app\src\schemas\producto.py", line 72, in crearGetProducto
    producto: GetProducto = GetProducto(session=session, id=id)
                            ^^^^^^^^^^^^^^^^^^^^^^^^^^^^^^^^^^^
TypeError: GetProducto.__init__() got an unexpected keyword argument 'session'
2024-11-17 19:44:33,926 - ERROR - Excepción capturada: 401: Credenciales inválidas
Traceback (most recent call last):
  File "C:\Users\Kevin\Desktop\KaminariApi\main.py", line 39, in login
    raise HTTPException(
fastapi.exceptions.HTTPException: 401: Credenciales inválidas
2024-11-17 19:45:07,255 - ERROR - Excepción capturada: 401: Credenciales inválidas
Traceback (most recent call last):
  File "C:\Users\Kevin\Desktop\KaminariApi\main.py", line 39, in login
    raise HTTPException(
fastapi.exceptions.HTTPException: 401: Credenciales inválidas
2024-11-17 19:47:38,524 - ERROR - Excepción capturada: 'int' object has no attribute 'value'
Traceback (most recent call last):
  File "C:\Users\Kevin\Desktop\KaminariApi\app\oauthJWT\encodeJwt.py", line 15, in encodeTheStr
    expiration = datetime.now(timezone.utc) + timedelta(minutes=InfomacionToEncodear.EXPIRETOKEN.value)
                                                                ^^^^^^^^^^^^^^^^^^^^^^^^^^^^^^^^^^^^^^
AttributeError: 'int' object has no attribute 'value'
2024-11-17 19:47:43,610 - ERROR - Excepción capturada: 'str' object has no attribute 'value'
Traceback (most recent call last):
  File "C:\Users\Kevin\Desktop\KaminariApi\app\oauthJWT\decodeJwt.py", line 24, in decodeToken
    key=InfomacionToEncodear.SECRETKEY.value,
        ^^^^^^^^^^^^^^^^^^^^^^^^^^^^^^^^^^^^
AttributeError: 'str' object has no attribute 'value'
2024-11-17 19:47:56,803 - ERROR - Excepción capturada: 401: Credenciales inválidas
Traceback (most recent call last):
  File "C:\Users\Kevin\Desktop\KaminariApi\main.py", line 39, in login
    raise HTTPException(
fastapi.exceptions.HTTPException: 401: Credenciales inválidas
2024-11-17 19:48:55,409 - ERROR - Excepción capturada: 'int' object has no attribute 'value'
Traceback (most recent call last):
  File "C:\Users\Kevin\Desktop\KaminariApi\app\oauthJWT\encodeJwt.py", line 15, in encodeTheStr
    expiration = datetime.now(timezone.utc) + timedelta(minutes=InfomacionToEncodear.EXPIRETOKEN.value)
                                                                ^^^^^^^^^^^^^^^^^^^^^^^^^^^^^^^^^^^^^^
AttributeError: 'int' object has no attribute 'value'
2024-11-17 19:48:58,435 - ERROR - Excepción capturada: 'str' object has no attribute 'value'
Traceback (most recent call last):
  File "C:\Users\Kevin\Desktop\KaminariApi\app\oauthJWT\decodeJwt.py", line 24, in decodeToken
    key=InfomacionToEncodear.SECRETKEY.value,
        ^^^^^^^^^^^^^^^^^^^^^^^^^^^^^^^^^^^^
AttributeError: 'str' object has no attribute 'value'
2024-11-17 20:04:37,059 - ERROR - Excepción capturada: 401: Credenciales inválidas
Traceback (most recent call last):
  File "C:\Users\Kevin\Desktop\KaminariApi\main.py", line 39, in login
    raise HTTPException(
fastapi.exceptions.HTTPException: 401: Credenciales inválidas
2024-11-18 00:10:28,889 - ERROR - Excepción capturada: 'ClienteHandler' object has no attribute 'conexionDb'
Traceback (most recent call last):
  File "C:\Users\Kevin\Desktop\KaminariApi\app\src\models\usuarioModels\contollerUsuario.py", line 29, in consultarClienteInDb
    session = self.conexionDb.abrirConexion()
              ^^^^^^^^^^^^^^^
AttributeError: 'ClienteHandler' object has no attribute 'conexionDb'
2024-11-18 00:10:28,896 - ERROR - Excepción capturada: 401: Credenciales inválidas
Traceback (most recent call last):
  File "C:\Users\Kevin\Desktop\KaminariApi\main.py", line 39, in login
    raise HTTPException(
fastapi.exceptions.HTTPException: 401: Credenciales inválidas
2024-11-18 00:10:55,657 - ERROR - Excepción capturada: 'ClienteHandler' object has no attribute 'conexionDb'
Traceback (most recent call last):
  File "C:\Users\Kevin\Desktop\KaminariApi\app\src\models\usuarioModels\contollerUsuario.py", line 29, in consultarClienteInDb
    session = self.conexionDb.abrirConexion()
              ^^^^^^^^^^^^^^^
AttributeError: 'ClienteHandler' object has no attribute 'conexionDb'
2024-11-18 00:10:55,661 - ERROR - Excepción capturada: 401: Credenciales inválidas
Traceback (most recent call last):
  File "C:\Users\Kevin\Desktop\KaminariApi\main.py", line 39, in login
    raise HTTPException(
fastapi.exceptions.HTTPException: 401: Credenciales inválidas
2024-11-18 00:12:14,213 - ERROR - Excepción capturada: 'ClienteHandler' object has no attribute 'consultarClienteInDb'
Traceback (most recent call last):
  File "C:\Users\Kevin\Desktop\KaminariApi\main.py", line 35, in login
    userInDb = ClienteHandler().consultarClienteInDb(username=form_data.username, pwd=form_data.password)
               ^^^^^^^^^^^^^^^^^^^^^^^^^^^^^^^^^^^^^
AttributeError: 'ClienteHandler' object has no attribute 'consultarClienteInDb'
2024-11-18 00:13:01,523 - ERROR - Excepción capturada: 'ClienteHandler' object has no attribute 'consultarClienteInDb'
Traceback (most recent call last):
  File "C:\Users\Kevin\Desktop\KaminariApi\main.py", line 35, in login
    userInDb = ClienteHandler().consultarClienteInDb(username=form_data.username, pwd=form_data.password)
               ^^^^^^^^^^^^^^^^^^^^^^^^^^^^^^^^^^^^^
AttributeError: 'ClienteHandler' object has no attribute 'consultarClienteInDb'
2024-11-18 00:16:33,993 - ERROR - Excepción capturada: 'ClienteHandler' object has no attribute 'consultarClienteInDb'
Traceback (most recent call last):
  File "C:\Users\Kevin\Desktop\KaminariApi\main.py", line 35, in login
    userInDb = ClienteHandler().consultarClienteInDb(username=form_data.username, pwd=form_data.password)
               ^^^^^^^^^^^^^^^^^^^^^^^^^^^^^^^^^^^^^
AttributeError: 'ClienteHandler' object has no attribute 'consultarClienteInDb'
2024-11-18 00:17:47,762 - ERROR - Excepción capturada: 'ClienteHandler' object has no attribute 'consultarClienteInDb'
Traceback (most recent call last):
  File "C:\Users\Kevin\Desktop\KaminariApi\main.py", line 35, in login
    userInDb = ClienteHandler().consultarClienteInDb(username=form_data.username, pwd=form_data.password)
               ^^^^^^^^^^^^^^^^^^^^^^^^^^^^^^^^^^^^^
AttributeError: 'ClienteHandler' object has no attribute 'consultarClienteInDb'
2024-11-18 00:18:34,605 - ERROR - Excepción capturada: 'ClienteHandler' object has no attribute 'consultarClienteInDb'
Traceback (most recent call last):
  File "C:\Users\Kevin\Desktop\KaminariApi\main.py", line 35, in login
    userInDb = ClienteHandler().consultarClienteInDb(username=form_data.username, pwd=form_data.password)
               ^^^^^^^^^^^^^^^^^^^^^^^^^^^^^^^^^^^^^
AttributeError: 'ClienteHandler' object has no attribute 'consultarClienteInDb'
2024-11-18 00:21:22,740 - ERROR - Excepción capturada: 'Cliente' object is not subscriptable
Traceback (most recent call last):
  File "C:\Users\Kevin\Desktop\KaminariApi\main.py", line 36, in login
    if not userInDb or form_data.password != userInDb['pwd']:
                                             ~~~~~~~~^^^^^^^
TypeError: 'Cliente' object is not subscriptable
2024-11-18 00:22:13,698 - ERROR - Excepción capturada: 'Cliente' object is not subscriptable
Traceback (most recent call last):
  File "C:\Users\Kevin\Desktop\KaminariApi\main.py", line 37, in login
    if not userInDb or form_data.password != userInDb['pwd']:
                                             ~~~~~~~~^^^^^^^
TypeError: 'Cliente' object is not subscriptable
2024-11-18 00:24:37,554 - ERROR - Excepción capturada: Instance <Cliente at 0x1f843ac4560> is not bound to a Session; attribute refresh operation cannot proceed (Background on this error at: https://sqlalche.me/e/20/bhk3)
Traceback (most recent call last):
  File "C:\Users\Kevin\Desktop\KaminariApi\main.py", line 37, in login
    if not userInDb or form_data.password != userInDb.pwd:
                                             ^^^^^^^^^^^^
  File "C:\Users\Kevin\Desktop\KaminariApi\venv\Lib\site-packages\sqlalchemy\orm\attributes.py", line 566, in __get__
    return self.impl.get(state, dict_)  # type: ignore[no-any-return]
           ^^^^^^^^^^^^^^^^^^^^^^^^^^^
  File "C:\Users\Kevin\Desktop\KaminariApi\venv\Lib\site-packages\sqlalchemy\orm\attributes.py", line 1086, in get
    value = self._fire_loader_callables(state, key, passive)
            ^^^^^^^^^^^^^^^^^^^^^^^^^^^^^^^^^^^^^^^^^^^^^^^^
  File "C:\Users\Kevin\Desktop\KaminariApi\venv\Lib\site-packages\sqlalchemy\orm\attributes.py", line 1116, in _fire_loader_callables
    return state._load_expired(state, passive)
           ^^^^^^^^^^^^^^^^^^^^^^^^^^^^^^^^^^^
  File "C:\Users\Kevin\Desktop\KaminariApi\venv\Lib\site-packages\sqlalchemy\orm\state.py", line 803, in _load_expired
    self.manager.expired_attribute_loader(self, toload, passive)
  File "C:\Users\Kevin\Desktop\KaminariApi\venv\Lib\site-packages\sqlalchemy\orm\loading.py", line 1603, in load_scalar_attributes
    raise orm_exc.DetachedInstanceError(
sqlalchemy.orm.exc.DetachedInstanceError: Instance <Cliente at 0x1f843ac4560> is not bound to a Session; attribute refresh operation cannot proceed (Background on this error at: https://sqlalche.me/e/20/bhk3)
2024-11-18 00:26:33,108 - ERROR - Excepción capturada: Instance <Cliente at 0x1b416fe6b40> is not bound to a Session; attribute refresh operation cannot proceed (Background on this error at: https://sqlalche.me/e/20/bhk3)
Traceback (most recent call last):
  File "C:\Users\Kevin\Desktop\KaminariApi\main.py", line 36, in login
    print(userInDb.id, userInDb.username,'dsssssssssssssssssss')
          ^^^^^^^^^^^
  File "C:\Users\Kevin\Desktop\KaminariApi\venv\Lib\site-packages\sqlalchemy\orm\attributes.py", line 566, in __get__
    return self.impl.get(state, dict_)  # type: ignore[no-any-return]
           ^^^^^^^^^^^^^^^^^^^^^^^^^^^
  File "C:\Users\Kevin\Desktop\KaminariApi\venv\Lib\site-packages\sqlalchemy\orm\attributes.py", line 1086, in get
    value = self._fire_loader_callables(state, key, passive)
            ^^^^^^^^^^^^^^^^^^^^^^^^^^^^^^^^^^^^^^^^^^^^^^^^
  File "C:\Users\Kevin\Desktop\KaminariApi\venv\Lib\site-packages\sqlalchemy\orm\attributes.py", line 1116, in _fire_loader_callables
    return state._load_expired(state, passive)
           ^^^^^^^^^^^^^^^^^^^^^^^^^^^^^^^^^^^
  File "C:\Users\Kevin\Desktop\KaminariApi\venv\Lib\site-packages\sqlalchemy\orm\state.py", line 803, in _load_expired
    self.manager.expired_attribute_loader(self, toload, passive)
  File "C:\Users\Kevin\Desktop\KaminariApi\venv\Lib\site-packages\sqlalchemy\orm\loading.py", line 1603, in load_scalar_attributes
    raise orm_exc.DetachedInstanceError(
sqlalchemy.orm.exc.DetachedInstanceError: Instance <Cliente at 0x1b416fe6b40> is not bound to a Session; attribute refresh operation cannot proceed (Background on this error at: https://sqlalche.me/e/20/bhk3)
2024-11-18 00:35:53,832 - ERROR - Excepción capturada: Instance <Cliente at 0x233d688e9c0> is not bound to a Session; attribute refresh operation cannot proceed (Background on this error at: https://sqlalche.me/e/20/bhk3)
Traceback (most recent call last):
  File "C:\Users\Kevin\Desktop\KaminariApi\app\src\models\usuarioModels\consultarUsuario.py", line 20, in consultarCliente
    return cliente.id
           ^^^^^^^^^^
  File "C:\Users\Kevin\Desktop\KaminariApi\venv\Lib\site-packages\sqlalchemy\orm\attributes.py", line 566, in __get__
    return self.impl.get(state, dict_)  # type: ignore[no-any-return]
           ^^^^^^^^^^^^^^^^^^^^^^^^^^^
  File "C:\Users\Kevin\Desktop\KaminariApi\venv\Lib\site-packages\sqlalchemy\orm\attributes.py", line 1086, in get
    value = self._fire_loader_callables(state, key, passive)
            ^^^^^^^^^^^^^^^^^^^^^^^^^^^^^^^^^^^^^^^^^^^^^^^^
  File "C:\Users\Kevin\Desktop\KaminariApi\venv\Lib\site-packages\sqlalchemy\orm\attributes.py", line 1116, in _fire_loader_callables
    return state._load_expired(state, passive)
           ^^^^^^^^^^^^^^^^^^^^^^^^^^^^^^^^^^^
  File "C:\Users\Kevin\Desktop\KaminariApi\venv\Lib\site-packages\sqlalchemy\orm\state.py", line 803, in _load_expired
    self.manager.expired_attribute_loader(self, toload, passive)
  File "C:\Users\Kevin\Desktop\KaminariApi\venv\Lib\site-packages\sqlalchemy\orm\loading.py", line 1603, in load_scalar_attributes
    raise orm_exc.DetachedInstanceError(
sqlalchemy.orm.exc.DetachedInstanceError: Instance <Cliente at 0x233d688e9c0> is not bound to a Session; attribute refresh operation cannot proceed (Background on this error at: https://sqlalche.me/e/20/bhk3)
2024-11-18 00:36:08,949 - ERROR - Excepción capturada: Instance <Cliente at 0x2a591f8ea50> is not bound to a Session; attribute refresh operation cannot proceed (Background on this error at: https://sqlalche.me/e/20/bhk3)
Traceback (most recent call last):
  File "C:\Users\Kevin\Desktop\KaminariApi\app\src\models\usuarioModels\consultarUsuario.py", line 20, in consultarCliente
    return cliente.id
           ^^^^^^^^^^
  File "C:\Users\Kevin\Desktop\KaminariApi\venv\Lib\site-packages\sqlalchemy\orm\attributes.py", line 566, in __get__
    return self.impl.get(state, dict_)  # type: ignore[no-any-return]
           ^^^^^^^^^^^^^^^^^^^^^^^^^^^
  File "C:\Users\Kevin\Desktop\KaminariApi\venv\Lib\site-packages\sqlalchemy\orm\attributes.py", line 1086, in get
    value = self._fire_loader_callables(state, key, passive)
            ^^^^^^^^^^^^^^^^^^^^^^^^^^^^^^^^^^^^^^^^^^^^^^^^
  File "C:\Users\Kevin\Desktop\KaminariApi\venv\Lib\site-packages\sqlalchemy\orm\attributes.py", line 1116, in _fire_loader_callables
    return state._load_expired(state, passive)
           ^^^^^^^^^^^^^^^^^^^^^^^^^^^^^^^^^^^
  File "C:\Users\Kevin\Desktop\KaminariApi\venv\Lib\site-packages\sqlalchemy\orm\state.py", line 803, in _load_expired
    self.manager.expired_attribute_loader(self, toload, passive)
  File "C:\Users\Kevin\Desktop\KaminariApi\venv\Lib\site-packages\sqlalchemy\orm\loading.py", line 1603, in load_scalar_attributes
    raise orm_exc.DetachedInstanceError(
sqlalchemy.orm.exc.DetachedInstanceError: Instance <Cliente at 0x2a591f8ea50> is not bound to a Session; attribute refresh operation cannot proceed (Background on this error at: https://sqlalche.me/e/20/bhk3)
2024-11-18 12:48:50,593 - ERROR - Excepción capturada: 'Cliente' object is not subscriptable
Traceback (most recent call last):
  File "C:\Users\Kevin\Desktop\KaminariApi\main.py", line 37, in login
    if not userInDb or form_data.password != userInDb['pwd']:
                                             ~~~~~~~~^^^^^^^
TypeError: 'Cliente' object is not subscriptable
2024-11-18 12:50:19,052 - ERROR - Excepción capturada: 'int' object has no attribute 'value'
Traceback (most recent call last):
  File "C:\Users\Kevin\Desktop\KaminariApi\app\oauthJWT\encodeJwt.py", line 15, in encodeTheStr
    expiration = datetime.now(timezone.utc) + timedelta(minutes=InfomacionToEncodear.EXPIRETOKEN.value)
                                                                ^^^^^^^^^^^^^^^^^^^^^^^^^^^^^^^^^^^^^^
AttributeError: 'int' object has no attribute 'value'
2024-11-18 12:50:23,500 - ERROR - Excepción capturada: Not enough segments
Traceback (most recent call last):
  File "C:\Users\Kevin\Desktop\KaminariApi\venv\Lib\site-packages\jose\jws.py", line 176, in _load
    signing_input, crypto_segment = jwt.rsplit(b".", 1)
    ^^^^^^^^^^^^^^^^^^^^^^^^^^^^^
ValueError: not enough values to unpack (expected 2, got 1)

During handling of the above exception, another exception occurred:

Traceback (most recent call last):
  File "C:\Users\Kevin\Desktop\KaminariApi\venv\Lib\site-packages\jose\jwt.py", line 142, in decode
    payload = jws.verify(token, key, algorithms, verify=verify_signature)
              ^^^^^^^^^^^^^^^^^^^^^^^^^^^^^^^^^^^^^^^^^^^^^^^^^^^^^^^^^^^
  File "C:\Users\Kevin\Desktop\KaminariApi\venv\Lib\site-packages\jose\jws.py", line 70, in verify
    header, payload, signing_input, signature = _load(token)
                                                ^^^^^^^^^^^^
  File "C:\Users\Kevin\Desktop\KaminariApi\venv\Lib\site-packages\jose\jws.py", line 180, in _load
    raise JWSError("Not enough segments")
jose.exceptions.JWSError: Not enough segments

During handling of the above exception, another exception occurred:

Traceback (most recent call last):
  File "C:\Users\Kevin\Desktop\KaminariApi\app\oauthJWT\decodeJwt.py", line 22, in decodeToken
    return decode(
           ^^^^^^^
  File "C:\Users\Kevin\Desktop\KaminariApi\venv\Lib\site-packages\jose\jwt.py", line 144, in decode
    raise JWTError(e)
jose.exceptions.JWTError: Not enough segments
2024-11-18 13:29:34,561 - ERROR - Excepción capturada: Session.delete() got an unexpected keyword argument 'synchronize_session'
Traceback (most recent call last):
  File "C:\Users\Kevin\Desktop\KaminariApi\app\src\models\usuarioModels\deleteUsuario.py", line 14, in deleteCliente
    session.delete(clientToDelete, synchronize_session=False)
TypeError: Session.delete() got an unexpected keyword argument 'synchronize_session'
